Error during execution: Traceback (most recent call last):
  File "urllib3\connection.py", line 198, in _new_conn
  File "urllib3\util\connection.py", line 85, in create_connection
  File "urllib3\util\connection.py", line 73, in create_connection
TimeoutError: [WinError 10060] 由于连接方在一段时间后没有正确答复或连接的主机没有反应，连接尝试失败。

The above exception was the direct cause of the following exception:

Traceback (most recent call last):
  File "urllib3\connectionpool.py", line 787, in urlopen
  File "urllib3\connectionpool.py", line 488, in _make_request
  File "urllib3\connectionpool.py", line 464, in _make_request
  File "urllib3\connectionpool.py", line 1093, in _validate_conn
  File "urllib3\connection.py", line 704, in connect
  File "urllib3\connection.py", line 207, in _new_conn
urllib3.exceptions.ConnectTimeoutError: (<urllib3.connection.HTTPSConnection object at 0x000001ED259044D0>, 'Connection to api.github.com timed out. (connect timeout=None)')

The above exception was the direct cause of the following exception:

Traceback (most recent call last):
  File "requests\adapters.py", line 667, in send
  File "urllib3\connectionpool.py", line 841, in urlopen
  File "urllib3\util\retry.py", line 519, in increment
urllib3.exceptions.MaxRetryError: HTTPSConnectionPool(host='api.github.com', port=443): Max retries exceeded with url: /repos/Ilikectrlmusic/auto_ip/contents/781_result/2025-02-19.txt (Caused by ConnectTimeoutError(<urllib3.connection.HTTPSConnection object at 0x000001ED259044D0>, 'Connection to api.github.com timed out. (connect timeout=None)'))

During handling of the above exception, another exception occurred:

Traceback (most recent call last):
  File "main.py", line 339, in <module>
  File "main.py", line 307, in upload_result
  File "requests\api.py", line 130, in put
  File "requests\api.py", line 59, in request
  File "requests\sessions.py", line 589, in request
  File "requests\sessions.py", line 703, in send
  File "requests\adapters.py", line 688, in send
requests.exceptions.ConnectTimeout: HTTPSConnectionPool(host='api.github.com', port=443): Max retries exceeded with url: /repos/Ilikectrlmusic/auto_ip/contents/781_result/2025-02-19.txt (Caused by ConnectTimeoutError(<urllib3.connection.HTTPSConnection object at 0x000001ED259044D0>, 'Connection to api.github.com timed out. (connect timeout=None)'))

Error during execution: Traceback (most recent call last):
  File "urllib3\connection.py", line 198, in _new_conn
  File "urllib3\util\connection.py", line 85, in create_connection
  File "urllib3\util\connection.py", line 73, in create_connection
TimeoutError: [WinError 10060] 由于连接方在一段时间后没有正确答复或连接的主机没有反应，连接尝试失败。

The above exception was the direct cause of the following exception:

Traceback (most recent call last):
  File "urllib3\connectionpool.py", line 787, in urlopen
  File "urllib3\connectionpool.py", line 488, in _make_request
  File "urllib3\connectionpool.py", line 464, in _make_request
  File "urllib3\connectionpool.py", line 1093, in _validate_conn
  File "urllib3\connection.py", line 704, in connect
  File "urllib3\connection.py", line 207, in _new_conn
urllib3.exceptions.ConnectTimeoutError: (<urllib3.connection.HTTPSConnection object at 0x000001ED25904650>, 'Connection to api.github.com timed out. (connect timeout=None)')

The above exception was the direct cause of the following exception:

Traceback (most recent call last):
  File "requests\adapters.py", line 667, in send
  File "urllib3\connectionpool.py", line 841, in urlopen
  File "urllib3\util\retry.py", line 519, in increment
urllib3.exceptions.MaxRetryError: HTTPSConnectionPool(host='api.github.com', port=443): Max retries exceeded with url: /repos/Ilikectrlmusic/auto_ip/contents/781_result/2025-02-19.txt (Caused by ConnectTimeoutError(<urllib3.connection.HTTPSConnection object at 0x000001ED25904650>, 'Connection to api.github.com timed out. (connect timeout=None)'))

During handling of the above exception, another exception occurred:

Traceback (most recent call last):
  File "main.py", line 339, in <module>
  File "main.py", line 307, in upload_result
  File "requests\api.py", line 130, in put
  File "requests\api.py", line 59, in request
  File "requests\sessions.py", line 589, in request
  File "requests\sessions.py", line 703, in send
  File "requests\adapters.py", line 688, in send
requests.exceptions.ConnectTimeout: HTTPSConnectionPool(host='api.github.com', port=443): Max retries exceeded with url: /repos/Ilikectrlmusic/auto_ip/contents/781_result/2025-02-19.txt (Caused by ConnectTimeoutError(<urllib3.connection.HTTPSConnection object at 0x000001ED25904650>, 'Connection to api.github.com timed out. (connect timeout=None)'))

Error during execution: Traceback (most recent call last):
  File "urllib3\connection.py", line 198, in _new_conn
  File "urllib3\util\connection.py", line 85, in create_connection
  File "urllib3\util\connection.py", line 73, in create_connection
TimeoutError: [WinError 10060] 由于连接方在一段时间后没有正确答复或连接的主机没有反应，连接尝试失败。

The above exception was the direct cause of the following exception:

Traceback (most recent call last):
  File "urllib3\connectionpool.py", line 787, in urlopen
  File "urllib3\connectionpool.py", line 488, in _make_request
  File "urllib3\connectionpool.py", line 464, in _make_request
  File "urllib3\connectionpool.py", line 1093, in _validate_conn
  File "urllib3\connection.py", line 704, in connect
  File "urllib3\connection.py", line 207, in _new_conn
urllib3.exceptions.ConnectTimeoutError: (<urllib3.connection.HTTPSConnection object at 0x000001ED258F4F50>, 'Connection to api.github.com timed out. (connect timeout=None)')

The above exception was the direct cause of the following exception:

Traceback (most recent call last):
  File "requests\adapters.py", line 667, in send
  File "urllib3\connectionpool.py", line 841, in urlopen
  File "urllib3\util\retry.py", line 519, in increment
urllib3.exceptions.MaxRetryError: HTTPSConnectionPool(host='api.github.com', port=443): Max retries exceeded with url: /repos/Ilikectrlmusic/auto_ip/contents/781_result/2025-02-19.txt (Caused by ConnectTimeoutError(<urllib3.connection.HTTPSConnection object at 0x000001ED258F4F50>, 'Connection to api.github.com timed out. (connect timeout=None)'))

During handling of the above exception, another exception occurred:

Traceback (most recent call last):
  File "main.py", line 339, in <module>
  File "main.py", line 307, in upload_result
  File "requests\api.py", line 130, in put
  File "requests\api.py", line 59, in request
  File "requests\sessions.py", line 589, in request
  File "requests\sessions.py", line 703, in send
  File "requests\adapters.py", line 688, in send
requests.exceptions.ConnectTimeout: HTTPSConnectionPool(host='api.github.com', port=443): Max retries exceeded with url: /repos/Ilikectrlmusic/auto_ip/contents/781_result/2025-02-19.txt (Caused by ConnectTimeoutError(<urllib3.connection.HTTPSConnection object at 0x000001ED258F4F50>, 'Connection to api.github.com timed out. (connect timeout=None)'))

Error during execution: Traceback (most recent call last):
  File "urllib3\connection.py", line 198, in _new_conn
  File "urllib3\util\connection.py", line 85, in create_connection
  File "urllib3\util\connection.py", line 73, in create_connection
TimeoutError: [WinError 10060] 由于连接方在一段时间后没有正确答复或连接的主机没有反应，连接尝试失败。

The above exception was the direct cause of the following exception:

Traceback (most recent call last):
  File "urllib3\connectionpool.py", line 787, in urlopen
  File "urllib3\connectionpool.py", line 488, in _make_request
  File "urllib3\connectionpool.py", line 464, in _make_request
  File "urllib3\connectionpool.py", line 1093, in _validate_conn
  File "urllib3\connection.py", line 704, in connect
  File "urllib3\connection.py", line 207, in _new_conn
urllib3.exceptions.ConnectTimeoutError: (<urllib3.connection.HTTPSConnection object at 0x000001ED25929AC0>, 'Connection to api.github.com timed out. (connect timeout=None)')

The above exception was the direct cause of the following exception:

Traceback (most recent call last):
  File "requests\adapters.py", line 667, in send
  File "urllib3\connectionpool.py", line 841, in urlopen
  File "urllib3\util\retry.py", line 519, in increment
urllib3.exceptions.MaxRetryError: HTTPSConnectionPool(host='api.github.com', port=443): Max retries exceeded with url: /repos/Ilikectrlmusic/auto_ip/contents/781_result/2025-02-19.txt (Caused by ConnectTimeoutError(<urllib3.connection.HTTPSConnection object at 0x000001ED25929AC0>, 'Connection to api.github.com timed out. (connect timeout=None)'))

During handling of the above exception, another exception occurred:

Traceback (most recent call last):
  File "main.py", line 339, in <module>
  File "main.py", line 307, in upload_result
  File "requests\api.py", line 130, in put
  File "requests\api.py", line 59, in request
  File "requests\sessions.py", line 589, in request
  File "requests\sessions.py", line 703, in send
  File "requests\adapters.py", line 688, in send
requests.exceptions.ConnectTimeout: HTTPSConnectionPool(host='api.github.com', port=443): Max retries exceeded with url: /repos/Ilikectrlmusic/auto_ip/contents/781_result/2025-02-19.txt (Caused by ConnectTimeoutError(<urllib3.connection.HTTPSConnection object at 0x000001ED25929AC0>, 'Connection to api.github.com timed out. (connect timeout=None)'))

Error during execution: Traceback (most recent call last):
  File "urllib3\connection.py", line 198, in _new_conn
  File "urllib3\util\connection.py", line 85, in create_connection
  File "urllib3\util\connection.py", line 73, in create_connection
TimeoutError: [WinError 10060] 由于连接方在一段时间后没有正确答复或连接的主机没有反应，连接尝试失败。

The above exception was the direct cause of the following exception:

Traceback (most recent call last):
  File "urllib3\connectionpool.py", line 787, in urlopen
  File "urllib3\connectionpool.py", line 488, in _make_request
  File "urllib3\connectionpool.py", line 464, in _make_request
  File "urllib3\connectionpool.py", line 1093, in _validate_conn
  File "urllib3\connection.py", line 704, in connect
  File "urllib3\connection.py", line 207, in _new_conn
urllib3.exceptions.ConnectTimeoutError: (<urllib3.connection.HTTPSConnection object at 0x000001ED258F7CB0>, 'Connection to api.github.com timed out. (connect timeout=None)')

The above exception was the direct cause of the following exception:

Traceback (most recent call last):
  File "requests\adapters.py", line 667, in send
  File "urllib3\connectionpool.py", line 841, in urlopen
  File "urllib3\util\retry.py", line 519, in increment
urllib3.exceptions.MaxRetryError: HTTPSConnectionPool(host='api.github.com', port=443): Max retries exceeded with url: /repos/Ilikectrlmusic/auto_ip/contents/781_result/2025-02-19.txt (Caused by ConnectTimeoutError(<urllib3.connection.HTTPSConnection object at 0x000001ED258F7CB0>, 'Connection to api.github.com timed out. (connect timeout=None)'))

During handling of the above exception, another exception occurred:

Traceback (most recent call last):
  File "main.py", line 339, in <module>
  File "main.py", line 288, in upload_result
  File "requests\api.py", line 73, in get
  File "requests\api.py", line 59, in request
  File "requests\sessions.py", line 589, in request
  File "requests\sessions.py", line 703, in send
  File "requests\adapters.py", line 688, in send
requests.exceptions.ConnectTimeout: HTTPSConnectionPool(host='api.github.com', port=443): Max retries exceeded with url: /repos/Ilikectrlmusic/auto_ip/contents/781_result/2025-02-19.txt (Caused by ConnectTimeoutError(<urllib3.connection.HTTPSConnection object at 0x000001ED258F7CB0>, 'Connection to api.github.com timed out. (connect timeout=None)'))

Error during execution: Traceback (most recent call last):
  File "urllib3\connection.py", line 198, in _new_conn
  File "urllib3\util\connection.py", line 85, in create_connection
  File "urllib3\util\connection.py", line 73, in create_connection
TimeoutError: [WinError 10060] 由于连接方在一段时间后没有正确答复或连接的主机没有反应，连接尝试失败。

The above exception was the direct cause of the following exception:

Traceback (most recent call last):
  File "urllib3\connectionpool.py", line 787, in urlopen
  File "urllib3\connectionpool.py", line 488, in _make_request
  File "urllib3\connectionpool.py", line 464, in _make_request
  File "urllib3\connectionpool.py", line 1093, in _validate_conn
  File "urllib3\connection.py", line 704, in connect
  File "urllib3\connection.py", line 207, in _new_conn
urllib3.exceptions.ConnectTimeoutError: (<urllib3.connection.HTTPSConnection object at 0x000001ED2592A8A0>, 'Connection to api.github.com timed out. (connect timeout=None)')

The above exception was the direct cause of the following exception:

Traceback (most recent call last):
  File "requests\adapters.py", line 667, in send
  File "urllib3\connectionpool.py", line 841, in urlopen
  File "urllib3\util\retry.py", line 519, in increment
urllib3.exceptions.MaxRetryError: HTTPSConnectionPool(host='api.github.com', port=443): Max retries exceeded with url: /repos/Ilikectrlmusic/auto_ip/contents/781_result/2025-02-19.txt (Caused by ConnectTimeoutError(<urllib3.connection.HTTPSConnection object at 0x000001ED2592A8A0>, 'Connection to api.github.com timed out. (connect timeout=None)'))

During handling of the above exception, another exception occurred:

Traceback (most recent call last):
  File "main.py", line 339, in <module>
  File "main.py", line 288, in upload_result
  File "requests\api.py", line 73, in get
  File "requests\api.py", line 59, in request
  File "requests\sessions.py", line 589, in request
  File "requests\sessions.py", line 703, in send
  File "requests\adapters.py", line 688, in send
requests.exceptions.ConnectTimeout: HTTPSConnectionPool(host='api.github.com', port=443): Max retries exceeded with url: /repos/Ilikectrlmusic/auto_ip/contents/781_result/2025-02-19.txt (Caused by ConnectTimeoutError(<urllib3.connection.HTTPSConnection object at 0x000001ED2592A8A0>, 'Connection to api.github.com timed out. (connect timeout=None)'))

Error during execution: Traceback (most recent call last):
  File "urllib3\connection.py", line 198, in _new_conn
  File "urllib3\util\connection.py", line 85, in create_connection
  File "urllib3\util\connection.py", line 73, in create_connection
TimeoutError: [WinError 10060] 由于连接方在一段时间后没有正确答复或连接的主机没有反应，连接尝试失败。

The above exception was the direct cause of the following exception:

Traceback (most recent call last):
  File "urllib3\connectionpool.py", line 787, in urlopen
  File "urllib3\connectionpool.py", line 488, in _make_request
  File "urllib3\connectionpool.py", line 464, in _make_request
  File "urllib3\connectionpool.py", line 1093, in _validate_conn
  File "urllib3\connection.py", line 704, in connect
  File "urllib3\connection.py", line 207, in _new_conn
urllib3.exceptions.ConnectTimeoutError: (<urllib3.connection.HTTPSConnection object at 0x000001ED258F6300>, 'Connection to api.github.com timed out. (connect timeout=None)')

The above exception was the direct cause of the following exception:

Traceback (most recent call last):
  File "requests\adapters.py", line 667, in send
  File "urllib3\connectionpool.py", line 841, in urlopen
  File "urllib3\util\retry.py", line 519, in increment
urllib3.exceptions.MaxRetryError: HTTPSConnectionPool(host='api.github.com', port=443): Max retries exceeded with url: /repos/Ilikectrlmusic/auto_ip/contents/781_result/2025-02-19.txt (Caused by ConnectTimeoutError(<urllib3.connection.HTTPSConnection object at 0x000001ED258F6300>, 'Connection to api.github.com timed out. (connect timeout=None)'))

During handling of the above exception, another exception occurred:

Traceback (most recent call last):
  File "main.py", line 339, in <module>
  File "main.py", line 307, in upload_result
  File "requests\api.py", line 130, in put
  File "requests\api.py", line 59, in request
  File "requests\sessions.py", line 589, in request
  File "requests\sessions.py", line 703, in send
  File "requests\adapters.py", line 688, in send
requests.exceptions.ConnectTimeout: HTTPSConnectionPool(host='api.github.com', port=443): Max retries exceeded with url: /repos/Ilikectrlmusic/auto_ip/contents/781_result/2025-02-19.txt (Caused by ConnectTimeoutError(<urllib3.connection.HTTPSConnection object at 0x000001ED258F6300>, 'Connection to api.github.com timed out. (connect timeout=None)'))

Error during execution: Traceback (most recent call last):
  File "urllib3\connection.py", line 198, in _new_conn
  File "urllib3\util\connection.py", line 85, in create_connection
  File "urllib3\util\connection.py", line 73, in create_connection
TimeoutError: [WinError 10060] 由于连接方在一段时间后没有正确答复或连接的主机没有反应，连接尝试失败。

The above exception was the direct cause of the following exception:

Traceback (most recent call last):
  File "urllib3\connectionpool.py", line 787, in urlopen
  File "urllib3\connectionpool.py", line 488, in _make_request
  File "urllib3\connectionpool.py", line 464, in _make_request
  File "urllib3\connectionpool.py", line 1093, in _validate_conn
  File "urllib3\connection.py", line 704, in connect
  File "urllib3\connection.py", line 207, in _new_conn
urllib3.exceptions.ConnectTimeoutError: (<urllib3.connection.HTTPSConnection object at 0x000001ED25905D00>, 'Connection to api.github.com timed out. (connect timeout=None)')

The above exception was the direct cause of the following exception:

Traceback (most recent call last):
  File "requests\adapters.py", line 667, in send
  File "urllib3\connectionpool.py", line 841, in urlopen
  File "urllib3\util\retry.py", line 519, in increment
urllib3.exceptions.MaxRetryError: HTTPSConnectionPool(host='api.github.com', port=443): Max retries exceeded with url: /repos/Ilikectrlmusic/auto_ip/contents/781_result/2025-02-19.txt (Caused by ConnectTimeoutError(<urllib3.connection.HTTPSConnection object at 0x000001ED25905D00>, 'Connection to api.github.com timed out. (connect timeout=None)'))

During handling of the above exception, another exception occurred:

Traceback (most recent call last):
  File "main.py", line 339, in <module>
  File "main.py", line 307, in upload_result
  File "requests\api.py", line 130, in put
  File "requests\api.py", line 59, in request
  File "requests\sessions.py", line 589, in request
  File "requests\sessions.py", line 703, in send
  File "requests\adapters.py", line 688, in send
requests.exceptions.ConnectTimeout: HTTPSConnectionPool(host='api.github.com', port=443): Max retries exceeded with url: /repos/Ilikectrlmusic/auto_ip/contents/781_result/2025-02-19.txt (Caused by ConnectTimeoutError(<urllib3.connection.HTTPSConnection object at 0x000001ED25905D00>, 'Connection to api.github.com timed out. (connect timeout=None)'))

Error during execution: Traceback (most recent call last):
  File "urllib3\connection.py", line 198, in _new_conn
  File "urllib3\util\connection.py", line 85, in create_connection
  File "urllib3\util\connection.py", line 73, in create_connection
TimeoutError: [WinError 10060] 由于连接方在一段时间后没有正确答复或连接的主机没有反应，连接尝试失败。

The above exception was the direct cause of the following exception:

Traceback (most recent call last):
  File "urllib3\connectionpool.py", line 787, in urlopen
  File "urllib3\connectionpool.py", line 488, in _make_request
  File "urllib3\connectionpool.py", line 464, in _make_request
  File "urllib3\connectionpool.py", line 1093, in _validate_conn
  File "urllib3\connection.py", line 704, in connect
  File "urllib3\connection.py", line 207, in _new_conn
urllib3.exceptions.ConnectTimeoutError: (<urllib3.connection.HTTPSConnection object at 0x000001ED259298E0>, 'Connection to api.github.com timed out. (connect timeout=None)')

The above exception was the direct cause of the following exception:

Traceback (most recent call last):
  File "requests\adapters.py", line 667, in send
  File "urllib3\connectionpool.py", line 841, in urlopen
  File "urllib3\util\retry.py", line 519, in increment
urllib3.exceptions.MaxRetryError: HTTPSConnectionPool(host='api.github.com', port=443): Max retries exceeded with url: /repos/Ilikectrlmusic/auto_ip/contents/781_result/2025-02-19.txt (Caused by ConnectTimeoutError(<urllib3.connection.HTTPSConnection object at 0x000001ED259298E0>, 'Connection to api.github.com timed out. (connect timeout=None)'))

During handling of the above exception, another exception occurred:

Traceback (most recent call last):
  File "main.py", line 339, in <module>
  File "main.py", line 307, in upload_result
  File "requests\api.py", line 130, in put
  File "requests\api.py", line 59, in request
  File "requests\sessions.py", line 589, in request
  File "requests\sessions.py", line 703, in send
  File "requests\adapters.py", line 688, in send
requests.exceptions.ConnectTimeout: HTTPSConnectionPool(host='api.github.com', port=443): Max retries exceeded with url: /repos/Ilikectrlmusic/auto_ip/contents/781_result/2025-02-19.txt (Caused by ConnectTimeoutError(<urllib3.connection.HTTPSConnection object at 0x000001ED259298E0>, 'Connection to api.github.com timed out. (connect timeout=None)'))

Error during execution: Traceback (most recent call last):
  File "urllib3\connection.py", line 198, in _new_conn
  File "urllib3\util\connection.py", line 85, in create_connection
  File "urllib3\util\connection.py", line 73, in create_connection
TimeoutError: [WinError 10060] 由于连接方在一段时间后没有正确答复或连接的主机没有反应，连接尝试失败。

The above exception was the direct cause of the following exception:

Traceback (most recent call last):
  File "urllib3\connectionpool.py", line 787, in urlopen
  File "urllib3\connectionpool.py", line 488, in _make_request
  File "urllib3\connectionpool.py", line 464, in _make_request
  File "urllib3\connectionpool.py", line 1093, in _validate_conn
  File "urllib3\connection.py", line 704, in connect
  File "urllib3\connection.py", line 207, in _new_conn
urllib3.exceptions.ConnectTimeoutError: (<urllib3.connection.HTTPSConnection object at 0x000001ED25882BD0>, 'Connection to api.github.com timed out. (connect timeout=None)')

The above exception was the direct cause of the following exception:

Traceback (most recent call last):
  File "requests\adapters.py", line 667, in send
  File "urllib3\connectionpool.py", line 841, in urlopen
  File "urllib3\util\retry.py", line 519, in increment
urllib3.exceptions.MaxRetryError: HTTPSConnectionPool(host='api.github.com', port=443): Max retries exceeded with url: /repos/Ilikectrlmusic/auto_ip/contents/781_result/2025-02-19.txt (Caused by ConnectTimeoutError(<urllib3.connection.HTTPSConnection object at 0x000001ED25882BD0>, 'Connection to api.github.com timed out. (connect timeout=None)'))

During handling of the above exception, another exception occurred:

Traceback (most recent call last):
  File "main.py", line 339, in <module>
  File "main.py", line 307, in upload_result
  File "requests\api.py", line 130, in put
  File "requests\api.py", line 59, in request
  File "requests\sessions.py", line 589, in request
  File "requests\sessions.py", line 703, in send
  File "requests\adapters.py", line 688, in send
requests.exceptions.ConnectTimeout: HTTPSConnectionPool(host='api.github.com', port=443): Max retries exceeded with url: /repos/Ilikectrlmusic/auto_ip/contents/781_result/2025-02-19.txt (Caused by ConnectTimeoutError(<urllib3.connection.HTTPSConnection object at 0x000001ED25882BD0>, 'Connection to api.github.com timed out. (connect timeout=None)'))

Error during execution: Traceback (most recent call last):
  File "urllib3\connection.py", line 198, in _new_conn
  File "urllib3\util\connection.py", line 85, in create_connection
  File "urllib3\util\connection.py", line 73, in create_connection
TimeoutError: [WinError 10060] 由于连接方在一段时间后没有正确答复或连接的主机没有反应，连接尝试失败。

The above exception was the direct cause of the following exception:

Traceback (most recent call last):
  File "urllib3\connectionpool.py", line 787, in urlopen
  File "urllib3\connectionpool.py", line 488, in _make_request
  File "urllib3\connectionpool.py", line 464, in _make_request
  File "urllib3\connectionpool.py", line 1093, in _validate_conn
  File "urllib3\connection.py", line 704, in connect
  File "urllib3\connection.py", line 207, in _new_conn
urllib3.exceptions.ConnectTimeoutError: (<urllib3.connection.HTTPSConnection object at 0x000001ED25906510>, 'Connection to api.github.com timed out. (connect timeout=None)')

The above exception was the direct cause of the following exception:

Traceback (most recent call last):
  File "requests\adapters.py", line 667, in send
  File "urllib3\connectionpool.py", line 841, in urlopen
  File "urllib3\util\retry.py", line 519, in increment
urllib3.exceptions.MaxRetryError: HTTPSConnectionPool(host='api.github.com', port=443): Max retries exceeded with url: /repos/Ilikectrlmusic/auto_ip/contents/781_result/2025-02-19.txt (Caused by ConnectTimeoutError(<urllib3.connection.HTTPSConnection object at 0x000001ED25906510>, 'Connection to api.github.com timed out. (connect timeout=None)'))

During handling of the above exception, another exception occurred:

Traceback (most recent call last):
  File "main.py", line 339, in <module>
  File "main.py", line 288, in upload_result
  File "requests\api.py", line 73, in get
  File "requests\api.py", line 59, in request
  File "requests\sessions.py", line 589, in request
  File "requests\sessions.py", line 703, in send
  File "requests\adapters.py", line 688, in send
requests.exceptions.ConnectTimeout: HTTPSConnectionPool(host='api.github.com', port=443): Max retries exceeded with url: /repos/Ilikectrlmusic/auto_ip/contents/781_result/2025-02-19.txt (Caused by ConnectTimeoutError(<urllib3.connection.HTTPSConnection object at 0x000001ED25906510>, 'Connection to api.github.com timed out. (connect timeout=None)'))

Error during execution: Traceback (most recent call last):
  File "urllib3\connection.py", line 198, in _new_conn
  File "urllib3\util\connection.py", line 85, in create_connection
  File "urllib3\util\connection.py", line 73, in create_connection
TimeoutError: [WinError 10060] 由于连接方在一段时间后没有正确答复或连接的主机没有反应，连接尝试失败。

The above exception was the direct cause of the following exception:

Traceback (most recent call last):
  File "urllib3\connectionpool.py", line 787, in urlopen
  File "urllib3\connectionpool.py", line 488, in _make_request
  File "urllib3\connectionpool.py", line 464, in _make_request
  File "urllib3\connectionpool.py", line 1093, in _validate_conn
  File "urllib3\connection.py", line 704, in connect
  File "urllib3\connection.py", line 207, in _new_conn
urllib3.exceptions.ConnectTimeoutError: (<urllib3.connection.HTTPSConnection object at 0x000001ED2592A360>, 'Connection to api.github.com timed out. (connect timeout=None)')

The above exception was the direct cause of the following exception:

Traceback (most recent call last):
  File "requests\adapters.py", line 667, in send
  File "urllib3\connectionpool.py", line 841, in urlopen
  File "urllib3\util\retry.py", line 519, in increment
urllib3.exceptions.MaxRetryError: HTTPSConnectionPool(host='api.github.com', port=443): Max retries exceeded with url: /repos/Ilikectrlmusic/auto_ip/contents/781_result/2025-02-19.txt (Caused by ConnectTimeoutError(<urllib3.connection.HTTPSConnection object at 0x000001ED2592A360>, 'Connection to api.github.com timed out. (connect timeout=None)'))

During handling of the above exception, another exception occurred:

Traceback (most recent call last):
  File "main.py", line 339, in <module>
  File "main.py", line 307, in upload_result
  File "requests\api.py", line 130, in put
  File "requests\api.py", line 59, in request
  File "requests\sessions.py", line 589, in request
  File "requests\sessions.py", line 703, in send
  File "requests\adapters.py", line 688, in send
requests.exceptions.ConnectTimeout: HTTPSConnectionPool(host='api.github.com', port=443): Max retries exceeded with url: /repos/Ilikectrlmusic/auto_ip/contents/781_result/2025-02-19.txt (Caused by ConnectTimeoutError(<urllib3.connection.HTTPSConnection object at 0x000001ED2592A360>, 'Connection to api.github.com timed out. (connect timeout=None)'))

Error during execution: Traceback (most recent call last):
  File "urllib3\connection.py", line 198, in _new_conn
  File "urllib3\util\connection.py", line 85, in create_connection
  File "urllib3\util\connection.py", line 73, in create_connection
TimeoutError: [WinError 10060] 由于连接方在一段时间后没有正确答复或连接的主机没有反应，连接尝试失败。

The above exception was the direct cause of the following exception:

Traceback (most recent call last):
  File "urllib3\connectionpool.py", line 787, in urlopen
  File "urllib3\connectionpool.py", line 488, in _make_request
  File "urllib3\connectionpool.py", line 464, in _make_request
  File "urllib3\connectionpool.py", line 1093, in _validate_conn
  File "urllib3\connection.py", line 704, in connect
  File "urllib3\connection.py", line 207, in _new_conn
urllib3.exceptions.ConnectTimeoutError: (<urllib3.connection.HTTPSConnection object at 0x000001ED2592B410>, 'Connection to api.github.com timed out. (connect timeout=None)')

The above exception was the direct cause of the following exception:

Traceback (most recent call last):
  File "requests\adapters.py", line 667, in send
  File "urllib3\connectionpool.py", line 841, in urlopen
  File "urllib3\util\retry.py", line 519, in increment
urllib3.exceptions.MaxRetryError: HTTPSConnectionPool(host='api.github.com', port=443): Max retries exceeded with url: /repos/Ilikectrlmusic/auto_ip/contents/781_result/2025-02-19.txt (Caused by ConnectTimeoutError(<urllib3.connection.HTTPSConnection object at 0x000001ED2592B410>, 'Connection to api.github.com timed out. (connect timeout=None)'))

During handling of the above exception, another exception occurred:

Traceback (most recent call last):
  File "main.py", line 339, in <module>
  File "main.py", line 307, in upload_result
  File "requests\api.py", line 130, in put
  File "requests\api.py", line 59, in request
  File "requests\sessions.py", line 589, in request
  File "requests\sessions.py", line 703, in send
  File "requests\adapters.py", line 688, in send
requests.exceptions.ConnectTimeout: HTTPSConnectionPool(host='api.github.com', port=443): Max retries exceeded with url: /repos/Ilikectrlmusic/auto_ip/contents/781_result/2025-02-19.txt (Caused by ConnectTimeoutError(<urllib3.connection.HTTPSConnection object at 0x000001ED2592B410>, 'Connection to api.github.com timed out. (connect timeout=None)'))

Error during execution: Traceback (most recent call last):
  File "urllib3\connection.py", line 198, in _new_conn
  File "urllib3\util\connection.py", line 85, in create_connection
  File "urllib3\util\connection.py", line 73, in create_connection
TimeoutError: [WinError 10060] 由于连接方在一段时间后没有正确答复或连接的主机没有反应，连接尝试失败。

The above exception was the direct cause of the following exception:

Traceback (most recent call last):
  File "urllib3\connectionpool.py", line 787, in urlopen
  File "urllib3\connectionpool.py", line 488, in _make_request
  File "urllib3\connectionpool.py", line 464, in _make_request
  File "urllib3\connectionpool.py", line 1093, in _validate_conn
  File "urllib3\connection.py", line 704, in connect
  File "urllib3\connection.py", line 207, in _new_conn
urllib3.exceptions.ConnectTimeoutError: (<urllib3.connection.HTTPSConnection object at 0x000001ED258F47A0>, 'Connection to api.github.com timed out. (connect timeout=None)')

The above exception was the direct cause of the following exception:

Traceback (most recent call last):
  File "requests\adapters.py", line 667, in send
  File "urllib3\connectionpool.py", line 841, in urlopen
  File "urllib3\util\retry.py", line 519, in increment
urllib3.exceptions.MaxRetryError: HTTPSConnectionPool(host='api.github.com', port=443): Max retries exceeded with url: /repos/Ilikectrlmusic/auto_ip/contents/781_result/2025-02-19.txt (Caused by ConnectTimeoutError(<urllib3.connection.HTTPSConnection object at 0x000001ED258F47A0>, 'Connection to api.github.com timed out. (connect timeout=None)'))

During handling of the above exception, another exception occurred:

Traceback (most recent call last):
  File "main.py", line 339, in <module>
  File "main.py", line 288, in upload_result
  File "requests\api.py", line 73, in get
  File "requests\api.py", line 59, in request
  File "requests\sessions.py", line 589, in request
  File "requests\sessions.py", line 703, in send
  File "requests\adapters.py", line 688, in send
requests.exceptions.ConnectTimeout: HTTPSConnectionPool(host='api.github.com', port=443): Max retries exceeded with url: /repos/Ilikectrlmusic/auto_ip/contents/781_result/2025-02-19.txt (Caused by ConnectTimeoutError(<urllib3.connection.HTTPSConnection object at 0x000001ED258F47A0>, 'Connection to api.github.com timed out. (connect timeout=None)'))

Error during execution: Traceback (most recent call last):
  File "urllib3\connection.py", line 198, in _new_conn
  File "urllib3\util\connection.py", line 85, in create_connection
  File "urllib3\util\connection.py", line 73, in create_connection
TimeoutError: [WinError 10060] 由于连接方在一段时间后没有正确答复或连接的主机没有反应，连接尝试失败。

The above exception was the direct cause of the following exception:

Traceback (most recent call last):
  File "urllib3\connectionpool.py", line 787, in urlopen
  File "urllib3\connectionpool.py", line 488, in _make_request
  File "urllib3\connectionpool.py", line 464, in _make_request
  File "urllib3\connectionpool.py", line 1093, in _validate_conn
  File "urllib3\connection.py", line 704, in connect
  File "urllib3\connection.py", line 207, in _new_conn
urllib3.exceptions.ConnectTimeoutError: (<urllib3.connection.HTTPSConnection object at 0x000001ED2592AAB0>, 'Connection to api.github.com timed out. (connect timeout=None)')

The above exception was the direct cause of the following exception:

Traceback (most recent call last):
  File "requests\adapters.py", line 667, in send
  File "urllib3\connectionpool.py", line 841, in urlopen
  File "urllib3\util\retry.py", line 519, in increment
urllib3.exceptions.MaxRetryError: HTTPSConnectionPool(host='api.github.com', port=443): Max retries exceeded with url: /repos/Ilikectrlmusic/auto_ip/contents/781_result/2025-02-19.txt (Caused by ConnectTimeoutError(<urllib3.connection.HTTPSConnection object at 0x000001ED2592AAB0>, 'Connection to api.github.com timed out. (connect timeout=None)'))

During handling of the above exception, another exception occurred:

Traceback (most recent call last):
  File "main.py", line 339, in <module>
  File "main.py", line 288, in upload_result
  File "requests\api.py", line 73, in get
  File "requests\api.py", line 59, in request
  File "requests\sessions.py", line 589, in request
  File "requests\sessions.py", line 703, in send
  File "requests\adapters.py", line 688, in send
requests.exceptions.ConnectTimeout: HTTPSConnectionPool(host='api.github.com', port=443): Max retries exceeded with url: /repos/Ilikectrlmusic/auto_ip/contents/781_result/2025-02-19.txt (Caused by ConnectTimeoutError(<urllib3.connection.HTTPSConnection object at 0x000001ED2592AAB0>, 'Connection to api.github.com timed out. (connect timeout=None)'))

Error during execution: Traceback (most recent call last):
  File "urllib3\connection.py", line 198, in _new_conn
  File "urllib3\util\connection.py", line 85, in create_connection
  File "urllib3\util\connection.py", line 73, in create_connection
TimeoutError: [WinError 10060] 由于连接方在一段时间后没有正确答复或连接的主机没有反应，连接尝试失败。

The above exception was the direct cause of the following exception:

Traceback (most recent call last):
  File "urllib3\connectionpool.py", line 787, in urlopen
  File "urllib3\connectionpool.py", line 488, in _make_request
  File "urllib3\connectionpool.py", line 464, in _make_request
  File "urllib3\connectionpool.py", line 1093, in _validate_conn
  File "urllib3\connection.py", line 704, in connect
  File "urllib3\connection.py", line 207, in _new_conn
urllib3.exceptions.ConnectTimeoutError: (<urllib3.connection.HTTPSConnection object at 0x000001ED25928FE0>, 'Connection to api.github.com timed out. (connect timeout=None)')

The above exception was the direct cause of the following exception:

Traceback (most recent call last):
  File "requests\adapters.py", line 667, in send
  File "urllib3\connectionpool.py", line 841, in urlopen
  File "urllib3\util\retry.py", line 519, in increment
urllib3.exceptions.MaxRetryError: HTTPSConnectionPool(host='api.github.com', port=443): Max retries exceeded with url: /repos/Ilikectrlmusic/auto_ip/contents/781_result/2025-02-19.txt (Caused by ConnectTimeoutError(<urllib3.connection.HTTPSConnection object at 0x000001ED25928FE0>, 'Connection to api.github.com timed out. (connect timeout=None)'))

During handling of the above exception, another exception occurred:

Traceback (most recent call last):
  File "main.py", line 339, in <module>
  File "main.py", line 288, in upload_result
  File "requests\api.py", line 73, in get
  File "requests\api.py", line 59, in request
  File "requests\sessions.py", line 589, in request
  File "requests\sessions.py", line 703, in send
  File "requests\adapters.py", line 688, in send
requests.exceptions.ConnectTimeout: HTTPSConnectionPool(host='api.github.com', port=443): Max retries exceeded with url: /repos/Ilikectrlmusic/auto_ip/contents/781_result/2025-02-19.txt (Caused by ConnectTimeoutError(<urllib3.connection.HTTPSConnection object at 0x000001ED25928FE0>, 'Connection to api.github.com timed out. (connect timeout=None)'))

Error during execution: Traceback (most recent call last):
  File "urllib3\connection.py", line 198, in _new_conn
  File "urllib3\util\connection.py", line 85, in create_connection
  File "urllib3\util\connection.py", line 73, in create_connection
TimeoutError: [WinError 10060] 由于连接方在一段时间后没有正确答复或连接的主机没有反应，连接尝试失败。

The above exception was the direct cause of the following exception:

Traceback (most recent call last):
  File "urllib3\connectionpool.py", line 787, in urlopen
  File "urllib3\connectionpool.py", line 488, in _make_request
  File "urllib3\connectionpool.py", line 464, in _make_request
  File "urllib3\connectionpool.py", line 1093, in _validate_conn
  File "urllib3\connection.py", line 704, in connect
  File "urllib3\connection.py", line 207, in _new_conn
urllib3.exceptions.ConnectTimeoutError: (<urllib3.connection.HTTPSConnection object at 0x000001ED25928740>, 'Connection to api.github.com timed out. (connect timeout=None)')

The above exception was the direct cause of the following exception:

Traceback (most recent call last):
  File "requests\adapters.py", line 667, in send
  File "urllib3\connectionpool.py", line 841, in urlopen
  File "urllib3\util\retry.py", line 519, in increment
urllib3.exceptions.MaxRetryError: HTTPSConnectionPool(host='api.github.com', port=443): Max retries exceeded with url: /repos/Ilikectrlmusic/auto_ip/contents/781_result/2025-02-19.txt (Caused by ConnectTimeoutError(<urllib3.connection.HTTPSConnection object at 0x000001ED25928740>, 'Connection to api.github.com timed out. (connect timeout=None)'))

During handling of the above exception, another exception occurred:

Traceback (most recent call last):
  File "main.py", line 339, in <module>
  File "main.py", line 288, in upload_result
  File "requests\api.py", line 73, in get
  File "requests\api.py", line 59, in request
  File "requests\sessions.py", line 589, in request
  File "requests\sessions.py", line 703, in send
  File "requests\adapters.py", line 688, in send
requests.exceptions.ConnectTimeout: HTTPSConnectionPool(host='api.github.com', port=443): Max retries exceeded with url: /repos/Ilikectrlmusic/auto_ip/contents/781_result/2025-02-19.txt (Caused by ConnectTimeoutError(<urllib3.connection.HTTPSConnection object at 0x000001ED25928740>, 'Connection to api.github.com timed out. (connect timeout=None)'))

Error during execution: Traceback (most recent call last):
  File "urllib3\connection.py", line 198, in _new_conn
  File "urllib3\util\connection.py", line 85, in create_connection
  File "urllib3\util\connection.py", line 73, in create_connection
TimeoutError: [WinError 10060] 由于连接方在一段时间后没有正确答复或连接的主机没有反应，连接尝试失败。

The above exception was the direct cause of the following exception:

Traceback (most recent call last):
  File "urllib3\connectionpool.py", line 787, in urlopen
  File "urllib3\connectionpool.py", line 488, in _make_request
  File "urllib3\connectionpool.py", line 464, in _make_request
  File "urllib3\connectionpool.py", line 1093, in _validate_conn
  File "urllib3\connection.py", line 704, in connect
  File "urllib3\connection.py", line 207, in _new_conn
urllib3.exceptions.ConnectTimeoutError: (<urllib3.connection.HTTPSConnection object at 0x000001ED25906990>, 'Connection to api.github.com timed out. (connect timeout=None)')

The above exception was the direct cause of the following exception:

Traceback (most recent call last):
  File "requests\adapters.py", line 667, in send
  File "urllib3\connectionpool.py", line 841, in urlopen
  File "urllib3\util\retry.py", line 519, in increment
urllib3.exceptions.MaxRetryError: HTTPSConnectionPool(host='api.github.com', port=443): Max retries exceeded with url: /repos/Ilikectrlmusic/auto_ip/contents/781_result/2025-02-19.txt (Caused by ConnectTimeoutError(<urllib3.connection.HTTPSConnection object at 0x000001ED25906990>, 'Connection to api.github.com timed out. (connect timeout=None)'))

During handling of the above exception, another exception occurred:

Traceback (most recent call last):
  File "main.py", line 339, in <module>
  File "main.py", line 307, in upload_result
  File "requests\api.py", line 130, in put
  File "requests\api.py", line 59, in request
  File "requests\sessions.py", line 589, in request
  File "requests\sessions.py", line 703, in send
  File "requests\adapters.py", line 688, in send
requests.exceptions.ConnectTimeout: HTTPSConnectionPool(host='api.github.com', port=443): Max retries exceeded with url: /repos/Ilikectrlmusic/auto_ip/contents/781_result/2025-02-19.txt (Caused by ConnectTimeoutError(<urllib3.connection.HTTPSConnection object at 0x000001ED25906990>, 'Connection to api.github.com timed out. (connect timeout=None)'))

Error during execution: Traceback (most recent call last):
  File "urllib3\connection.py", line 198, in _new_conn
  File "urllib3\util\connection.py", line 85, in create_connection
  File "urllib3\util\connection.py", line 73, in create_connection
TimeoutError: [WinError 10060] 由于连接方在一段时间后没有正确答复或连接的主机没有反应，连接尝试失败。

The above exception was the direct cause of the following exception:

Traceback (most recent call last):
  File "urllib3\connectionpool.py", line 787, in urlopen
  File "urllib3\connectionpool.py", line 488, in _make_request
  File "urllib3\connectionpool.py", line 464, in _make_request
  File "urllib3\connectionpool.py", line 1093, in _validate_conn
  File "urllib3\connection.py", line 704, in connect
  File "urllib3\connection.py", line 207, in _new_conn
urllib3.exceptions.ConnectTimeoutError: (<urllib3.connection.HTTPSConnection object at 0x000001ED258F1F70>, 'Connection to api.github.com timed out. (connect timeout=None)')

The above exception was the direct cause of the following exception:

Traceback (most recent call last):
  File "requests\adapters.py", line 667, in send
  File "urllib3\connectionpool.py", line 841, in urlopen
  File "urllib3\util\retry.py", line 519, in increment
urllib3.exceptions.MaxRetryError: HTTPSConnectionPool(host='api.github.com', port=443): Max retries exceeded with url: /repos/Ilikectrlmusic/auto_ip/contents/781_result/2025-02-19.txt (Caused by ConnectTimeoutError(<urllib3.connection.HTTPSConnection object at 0x000001ED258F1F70>, 'Connection to api.github.com timed out. (connect timeout=None)'))

During handling of the above exception, another exception occurred:

Traceback (most recent call last):
  File "main.py", line 339, in <module>
  File "main.py", line 307, in upload_result
  File "requests\api.py", line 130, in put
  File "requests\api.py", line 59, in request
  File "requests\sessions.py", line 589, in request
  File "requests\sessions.py", line 703, in send
  File "requests\adapters.py", line 688, in send
requests.exceptions.ConnectTimeout: HTTPSConnectionPool(host='api.github.com', port=443): Max retries exceeded with url: /repos/Ilikectrlmusic/auto_ip/contents/781_result/2025-02-19.txt (Caused by ConnectTimeoutError(<urllib3.connection.HTTPSConnection object at 0x000001ED258F1F70>, 'Connection to api.github.com timed out. (connect timeout=None)'))

Error during execution: Traceback (most recent call last):
  File "urllib3\connection.py", line 198, in _new_conn
  File "urllib3\util\connection.py", line 85, in create_connection
  File "urllib3\util\connection.py", line 73, in create_connection
TimeoutError: [WinError 10060] 由于连接方在一段时间后没有正确答复或连接的主机没有反应，连接尝试失败。

The above exception was the direct cause of the following exception:

Traceback (most recent call last):
  File "urllib3\connectionpool.py", line 787, in urlopen
  File "urllib3\connectionpool.py", line 488, in _make_request
  File "urllib3\connectionpool.py", line 464, in _make_request
  File "urllib3\connectionpool.py", line 1093, in _validate_conn
  File "urllib3\connection.py", line 704, in connect
  File "urllib3\connection.py", line 207, in _new_conn
urllib3.exceptions.ConnectTimeoutError: (<urllib3.connection.HTTPSConnection object at 0x000001ED258F03E0>, 'Connection to api.github.com timed out. (connect timeout=None)')

The above exception was the direct cause of the following exception:

Traceback (most recent call last):
  File "requests\adapters.py", line 667, in send
  File "urllib3\connectionpool.py", line 841, in urlopen
  File "urllib3\util\retry.py", line 519, in increment
urllib3.exceptions.MaxRetryError: HTTPSConnectionPool(host='api.github.com', port=443): Max retries exceeded with url: /repos/Ilikectrlmusic/auto_ip/contents/781_result/2025-02-19.txt (Caused by ConnectTimeoutError(<urllib3.connection.HTTPSConnection object at 0x000001ED258F03E0>, 'Connection to api.github.com timed out. (connect timeout=None)'))

During handling of the above exception, another exception occurred:

Traceback (most recent call last):
  File "main.py", line 339, in <module>
  File "main.py", line 307, in upload_result
  File "requests\api.py", line 130, in put
  File "requests\api.py", line 59, in request
  File "requests\sessions.py", line 589, in request
  File "requests\sessions.py", line 703, in send
  File "requests\adapters.py", line 688, in send
requests.exceptions.ConnectTimeout: HTTPSConnectionPool(host='api.github.com', port=443): Max retries exceeded with url: /repos/Ilikectrlmusic/auto_ip/contents/781_result/2025-02-19.txt (Caused by ConnectTimeoutError(<urllib3.connection.HTTPSConnection object at 0x000001ED258F03E0>, 'Connection to api.github.com timed out. (connect timeout=None)'))

Error during execution: Traceback (most recent call last):
  File "urllib3\connection.py", line 198, in _new_conn
  File "urllib3\util\connection.py", line 85, in create_connection
  File "urllib3\util\connection.py", line 73, in create_connection
TimeoutError: [WinError 10060] 由于连接方在一段时间后没有正确答复或连接的主机没有反应，连接尝试失败。

The above exception was the direct cause of the following exception:

Traceback (most recent call last):
  File "urllib3\connectionpool.py", line 787, in urlopen
  File "urllib3\connectionpool.py", line 488, in _make_request
  File "urllib3\connectionpool.py", line 464, in _make_request
  File "urllib3\connectionpool.py", line 1093, in _validate_conn
  File "urllib3\connection.py", line 704, in connect
  File "urllib3\connection.py", line 207, in _new_conn
urllib3.exceptions.ConnectTimeoutError: (<urllib3.connection.HTTPSConnection object at 0x000001ED258F04A0>, 'Connection to api.github.com timed out. (connect timeout=None)')

The above exception was the direct cause of the following exception:

Traceback (most recent call last):
  File "requests\adapters.py", line 667, in send
  File "urllib3\connectionpool.py", line 841, in urlopen
  File "urllib3\util\retry.py", line 519, in increment
urllib3.exceptions.MaxRetryError: HTTPSConnectionPool(host='api.github.com', port=443): Max retries exceeded with url: /repos/Ilikectrlmusic/auto_ip/contents/781_result/2025-02-19.txt (Caused by ConnectTimeoutError(<urllib3.connection.HTTPSConnection object at 0x000001ED258F04A0>, 'Connection to api.github.com timed out. (connect timeout=None)'))

During handling of the above exception, another exception occurred:

Traceback (most recent call last):
  File "main.py", line 339, in <module>
  File "main.py", line 307, in upload_result
  File "requests\api.py", line 130, in put
  File "requests\api.py", line 59, in request
  File "requests\sessions.py", line 589, in request
  File "requests\sessions.py", line 703, in send
  File "requests\adapters.py", line 688, in send
requests.exceptions.ConnectTimeout: HTTPSConnectionPool(host='api.github.com', port=443): Max retries exceeded with url: /repos/Ilikectrlmusic/auto_ip/contents/781_result/2025-02-19.txt (Caused by ConnectTimeoutError(<urllib3.connection.HTTPSConnection object at 0x000001ED258F04A0>, 'Connection to api.github.com timed out. (connect timeout=None)'))

Error during execution: Traceback (most recent call last):
  File "urllib3\connection.py", line 198, in _new_conn
  File "urllib3\util\connection.py", line 85, in create_connection
  File "urllib3\util\connection.py", line 73, in create_connection
TimeoutError: [WinError 10060] 由于连接方在一段时间后没有正确答复或连接的主机没有反应，连接尝试失败。

The above exception was the direct cause of the following exception:

Traceback (most recent call last):
  File "urllib3\connectionpool.py", line 787, in urlopen
  File "urllib3\connectionpool.py", line 488, in _make_request
  File "urllib3\connectionpool.py", line 464, in _make_request
  File "urllib3\connectionpool.py", line 1093, in _validate_conn
  File "urllib3\connection.py", line 704, in connect
  File "urllib3\connection.py", line 207, in _new_conn
urllib3.exceptions.ConnectTimeoutError: (<urllib3.connection.HTTPSConnection object at 0x000001ED258F1430>, 'Connection to api.github.com timed out. (connect timeout=None)')

The above exception was the direct cause of the following exception:

Traceback (most recent call last):
  File "requests\adapters.py", line 667, in send
  File "urllib3\connectionpool.py", line 841, in urlopen
  File "urllib3\util\retry.py", line 519, in increment
urllib3.exceptions.MaxRetryError: HTTPSConnectionPool(host='api.github.com', port=443): Max retries exceeded with url: /repos/Ilikectrlmusic/auto_ip/contents/781_result/2025-02-19.txt (Caused by ConnectTimeoutError(<urllib3.connection.HTTPSConnection object at 0x000001ED258F1430>, 'Connection to api.github.com timed out. (connect timeout=None)'))

During handling of the above exception, another exception occurred:

Traceback (most recent call last):
  File "main.py", line 339, in <module>
  File "main.py", line 288, in upload_result
  File "requests\api.py", line 73, in get
  File "requests\api.py", line 59, in request
  File "requests\sessions.py", line 589, in request
  File "requests\sessions.py", line 703, in send
  File "requests\adapters.py", line 688, in send
requests.exceptions.ConnectTimeout: HTTPSConnectionPool(host='api.github.com', port=443): Max retries exceeded with url: /repos/Ilikectrlmusic/auto_ip/contents/781_result/2025-02-19.txt (Caused by ConnectTimeoutError(<urllib3.connection.HTTPSConnection object at 0x000001ED258F1430>, 'Connection to api.github.com timed out. (connect timeout=None)'))

Error during execution: Traceback (most recent call last):
  File "urllib3\connection.py", line 198, in _new_conn
  File "urllib3\util\connection.py", line 85, in create_connection
  File "urllib3\util\connection.py", line 73, in create_connection
TimeoutError: [WinError 10060] 由于连接方在一段时间后没有正确答复或连接的主机没有反应，连接尝试失败。

The above exception was the direct cause of the following exception:

Traceback (most recent call last):
  File "urllib3\connectionpool.py", line 787, in urlopen
  File "urllib3\connectionpool.py", line 488, in _make_request
  File "urllib3\connectionpool.py", line 464, in _make_request
  File "urllib3\connectionpool.py", line 1093, in _validate_conn
  File "urllib3\connection.py", line 704, in connect
  File "urllib3\connection.py", line 207, in _new_conn
urllib3.exceptions.ConnectTimeoutError: (<urllib3.connection.HTTPSConnection object at 0x000001ED2592BDA0>, 'Connection to api.github.com timed out. (connect timeout=None)')

The above exception was the direct cause of the following exception:

Traceback (most recent call last):
  File "requests\adapters.py", line 667, in send
  File "urllib3\connectionpool.py", line 841, in urlopen
  File "urllib3\util\retry.py", line 519, in increment
urllib3.exceptions.MaxRetryError: HTTPSConnectionPool(host='api.github.com', port=443): Max retries exceeded with url: /repos/Ilikectrlmusic/auto_ip/contents/781_result/2025-02-19.txt (Caused by ConnectTimeoutError(<urllib3.connection.HTTPSConnection object at 0x000001ED2592BDA0>, 'Connection to api.github.com timed out. (connect timeout=None)'))

During handling of the above exception, another exception occurred:

Traceback (most recent call last):
  File "main.py", line 339, in <module>
  File "main.py", line 307, in upload_result
  File "requests\api.py", line 130, in put
  File "requests\api.py", line 59, in request
  File "requests\sessions.py", line 589, in request
  File "requests\sessions.py", line 703, in send
  File "requests\adapters.py", line 688, in send
requests.exceptions.ConnectTimeout: HTTPSConnectionPool(host='api.github.com', port=443): Max retries exceeded with url: /repos/Ilikectrlmusic/auto_ip/contents/781_result/2025-02-19.txt (Caused by ConnectTimeoutError(<urllib3.connection.HTTPSConnection object at 0x000001ED2592BDA0>, 'Connection to api.github.com timed out. (connect timeout=None)'))

Error during execution: Traceback (most recent call last):
  File "urllib3\connection.py", line 198, in _new_conn
  File "urllib3\util\connection.py", line 85, in create_connection
  File "urllib3\util\connection.py", line 73, in create_connection
TimeoutError: [WinError 10060] 由于连接方在一段时间后没有正确答复或连接的主机没有反应，连接尝试失败。

The above exception was the direct cause of the following exception:

Traceback (most recent call last):
  File "urllib3\connectionpool.py", line 787, in urlopen
  File "urllib3\connectionpool.py", line 488, in _make_request
  File "urllib3\connectionpool.py", line 464, in _make_request
  File "urllib3\connectionpool.py", line 1093, in _validate_conn
  File "urllib3\connection.py", line 704, in connect
  File "urllib3\connection.py", line 207, in _new_conn
urllib3.exceptions.ConnectTimeoutError: (<urllib3.connection.HTTPSConnection object at 0x000001ED25929940>, 'Connection to api.github.com timed out. (connect timeout=None)')

The above exception was the direct cause of the following exception:

Traceback (most recent call last):
  File "requests\adapters.py", line 667, in send
  File "urllib3\connectionpool.py", line 841, in urlopen
  File "urllib3\util\retry.py", line 519, in increment
urllib3.exceptions.MaxRetryError: HTTPSConnectionPool(host='api.github.com', port=443): Max retries exceeded with url: /repos/Ilikectrlmusic/auto_ip/contents/781_result/2025-02-19.txt (Caused by ConnectTimeoutError(<urllib3.connection.HTTPSConnection object at 0x000001ED25929940>, 'Connection to api.github.com timed out. (connect timeout=None)'))

During handling of the above exception, another exception occurred:

Traceback (most recent call last):
  File "main.py", line 339, in <module>
  File "main.py", line 288, in upload_result
  File "requests\api.py", line 73, in get
  File "requests\api.py", line 59, in request
  File "requests\sessions.py", line 589, in request
  File "requests\sessions.py", line 703, in send
  File "requests\adapters.py", line 688, in send
requests.exceptions.ConnectTimeout: HTTPSConnectionPool(host='api.github.com', port=443): Max retries exceeded with url: /repos/Ilikectrlmusic/auto_ip/contents/781_result/2025-02-19.txt (Caused by ConnectTimeoutError(<urllib3.connection.HTTPSConnection object at 0x000001ED25929940>, 'Connection to api.github.com timed out. (connect timeout=None)'))

Error during execution: Traceback (most recent call last):
  File "urllib3\connection.py", line 198, in _new_conn
  File "urllib3\util\connection.py", line 85, in create_connection
  File "urllib3\util\connection.py", line 73, in create_connection
TimeoutError: [WinError 10060] 由于连接方在一段时间后没有正确答复或连接的主机没有反应，连接尝试失败。

The above exception was the direct cause of the following exception:

Traceback (most recent call last):
  File "urllib3\connectionpool.py", line 787, in urlopen
  File "urllib3\connectionpool.py", line 488, in _make_request
  File "urllib3\connectionpool.py", line 464, in _make_request
  File "urllib3\connectionpool.py", line 1093, in _validate_conn
  File "urllib3\connection.py", line 704, in connect
  File "urllib3\connection.py", line 207, in _new_conn
urllib3.exceptions.ConnectTimeoutError: (<urllib3.connection.HTTPSConnection object at 0x000001ED258F03E0>, 'Connection to api.github.com timed out. (connect timeout=None)')

The above exception was the direct cause of the following exception:

Traceback (most recent call last):
  File "requests\adapters.py", line 667, in send
  File "urllib3\connectionpool.py", line 841, in urlopen
  File "urllib3\util\retry.py", line 519, in increment
urllib3.exceptions.MaxRetryError: HTTPSConnectionPool(host='api.github.com', port=443): Max retries exceeded with url: /repos/Ilikectrlmusic/auto_ip/contents/781_result/2025-02-19.txt (Caused by ConnectTimeoutError(<urllib3.connection.HTTPSConnection object at 0x000001ED258F03E0>, 'Connection to api.github.com timed out. (connect timeout=None)'))

During handling of the above exception, another exception occurred:

Traceback (most recent call last):
  File "main.py", line 339, in <module>
  File "main.py", line 288, in upload_result
  File "requests\api.py", line 73, in get
  File "requests\api.py", line 59, in request
  File "requests\sessions.py", line 589, in request
  File "requests\sessions.py", line 703, in send
  File "requests\adapters.py", line 688, in send
requests.exceptions.ConnectTimeout: HTTPSConnectionPool(host='api.github.com', port=443): Max retries exceeded with url: /repos/Ilikectrlmusic/auto_ip/contents/781_result/2025-02-19.txt (Caused by ConnectTimeoutError(<urllib3.connection.HTTPSConnection object at 0x000001ED258F03E0>, 'Connection to api.github.com timed out. (connect timeout=None)'))

Error during execution: Traceback (most recent call last):
  File "urllib3\connection.py", line 198, in _new_conn
  File "urllib3\util\connection.py", line 85, in create_connection
  File "urllib3\util\connection.py", line 73, in create_connection
TimeoutError: [WinError 10060] 由于连接方在一段时间后没有正确答复或连接的主机没有反应，连接尝试失败。

The above exception was the direct cause of the following exception:

Traceback (most recent call last):
  File "urllib3\connectionpool.py", line 787, in urlopen
  File "urllib3\connectionpool.py", line 488, in _make_request
  File "urllib3\connectionpool.py", line 464, in _make_request
  File "urllib3\connectionpool.py", line 1093, in _validate_conn
  File "urllib3\connection.py", line 704, in connect
  File "urllib3\connection.py", line 207, in _new_conn
urllib3.exceptions.ConnectTimeoutError: (<urllib3.connection.HTTPSConnection object at 0x000001ED25882B10>, 'Connection to api.github.com timed out. (connect timeout=None)')

The above exception was the direct cause of the following exception:

Traceback (most recent call last):
  File "requests\adapters.py", line 667, in send
  File "urllib3\connectionpool.py", line 841, in urlopen
  File "urllib3\util\retry.py", line 519, in increment
urllib3.exceptions.MaxRetryError: HTTPSConnectionPool(host='api.github.com', port=443): Max retries exceeded with url: /repos/Ilikectrlmusic/auto_ip/contents/781_result/2025-02-19.txt (Caused by ConnectTimeoutError(<urllib3.connection.HTTPSConnection object at 0x000001ED25882B10>, 'Connection to api.github.com timed out. (connect timeout=None)'))

During handling of the above exception, another exception occurred:

Traceback (most recent call last):
  File "main.py", line 339, in <module>
  File "main.py", line 288, in upload_result
  File "requests\api.py", line 73, in get
  File "requests\api.py", line 59, in request
  File "requests\sessions.py", line 589, in request
  File "requests\sessions.py", line 703, in send
  File "requests\adapters.py", line 688, in send
requests.exceptions.ConnectTimeout: HTTPSConnectionPool(host='api.github.com', port=443): Max retries exceeded with url: /repos/Ilikectrlmusic/auto_ip/contents/781_result/2025-02-19.txt (Caused by ConnectTimeoutError(<urllib3.connection.HTTPSConnection object at 0x000001ED25882B10>, 'Connection to api.github.com timed out. (connect timeout=None)'))

Error during execution: Traceback (most recent call last):
  File "urllib3\connection.py", line 198, in _new_conn
  File "urllib3\util\connection.py", line 85, in create_connection
  File "urllib3\util\connection.py", line 73, in create_connection
TimeoutError: [WinError 10060] 由于连接方在一段时间后没有正确答复或连接的主机没有反应，连接尝试失败。

The above exception was the direct cause of the following exception:

Traceback (most recent call last):
  File "urllib3\connectionpool.py", line 787, in urlopen
  File "urllib3\connectionpool.py", line 488, in _make_request
  File "urllib3\connectionpool.py", line 464, in _make_request
  File "urllib3\connectionpool.py", line 1093, in _validate_conn
  File "urllib3\connection.py", line 704, in connect
  File "urllib3\connection.py", line 207, in _new_conn
urllib3.exceptions.ConnectTimeoutError: (<urllib3.connection.HTTPSConnection object at 0x000001ED259294F0>, 'Connection to api.github.com timed out. (connect timeout=None)')

The above exception was the direct cause of the following exception:

Traceback (most recent call last):
  File "requests\adapters.py", line 667, in send
  File "urllib3\connectionpool.py", line 841, in urlopen
  File "urllib3\util\retry.py", line 519, in increment
urllib3.exceptions.MaxRetryError: HTTPSConnectionPool(host='api.github.com', port=443): Max retries exceeded with url: /repos/Ilikectrlmusic/auto_ip/contents/781_result/2025-02-19.txt (Caused by ConnectTimeoutError(<urllib3.connection.HTTPSConnection object at 0x000001ED259294F0>, 'Connection to api.github.com timed out. (connect timeout=None)'))

During handling of the above exception, another exception occurred:

Traceback (most recent call last):
  File "main.py", line 339, in <module>
  File "main.py", line 288, in upload_result
  File "requests\api.py", line 73, in get
  File "requests\api.py", line 59, in request
  File "requests\sessions.py", line 589, in request
  File "requests\sessions.py", line 703, in send
  File "requests\adapters.py", line 688, in send
requests.exceptions.ConnectTimeout: HTTPSConnectionPool(host='api.github.com', port=443): Max retries exceeded with url: /repos/Ilikectrlmusic/auto_ip/contents/781_result/2025-02-19.txt (Caused by ConnectTimeoutError(<urllib3.connection.HTTPSConnection object at 0x000001ED259294F0>, 'Connection to api.github.com timed out. (connect timeout=None)'))

Error uploading log: HTTPSConnectionPool(host='api.github.com', port=443): Max retries exceeded with url: /repos/Ilikectrlmusic/auto_ip/contents/log/2025-02-19.log (Caused by ConnectTimeoutError(<urllib3.connection.HTTPSConnection object at 0x000001ED258F3E90>, 'Connection to api.github.com timed out. (connect timeout=None)'))
Error during execution: Traceback (most recent call last):
  File "urllib3\connection.py", line 198, in _new_conn
  File "urllib3\util\connection.py", line 85, in create_connection
  File "urllib3\util\connection.py", line 73, in create_connection
TimeoutError: [WinError 10060] 由于连接方在一段时间后没有正确答复或连接的主机没有反应，连接尝试失败。

The above exception was the direct cause of the following exception:

Traceback (most recent call last):
  File "urllib3\connectionpool.py", line 787, in urlopen
  File "urllib3\connectionpool.py", line 488, in _make_request
  File "urllib3\connectionpool.py", line 464, in _make_request
  File "urllib3\connectionpool.py", line 1093, in _validate_conn
  File "urllib3\connection.py", line 704, in connect
  File "urllib3\connection.py", line 207, in _new_conn
urllib3.exceptions.ConnectTimeoutError: (<urllib3.connection.HTTPSConnection object at 0x000001ED258F34D0>, 'Connection to api.github.com timed out. (connect timeout=None)')

The above exception was the direct cause of the following exception:

Traceback (most recent call last):
  File "requests\adapters.py", line 667, in send
  File "urllib3\connectionpool.py", line 841, in urlopen
  File "urllib3\util\retry.py", line 519, in increment
urllib3.exceptions.MaxRetryError: HTTPSConnectionPool(host='api.github.com', port=443): Max retries exceeded with url: /repos/Ilikectrlmusic/auto_ip/contents/781_result/2025-02-19.txt (Caused by ConnectTimeoutError(<urllib3.connection.HTTPSConnection object at 0x000001ED258F34D0>, 'Connection to api.github.com timed out. (connect timeout=None)'))

During handling of the above exception, another exception occurred:

Traceback (most recent call last):
  File "main.py", line 339, in <module>
  File "main.py", line 288, in upload_result
  File "requests\api.py", line 73, in get
  File "requests\api.py", line 59, in request
  File "requests\sessions.py", line 589, in request
  File "requests\sessions.py", line 703, in send
  File "requests\adapters.py", line 688, in send
requests.exceptions.ConnectTimeout: HTTPSConnectionPool(host='api.github.com', port=443): Max retries exceeded with url: /repos/Ilikectrlmusic/auto_ip/contents/781_result/2025-02-19.txt (Caused by ConnectTimeoutError(<urllib3.connection.HTTPSConnection object at 0x000001ED258F34D0>, 'Connection to api.github.com timed out. (connect timeout=None)'))

Error during execution: Traceback (most recent call last):
  File "urllib3\connection.py", line 198, in _new_conn
  File "urllib3\util\connection.py", line 85, in create_connection
  File "urllib3\util\connection.py", line 73, in create_connection
TimeoutError: [WinError 10060] 由于连接方在一段时间后没有正确答复或连接的主机没有反应，连接尝试失败。

The above exception was the direct cause of the following exception:

Traceback (most recent call last):
  File "urllib3\connectionpool.py", line 787, in urlopen
  File "urllib3\connectionpool.py", line 488, in _make_request
  File "urllib3\connectionpool.py", line 464, in _make_request
  File "urllib3\connectionpool.py", line 1093, in _validate_conn
  File "urllib3\connection.py", line 704, in connect
  File "urllib3\connection.py", line 207, in _new_conn
urllib3.exceptions.ConnectTimeoutError: (<urllib3.connection.HTTPSConnection object at 0x000001ED2592A7E0>, 'Connection to api.github.com timed out. (connect timeout=None)')

The above exception was the direct cause of the following exception:

Traceback (most recent call last):
  File "requests\adapters.py", line 667, in send
  File "urllib3\connectionpool.py", line 841, in urlopen
  File "urllib3\util\retry.py", line 519, in increment
urllib3.exceptions.MaxRetryError: HTTPSConnectionPool(host='api.github.com', port=443): Max retries exceeded with url: /repos/Ilikectrlmusic/auto_ip/contents/781_result/2025-02-19.txt (Caused by ConnectTimeoutError(<urllib3.connection.HTTPSConnection object at 0x000001ED2592A7E0>, 'Connection to api.github.com timed out. (connect timeout=None)'))

During handling of the above exception, another exception occurred:

Traceback (most recent call last):
  File "main.py", line 339, in <module>
  File "main.py", line 288, in upload_result
  File "requests\api.py", line 73, in get
  File "requests\api.py", line 59, in request
  File "requests\sessions.py", line 589, in request
  File "requests\sessions.py", line 703, in send
  File "requests\adapters.py", line 688, in send
requests.exceptions.ConnectTimeout: HTTPSConnectionPool(host='api.github.com', port=443): Max retries exceeded with url: /repos/Ilikectrlmusic/auto_ip/contents/781_result/2025-02-19.txt (Caused by ConnectTimeoutError(<urllib3.connection.HTTPSConnection object at 0x000001ED2592A7E0>, 'Connection to api.github.com timed out. (connect timeout=None)'))

Error during execution: Traceback (most recent call last):
  File "urllib3\connection.py", line 198, in _new_conn
  File "urllib3\util\connection.py", line 85, in create_connection
  File "urllib3\util\connection.py", line 73, in create_connection
TimeoutError: [WinError 10060] 由于连接方在一段时间后没有正确答复或连接的主机没有反应，连接尝试失败。

The above exception was the direct cause of the following exception:

Traceback (most recent call last):
  File "urllib3\connectionpool.py", line 787, in urlopen
  File "urllib3\connectionpool.py", line 488, in _make_request
  File "urllib3\connectionpool.py", line 464, in _make_request
  File "urllib3\connectionpool.py", line 1093, in _validate_conn
  File "urllib3\connection.py", line 704, in connect
  File "urllib3\connection.py", line 207, in _new_conn
urllib3.exceptions.ConnectTimeoutError: (<urllib3.connection.HTTPSConnection object at 0x000001ED258F4740>, 'Connection to api.github.com timed out. (connect timeout=None)')

The above exception was the direct cause of the following exception:

Traceback (most recent call last):
  File "requests\adapters.py", line 667, in send
  File "urllib3\connectionpool.py", line 841, in urlopen
  File "urllib3\util\retry.py", line 519, in increment
urllib3.exceptions.MaxRetryError: HTTPSConnectionPool(host='api.github.com', port=443): Max retries exceeded with url: /repos/Ilikectrlmusic/auto_ip/contents/781_result/2025-02-19.txt (Caused by ConnectTimeoutError(<urllib3.connection.HTTPSConnection object at 0x000001ED258F4740>, 'Connection to api.github.com timed out. (connect timeout=None)'))

During handling of the above exception, another exception occurred:

Traceback (most recent call last):
  File "main.py", line 339, in <module>
  File "main.py", line 288, in upload_result
  File "requests\api.py", line 73, in get
  File "requests\api.py", line 59, in request
  File "requests\sessions.py", line 589, in request
  File "requests\sessions.py", line 703, in send
  File "requests\adapters.py", line 688, in send
requests.exceptions.ConnectTimeout: HTTPSConnectionPool(host='api.github.com', port=443): Max retries exceeded with url: /repos/Ilikectrlmusic/auto_ip/contents/781_result/2025-02-19.txt (Caused by ConnectTimeoutError(<urllib3.connection.HTTPSConnection object at 0x000001ED258F4740>, 'Connection to api.github.com timed out. (connect timeout=None)'))

Error during execution: Traceback (most recent call last):
  File "urllib3\connection.py", line 198, in _new_conn
  File "urllib3\util\connection.py", line 85, in create_connection
  File "urllib3\util\connection.py", line 73, in create_connection
TimeoutError: [WinError 10060] 由于连接方在一段时间后没有正确答复或连接的主机没有反应，连接尝试失败。

The above exception was the direct cause of the following exception:

Traceback (most recent call last):
  File "urllib3\connectionpool.py", line 787, in urlopen
  File "urllib3\connectionpool.py", line 488, in _make_request
  File "urllib3\connectionpool.py", line 464, in _make_request
  File "urllib3\connectionpool.py", line 1093, in _validate_conn
  File "urllib3\connection.py", line 704, in connect
  File "urllib3\connection.py", line 207, in _new_conn
urllib3.exceptions.ConnectTimeoutError: (<urllib3.connection.HTTPSConnection object at 0x000001ED258F38F0>, 'Connection to api.github.com timed out. (connect timeout=None)')

The above exception was the direct cause of the following exception:

Traceback (most recent call last):
  File "requests\adapters.py", line 667, in send
  File "urllib3\connectionpool.py", line 841, in urlopen
  File "urllib3\util\retry.py", line 519, in increment
urllib3.exceptions.MaxRetryError: HTTPSConnectionPool(host='api.github.com', port=443): Max retries exceeded with url: /repos/Ilikectrlmusic/auto_ip/contents/781_result/2025-02-19.txt (Caused by ConnectTimeoutError(<urllib3.connection.HTTPSConnection object at 0x000001ED258F38F0>, 'Connection to api.github.com timed out. (connect timeout=None)'))

During handling of the above exception, another exception occurred:

Traceback (most recent call last):
  File "main.py", line 339, in <module>
  File "main.py", line 288, in upload_result
  File "requests\api.py", line 73, in get
  File "requests\api.py", line 59, in request
  File "requests\sessions.py", line 589, in request
  File "requests\sessions.py", line 703, in send
  File "requests\adapters.py", line 688, in send
requests.exceptions.ConnectTimeout: HTTPSConnectionPool(host='api.github.com', port=443): Max retries exceeded with url: /repos/Ilikectrlmusic/auto_ip/contents/781_result/2025-02-19.txt (Caused by ConnectTimeoutError(<urllib3.connection.HTTPSConnection object at 0x000001ED258F38F0>, 'Connection to api.github.com timed out. (connect timeout=None)'))

Error during execution: Traceback (most recent call last):
  File "urllib3\connection.py", line 198, in _new_conn
  File "urllib3\util\connection.py", line 85, in create_connection
  File "urllib3\util\connection.py", line 73, in create_connection
TimeoutError: [WinError 10060] 由于连接方在一段时间后没有正确答复或连接的主机没有反应，连接尝试失败。

The above exception was the direct cause of the following exception:

Traceback (most recent call last):
  File "urllib3\connectionpool.py", line 787, in urlopen
  File "urllib3\connectionpool.py", line 488, in _make_request
  File "urllib3\connectionpool.py", line 464, in _make_request
  File "urllib3\connectionpool.py", line 1093, in _validate_conn
  File "urllib3\connection.py", line 704, in connect
  File "urllib3\connection.py", line 207, in _new_conn
urllib3.exceptions.ConnectTimeoutError: (<urllib3.connection.HTTPSConnection object at 0x000001ED259284A0>, 'Connection to api.github.com timed out. (connect timeout=None)')

The above exception was the direct cause of the following exception:

Traceback (most recent call last):
  File "requests\adapters.py", line 667, in send
  File "urllib3\connectionpool.py", line 841, in urlopen
  File "urllib3\util\retry.py", line 519, in increment
urllib3.exceptions.MaxRetryError: HTTPSConnectionPool(host='api.github.com', port=443): Max retries exceeded with url: /repos/Ilikectrlmusic/auto_ip/contents/781_result/2025-02-19.txt (Caused by ConnectTimeoutError(<urllib3.connection.HTTPSConnection object at 0x000001ED259284A0>, 'Connection to api.github.com timed out. (connect timeout=None)'))

During handling of the above exception, another exception occurred:

Traceback (most recent call last):
  File "main.py", line 339, in <module>
  File "main.py", line 288, in upload_result
  File "requests\api.py", line 73, in get
  File "requests\api.py", line 59, in request
  File "requests\sessions.py", line 589, in request
  File "requests\sessions.py", line 703, in send
  File "requests\adapters.py", line 688, in send
requests.exceptions.ConnectTimeout: HTTPSConnectionPool(host='api.github.com', port=443): Max retries exceeded with url: /repos/Ilikectrlmusic/auto_ip/contents/781_result/2025-02-19.txt (Caused by ConnectTimeoutError(<urllib3.connection.HTTPSConnection object at 0x000001ED259284A0>, 'Connection to api.github.com timed out. (connect timeout=None)'))

Error during execution: Traceback (most recent call last):
  File "urllib3\connection.py", line 198, in _new_conn
  File "urllib3\util\connection.py", line 85, in create_connection
  File "urllib3\util\connection.py", line 73, in create_connection
TimeoutError: [WinError 10060] 由于连接方在一段时间后没有正确答复或连接的主机没有反应，连接尝试失败。

The above exception was the direct cause of the following exception:

Traceback (most recent call last):
  File "urllib3\connectionpool.py", line 787, in urlopen
  File "urllib3\connectionpool.py", line 488, in _make_request
  File "urllib3\connectionpool.py", line 464, in _make_request
  File "urllib3\connectionpool.py", line 1093, in _validate_conn
  File "urllib3\connection.py", line 704, in connect
  File "urllib3\connection.py", line 207, in _new_conn
urllib3.exceptions.ConnectTimeoutError: (<urllib3.connection.HTTPSConnection object at 0x000001ED259295B0>, 'Connection to api.github.com timed out. (connect timeout=None)')

The above exception was the direct cause of the following exception:

Traceback (most recent call last):
  File "requests\adapters.py", line 667, in send
  File "urllib3\connectionpool.py", line 841, in urlopen
  File "urllib3\util\retry.py", line 519, in increment
urllib3.exceptions.MaxRetryError: HTTPSConnectionPool(host='api.github.com', port=443): Max retries exceeded with url: /repos/Ilikectrlmusic/auto_ip/contents/781_result/2025-02-19.txt (Caused by ConnectTimeoutError(<urllib3.connection.HTTPSConnection object at 0x000001ED259295B0>, 'Connection to api.github.com timed out. (connect timeout=None)'))

During handling of the above exception, another exception occurred:

Traceback (most recent call last):
  File "main.py", line 339, in <module>
  File "main.py", line 288, in upload_result
  File "requests\api.py", line 73, in get
  File "requests\api.py", line 59, in request
  File "requests\sessions.py", line 589, in request
  File "requests\sessions.py", line 703, in send
  File "requests\adapters.py", line 688, in send
requests.exceptions.ConnectTimeout: HTTPSConnectionPool(host='api.github.com', port=443): Max retries exceeded with url: /repos/Ilikectrlmusic/auto_ip/contents/781_result/2025-02-19.txt (Caused by ConnectTimeoutError(<urllib3.connection.HTTPSConnection object at 0x000001ED259295B0>, 'Connection to api.github.com timed out. (connect timeout=None)'))

Error during execution: Traceback (most recent call last):
  File "urllib3\connection.py", line 198, in _new_conn
  File "urllib3\util\connection.py", line 85, in create_connection
  File "urllib3\util\connection.py", line 73, in create_connection
TimeoutError: [WinError 10060] 由于连接方在一段时间后没有正确答复或连接的主机没有反应，连接尝试失败。

The above exception was the direct cause of the following exception:

Traceback (most recent call last):
  File "urllib3\connectionpool.py", line 787, in urlopen
  File "urllib3\connectionpool.py", line 488, in _make_request
  File "urllib3\connectionpool.py", line 464, in _make_request
  File "urllib3\connectionpool.py", line 1093, in _validate_conn
  File "urllib3\connection.py", line 704, in connect
  File "urllib3\connection.py", line 207, in _new_conn
urllib3.exceptions.ConnectTimeoutError: (<urllib3.connection.HTTPSConnection object at 0x000001ED258F2C00>, 'Connection to api.github.com timed out. (connect timeout=None)')

The above exception was the direct cause of the following exception:

Traceback (most recent call last):
  File "requests\adapters.py", line 667, in send
  File "urllib3\connectionpool.py", line 841, in urlopen
  File "urllib3\util\retry.py", line 519, in increment
urllib3.exceptions.MaxRetryError: HTTPSConnectionPool(host='api.github.com', port=443): Max retries exceeded with url: /repos/Ilikectrlmusic/auto_ip/contents/781_result/2025-02-19.txt (Caused by ConnectTimeoutError(<urllib3.connection.HTTPSConnection object at 0x000001ED258F2C00>, 'Connection to api.github.com timed out. (connect timeout=None)'))

During handling of the above exception, another exception occurred:

Traceback (most recent call last):
  File "main.py", line 339, in <module>
  File "main.py", line 288, in upload_result
  File "requests\api.py", line 73, in get
  File "requests\api.py", line 59, in request
  File "requests\sessions.py", line 589, in request
  File "requests\sessions.py", line 703, in send
  File "requests\adapters.py", line 688, in send
requests.exceptions.ConnectTimeout: HTTPSConnectionPool(host='api.github.com', port=443): Max retries exceeded with url: /repos/Ilikectrlmusic/auto_ip/contents/781_result/2025-02-19.txt (Caused by ConnectTimeoutError(<urllib3.connection.HTTPSConnection object at 0x000001ED258F2C00>, 'Connection to api.github.com timed out. (connect timeout=None)'))

Error during execution: Traceback (most recent call last):
  File "urllib3\connection.py", line 198, in _new_conn
  File "urllib3\util\connection.py", line 85, in create_connection
  File "urllib3\util\connection.py", line 73, in create_connection
TimeoutError: [WinError 10060] 由于连接方在一段时间后没有正确答复或连接的主机没有反应，连接尝试失败。

The above exception was the direct cause of the following exception:

Traceback (most recent call last):
  File "urllib3\connectionpool.py", line 787, in urlopen
  File "urllib3\connectionpool.py", line 488, in _make_request
  File "urllib3\connectionpool.py", line 464, in _make_request
  File "urllib3\connectionpool.py", line 1093, in _validate_conn
  File "urllib3\connection.py", line 704, in connect
  File "urllib3\connection.py", line 207, in _new_conn
urllib3.exceptions.ConnectTimeoutError: (<urllib3.connection.HTTPSConnection object at 0x000001ED258F0C20>, 'Connection to api.github.com timed out. (connect timeout=None)')

The above exception was the direct cause of the following exception:

Traceback (most recent call last):
  File "requests\adapters.py", line 667, in send
  File "urllib3\connectionpool.py", line 841, in urlopen
  File "urllib3\util\retry.py", line 519, in increment
urllib3.exceptions.MaxRetryError: HTTPSConnectionPool(host='api.github.com', port=443): Max retries exceeded with url: /repos/Ilikectrlmusic/auto_ip/contents/781_result/2025-02-19.txt (Caused by ConnectTimeoutError(<urllib3.connection.HTTPSConnection object at 0x000001ED258F0C20>, 'Connection to api.github.com timed out. (connect timeout=None)'))

During handling of the above exception, another exception occurred:

Traceback (most recent call last):
  File "main.py", line 339, in <module>
  File "main.py", line 307, in upload_result
  File "requests\api.py", line 130, in put
  File "requests\api.py", line 59, in request
  File "requests\sessions.py", line 589, in request
  File "requests\sessions.py", line 703, in send
  File "requests\adapters.py", line 688, in send
requests.exceptions.ConnectTimeout: HTTPSConnectionPool(host='api.github.com', port=443): Max retries exceeded with url: /repos/Ilikectrlmusic/auto_ip/contents/781_result/2025-02-19.txt (Caused by ConnectTimeoutError(<urllib3.connection.HTTPSConnection object at 0x000001ED258F0C20>, 'Connection to api.github.com timed out. (connect timeout=None)'))

Error uploading log: HTTPSConnectionPool(host='api.github.com', port=443): Max retries exceeded with url: /repos/Ilikectrlmusic/auto_ip/contents/log/2025-02-19.log (Caused by ConnectTimeoutError(<urllib3.connection.HTTPSConnection object at 0x000001ED25929340>, 'Connection to api.github.com timed out. (connect timeout=None)'))
Error during execution: Traceback (most recent call last):
  File "urllib3\connection.py", line 198, in _new_conn
  File "urllib3\util\connection.py", line 85, in create_connection
  File "urllib3\util\connection.py", line 73, in create_connection
TimeoutError: [WinError 10060] 由于连接方在一段时间后没有正确答复或连接的主机没有反应，连接尝试失败。

The above exception was the direct cause of the following exception:

Traceback (most recent call last):
  File "urllib3\connectionpool.py", line 787, in urlopen
  File "urllib3\connectionpool.py", line 488, in _make_request
  File "urllib3\connectionpool.py", line 464, in _make_request
  File "urllib3\connectionpool.py", line 1093, in _validate_conn
  File "urllib3\connection.py", line 704, in connect
  File "urllib3\connection.py", line 207, in _new_conn
urllib3.exceptions.ConnectTimeoutError: (<urllib3.connection.HTTPSConnection object at 0x000001ED258F3B30>, 'Connection to api.github.com timed out. (connect timeout=None)')

The above exception was the direct cause of the following exception:

Traceback (most recent call last):
  File "requests\adapters.py", line 667, in send
  File "urllib3\connectionpool.py", line 841, in urlopen
  File "urllib3\util\retry.py", line 519, in increment
urllib3.exceptions.MaxRetryError: HTTPSConnectionPool(host='api.github.com', port=443): Max retries exceeded with url: /repos/Ilikectrlmusic/auto_ip/contents/781_result/2025-02-19.txt (Caused by ConnectTimeoutError(<urllib3.connection.HTTPSConnection object at 0x000001ED258F3B30>, 'Connection to api.github.com timed out. (connect timeout=None)'))

During handling of the above exception, another exception occurred:

Traceback (most recent call last):
  File "main.py", line 339, in <module>
  File "main.py", line 307, in upload_result
  File "requests\api.py", line 130, in put
  File "requests\api.py", line 59, in request
  File "requests\sessions.py", line 589, in request
  File "requests\sessions.py", line 703, in send
  File "requests\adapters.py", line 688, in send
requests.exceptions.ConnectTimeout: HTTPSConnectionPool(host='api.github.com', port=443): Max retries exceeded with url: /repos/Ilikectrlmusic/auto_ip/contents/781_result/2025-02-19.txt (Caused by ConnectTimeoutError(<urllib3.connection.HTTPSConnection object at 0x000001ED258F3B30>, 'Connection to api.github.com timed out. (connect timeout=None)'))

Error during execution: Traceback (most recent call last):
  File "urllib3\connection.py", line 198, in _new_conn
  File "urllib3\util\connection.py", line 85, in create_connection
  File "urllib3\util\connection.py", line 73, in create_connection
TimeoutError: [WinError 10060] 由于连接方在一段时间后没有正确答复或连接的主机没有反应，连接尝试失败。

The above exception was the direct cause of the following exception:

Traceback (most recent call last):
  File "urllib3\connectionpool.py", line 787, in urlopen
  File "urllib3\connectionpool.py", line 488, in _make_request
  File "urllib3\connectionpool.py", line 464, in _make_request
  File "urllib3\connectionpool.py", line 1093, in _validate_conn
  File "urllib3\connection.py", line 704, in connect
  File "urllib3\connection.py", line 207, in _new_conn
urllib3.exceptions.ConnectTimeoutError: (<urllib3.connection.HTTPSConnection object at 0x000001ED258F1310>, 'Connection to api.github.com timed out. (connect timeout=None)')

The above exception was the direct cause of the following exception:

Traceback (most recent call last):
  File "requests\adapters.py", line 667, in send
  File "urllib3\connectionpool.py", line 841, in urlopen
  File "urllib3\util\retry.py", line 519, in increment
urllib3.exceptions.MaxRetryError: HTTPSConnectionPool(host='api.github.com', port=443): Max retries exceeded with url: /repos/Ilikectrlmusic/auto_ip/contents/781_result/2025-02-19.txt (Caused by ConnectTimeoutError(<urllib3.connection.HTTPSConnection object at 0x000001ED258F1310>, 'Connection to api.github.com timed out. (connect timeout=None)'))

During handling of the above exception, another exception occurred:

Traceback (most recent call last):
  File "main.py", line 339, in <module>
  File "main.py", line 307, in upload_result
  File "requests\api.py", line 130, in put
  File "requests\api.py", line 59, in request
  File "requests\sessions.py", line 589, in request
  File "requests\sessions.py", line 703, in send
  File "requests\adapters.py", line 688, in send
requests.exceptions.ConnectTimeout: HTTPSConnectionPool(host='api.github.com', port=443): Max retries exceeded with url: /repos/Ilikectrlmusic/auto_ip/contents/781_result/2025-02-19.txt (Caused by ConnectTimeoutError(<urllib3.connection.HTTPSConnection object at 0x000001ED258F1310>, 'Connection to api.github.com timed out. (connect timeout=None)'))

Error during execution: Traceback (most recent call last):
  File "urllib3\connection.py", line 198, in _new_conn
  File "urllib3\util\connection.py", line 85, in create_connection
  File "urllib3\util\connection.py", line 73, in create_connection
TimeoutError: [WinError 10060] 由于连接方在一段时间后没有正确答复或连接的主机没有反应，连接尝试失败。

The above exception was the direct cause of the following exception:

Traceback (most recent call last):
  File "urllib3\connectionpool.py", line 787, in urlopen
  File "urllib3\connectionpool.py", line 488, in _make_request
  File "urllib3\connectionpool.py", line 464, in _make_request
  File "urllib3\connectionpool.py", line 1093, in _validate_conn
  File "urllib3\connection.py", line 704, in connect
  File "urllib3\connection.py", line 207, in _new_conn
urllib3.exceptions.ConnectTimeoutError: (<urllib3.connection.HTTPSConnection object at 0x000001ED25929D90>, 'Connection to api.github.com timed out. (connect timeout=None)')

The above exception was the direct cause of the following exception:

Traceback (most recent call last):
  File "requests\adapters.py", line 667, in send
  File "urllib3\connectionpool.py", line 841, in urlopen
  File "urllib3\util\retry.py", line 519, in increment
urllib3.exceptions.MaxRetryError: HTTPSConnectionPool(host='api.github.com', port=443): Max retries exceeded with url: /repos/Ilikectrlmusic/auto_ip/contents/781_result/2025-02-19.txt (Caused by ConnectTimeoutError(<urllib3.connection.HTTPSConnection object at 0x000001ED25929D90>, 'Connection to api.github.com timed out. (connect timeout=None)'))

During handling of the above exception, another exception occurred:

Traceback (most recent call last):
  File "main.py", line 339, in <module>
  File "main.py", line 307, in upload_result
  File "requests\api.py", line 130, in put
  File "requests\api.py", line 59, in request
  File "requests\sessions.py", line 589, in request
  File "requests\sessions.py", line 703, in send
  File "requests\adapters.py", line 688, in send
requests.exceptions.ConnectTimeout: HTTPSConnectionPool(host='api.github.com', port=443): Max retries exceeded with url: /repos/Ilikectrlmusic/auto_ip/contents/781_result/2025-02-19.txt (Caused by ConnectTimeoutError(<urllib3.connection.HTTPSConnection object at 0x000001ED25929D90>, 'Connection to api.github.com timed out. (connect timeout=None)'))

Error during execution: Traceback (most recent call last):
  File "urllib3\connection.py", line 198, in _new_conn
  File "urllib3\util\connection.py", line 85, in create_connection
  File "urllib3\util\connection.py", line 73, in create_connection
TimeoutError: [WinError 10060] 由于连接方在一段时间后没有正确答复或连接的主机没有反应，连接尝试失败。

The above exception was the direct cause of the following exception:

Traceback (most recent call last):
  File "urllib3\connectionpool.py", line 787, in urlopen
  File "urllib3\connectionpool.py", line 488, in _make_request
  File "urllib3\connectionpool.py", line 464, in _make_request
  File "urllib3\connectionpool.py", line 1093, in _validate_conn
  File "urllib3\connection.py", line 704, in connect
  File "urllib3\connection.py", line 207, in _new_conn
urllib3.exceptions.ConnectTimeoutError: (<urllib3.connection.HTTPSConnection object at 0x000001ED258F60F0>, 'Connection to api.github.com timed out. (connect timeout=None)')

The above exception was the direct cause of the following exception:

Traceback (most recent call last):
  File "requests\adapters.py", line 667, in send
  File "urllib3\connectionpool.py", line 841, in urlopen
  File "urllib3\util\retry.py", line 519, in increment
urllib3.exceptions.MaxRetryError: HTTPSConnectionPool(host='api.github.com', port=443): Max retries exceeded with url: /repos/Ilikectrlmusic/auto_ip/contents/781_result/2025-02-19.txt (Caused by ConnectTimeoutError(<urllib3.connection.HTTPSConnection object at 0x000001ED258F60F0>, 'Connection to api.github.com timed out. (connect timeout=None)'))

During handling of the above exception, another exception occurred:

Traceback (most recent call last):
  File "main.py", line 339, in <module>
  File "main.py", line 307, in upload_result
  File "requests\api.py", line 130, in put
  File "requests\api.py", line 59, in request
  File "requests\sessions.py", line 589, in request
  File "requests\sessions.py", line 703, in send
  File "requests\adapters.py", line 688, in send
requests.exceptions.ConnectTimeout: HTTPSConnectionPool(host='api.github.com', port=443): Max retries exceeded with url: /repos/Ilikectrlmusic/auto_ip/contents/781_result/2025-02-19.txt (Caused by ConnectTimeoutError(<urllib3.connection.HTTPSConnection object at 0x000001ED258F60F0>, 'Connection to api.github.com timed out. (connect timeout=None)'))

Error during execution: Traceback (most recent call last):
  File "urllib3\connection.py", line 198, in _new_conn
  File "urllib3\util\connection.py", line 85, in create_connection
  File "urllib3\util\connection.py", line 73, in create_connection
TimeoutError: [WinError 10060] 由于连接方在一段时间后没有正确答复或连接的主机没有反应，连接尝试失败。

The above exception was the direct cause of the following exception:

Traceback (most recent call last):
  File "urllib3\connectionpool.py", line 787, in urlopen
  File "urllib3\connectionpool.py", line 488, in _make_request
  File "urllib3\connectionpool.py", line 464, in _make_request
  File "urllib3\connectionpool.py", line 1093, in _validate_conn
  File "urllib3\connection.py", line 704, in connect
  File "urllib3\connection.py", line 207, in _new_conn
urllib3.exceptions.ConnectTimeoutError: (<urllib3.connection.HTTPSConnection object at 0x000001ED258F5310>, 'Connection to api.github.com timed out. (connect timeout=None)')

The above exception was the direct cause of the following exception:

Traceback (most recent call last):
  File "requests\adapters.py", line 667, in send
  File "urllib3\connectionpool.py", line 841, in urlopen
  File "urllib3\util\retry.py", line 519, in increment
urllib3.exceptions.MaxRetryError: HTTPSConnectionPool(host='api.github.com', port=443): Max retries exceeded with url: /repos/Ilikectrlmusic/auto_ip/contents/781_result/2025-02-19.txt (Caused by ConnectTimeoutError(<urllib3.connection.HTTPSConnection object at 0x000001ED258F5310>, 'Connection to api.github.com timed out. (connect timeout=None)'))

During handling of the above exception, another exception occurred:

Traceback (most recent call last):
  File "main.py", line 339, in <module>
  File "main.py", line 288, in upload_result
  File "requests\api.py", line 73, in get
  File "requests\api.py", line 59, in request
  File "requests\sessions.py", line 589, in request
  File "requests\sessions.py", line 703, in send
  File "requests\adapters.py", line 688, in send
requests.exceptions.ConnectTimeout: HTTPSConnectionPool(host='api.github.com', port=443): Max retries exceeded with url: /repos/Ilikectrlmusic/auto_ip/contents/781_result/2025-02-19.txt (Caused by ConnectTimeoutError(<urllib3.connection.HTTPSConnection object at 0x000001ED258F5310>, 'Connection to api.github.com timed out. (connect timeout=None)'))

Error during execution: Traceback (most recent call last):
  File "urllib3\connection.py", line 198, in _new_conn
  File "urllib3\util\connection.py", line 85, in create_connection
  File "urllib3\util\connection.py", line 73, in create_connection
TimeoutError: [WinError 10060] 由于连接方在一段时间后没有正确答复或连接的主机没有反应，连接尝试失败。

The above exception was the direct cause of the following exception:

Traceback (most recent call last):
  File "urllib3\connectionpool.py", line 787, in urlopen
  File "urllib3\connectionpool.py", line 488, in _make_request
  File "urllib3\connectionpool.py", line 464, in _make_request
  File "urllib3\connectionpool.py", line 1093, in _validate_conn
  File "urllib3\connection.py", line 704, in connect
  File "urllib3\connection.py", line 207, in _new_conn
urllib3.exceptions.ConnectTimeoutError: (<urllib3.connection.HTTPSConnection object at 0x000001ED2592A630>, 'Connection to api.github.com timed out. (connect timeout=None)')

The above exception was the direct cause of the following exception:

Traceback (most recent call last):
  File "requests\adapters.py", line 667, in send
  File "urllib3\connectionpool.py", line 841, in urlopen
  File "urllib3\util\retry.py", line 519, in increment
urllib3.exceptions.MaxRetryError: HTTPSConnectionPool(host='api.github.com', port=443): Max retries exceeded with url: /repos/Ilikectrlmusic/auto_ip/contents/781_result/2025-02-19.txt (Caused by ConnectTimeoutError(<urllib3.connection.HTTPSConnection object at 0x000001ED2592A630>, 'Connection to api.github.com timed out. (connect timeout=None)'))

During handling of the above exception, another exception occurred:

Traceback (most recent call last):
  File "main.py", line 339, in <module>
  File "main.py", line 288, in upload_result
  File "requests\api.py", line 73, in get
  File "requests\api.py", line 59, in request
  File "requests\sessions.py", line 589, in request
  File "requests\sessions.py", line 703, in send
  File "requests\adapters.py", line 688, in send
requests.exceptions.ConnectTimeout: HTTPSConnectionPool(host='api.github.com', port=443): Max retries exceeded with url: /repos/Ilikectrlmusic/auto_ip/contents/781_result/2025-02-19.txt (Caused by ConnectTimeoutError(<urllib3.connection.HTTPSConnection object at 0x000001ED2592A630>, 'Connection to api.github.com timed out. (connect timeout=None)'))

Error during execution: Traceback (most recent call last):
  File "urllib3\connection.py", line 198, in _new_conn
  File "urllib3\util\connection.py", line 85, in create_connection
  File "urllib3\util\connection.py", line 73, in create_connection
TimeoutError: [WinError 10060] 由于连接方在一段时间后没有正确答复或连接的主机没有反应，连接尝试失败。

The above exception was the direct cause of the following exception:

Traceback (most recent call last):
  File "urllib3\connectionpool.py", line 787, in urlopen
  File "urllib3\connectionpool.py", line 488, in _make_request
  File "urllib3\connectionpool.py", line 464, in _make_request
  File "urllib3\connectionpool.py", line 1093, in _validate_conn
  File "urllib3\connection.py", line 704, in connect
  File "urllib3\connection.py", line 207, in _new_conn
urllib3.exceptions.ConnectTimeoutError: (<urllib3.connection.HTTPSConnection object at 0x000001ED258829F0>, 'Connection to api.github.com timed out. (connect timeout=None)')

The above exception was the direct cause of the following exception:

Traceback (most recent call last):
  File "requests\adapters.py", line 667, in send
  File "urllib3\connectionpool.py", line 841, in urlopen
  File "urllib3\util\retry.py", line 519, in increment
urllib3.exceptions.MaxRetryError: HTTPSConnectionPool(host='api.github.com', port=443): Max retries exceeded with url: /repos/Ilikectrlmusic/auto_ip/contents/781_result/2025-02-19.txt (Caused by ConnectTimeoutError(<urllib3.connection.HTTPSConnection object at 0x000001ED258829F0>, 'Connection to api.github.com timed out. (connect timeout=None)'))

During handling of the above exception, another exception occurred:

Traceback (most recent call last):
  File "main.py", line 339, in <module>
  File "main.py", line 288, in upload_result
  File "requests\api.py", line 73, in get
  File "requests\api.py", line 59, in request
  File "requests\sessions.py", line 589, in request
  File "requests\sessions.py", line 703, in send
  File "requests\adapters.py", line 688, in send
requests.exceptions.ConnectTimeout: HTTPSConnectionPool(host='api.github.com', port=443): Max retries exceeded with url: /repos/Ilikectrlmusic/auto_ip/contents/781_result/2025-02-19.txt (Caused by ConnectTimeoutError(<urllib3.connection.HTTPSConnection object at 0x000001ED258829F0>, 'Connection to api.github.com timed out. (connect timeout=None)'))

Error during execution: Traceback (most recent call last):
  File "urllib3\connection.py", line 198, in _new_conn
  File "urllib3\util\connection.py", line 85, in create_connection
  File "urllib3\util\connection.py", line 73, in create_connection
TimeoutError: [WinError 10060] 由于连接方在一段时间后没有正确答复或连接的主机没有反应，连接尝试失败。

The above exception was the direct cause of the following exception:

Traceback (most recent call last):
  File "urllib3\connectionpool.py", line 787, in urlopen
  File "urllib3\connectionpool.py", line 488, in _make_request
  File "urllib3\connectionpool.py", line 464, in _make_request
  File "urllib3\connectionpool.py", line 1093, in _validate_conn
  File "urllib3\connection.py", line 704, in connect
  File "urllib3\connection.py", line 207, in _new_conn
urllib3.exceptions.ConnectTimeoutError: (<urllib3.connection.HTTPSConnection object at 0x000001ED258831A0>, 'Connection to api.github.com timed out. (connect timeout=None)')

The above exception was the direct cause of the following exception:

Traceback (most recent call last):
  File "requests\adapters.py", line 667, in send
  File "urllib3\connectionpool.py", line 841, in urlopen
  File "urllib3\util\retry.py", line 519, in increment
urllib3.exceptions.MaxRetryError: HTTPSConnectionPool(host='api.github.com', port=443): Max retries exceeded with url: /repos/Ilikectrlmusic/auto_ip/contents/781_result/2025-02-19.txt (Caused by ConnectTimeoutError(<urllib3.connection.HTTPSConnection object at 0x000001ED258831A0>, 'Connection to api.github.com timed out. (connect timeout=None)'))

During handling of the above exception, another exception occurred:

Traceback (most recent call last):
  File "main.py", line 339, in <module>
  File "main.py", line 307, in upload_result
  File "requests\api.py", line 130, in put
  File "requests\api.py", line 59, in request
  File "requests\sessions.py", line 589, in request
  File "requests\sessions.py", line 703, in send
  File "requests\adapters.py", line 688, in send
requests.exceptions.ConnectTimeout: HTTPSConnectionPool(host='api.github.com', port=443): Max retries exceeded with url: /repos/Ilikectrlmusic/auto_ip/contents/781_result/2025-02-19.txt (Caused by ConnectTimeoutError(<urllib3.connection.HTTPSConnection object at 0x000001ED258831A0>, 'Connection to api.github.com timed out. (connect timeout=None)'))

Error during execution: Traceback (most recent call last):
  File "urllib3\connection.py", line 198, in _new_conn
  File "urllib3\util\connection.py", line 85, in create_connection
  File "urllib3\util\connection.py", line 73, in create_connection
TimeoutError: [WinError 10060] 由于连接方在一段时间后没有正确答复或连接的主机没有反应，连接尝试失败。

The above exception was the direct cause of the following exception:

Traceback (most recent call last):
  File "urllib3\connectionpool.py", line 787, in urlopen
  File "urllib3\connectionpool.py", line 488, in _make_request
  File "urllib3\connectionpool.py", line 464, in _make_request
  File "urllib3\connectionpool.py", line 1093, in _validate_conn
  File "urllib3\connection.py", line 704, in connect
  File "urllib3\connection.py", line 207, in _new_conn
urllib3.exceptions.ConnectTimeoutError: (<urllib3.connection.HTTPSConnection object at 0x000001ED2592AD50>, 'Connection to api.github.com timed out. (connect timeout=None)')

The above exception was the direct cause of the following exception:

Traceback (most recent call last):
  File "requests\adapters.py", line 667, in send
  File "urllib3\connectionpool.py", line 841, in urlopen
  File "urllib3\util\retry.py", line 519, in increment
urllib3.exceptions.MaxRetryError: HTTPSConnectionPool(host='api.github.com', port=443): Max retries exceeded with url: /repos/Ilikectrlmusic/auto_ip/contents/781_result/2025-02-19.txt (Caused by ConnectTimeoutError(<urllib3.connection.HTTPSConnection object at 0x000001ED2592AD50>, 'Connection to api.github.com timed out. (connect timeout=None)'))

During handling of the above exception, another exception occurred:

Traceback (most recent call last):
  File "main.py", line 339, in <module>
  File "main.py", line 307, in upload_result
  File "requests\api.py", line 130, in put
  File "requests\api.py", line 59, in request
  File "requests\sessions.py", line 589, in request
  File "requests\sessions.py", line 703, in send
  File "requests\adapters.py", line 688, in send
requests.exceptions.ConnectTimeout: HTTPSConnectionPool(host='api.github.com', port=443): Max retries exceeded with url: /repos/Ilikectrlmusic/auto_ip/contents/781_result/2025-02-19.txt (Caused by ConnectTimeoutError(<urllib3.connection.HTTPSConnection object at 0x000001ED2592AD50>, 'Connection to api.github.com timed out. (connect timeout=None)'))

Error during execution: Traceback (most recent call last):
  File "urllib3\connection.py", line 198, in _new_conn
  File "urllib3\util\connection.py", line 85, in create_connection
  File "urllib3\util\connection.py", line 73, in create_connection
TimeoutError: [WinError 10060] 由于连接方在一段时间后没有正确答复或连接的主机没有反应，连接尝试失败。

The above exception was the direct cause of the following exception:

Traceback (most recent call last):
  File "urllib3\connectionpool.py", line 787, in urlopen
  File "urllib3\connectionpool.py", line 488, in _make_request
  File "urllib3\connectionpool.py", line 464, in _make_request
  File "urllib3\connectionpool.py", line 1093, in _validate_conn
  File "urllib3\connection.py", line 704, in connect
  File "urllib3\connection.py", line 207, in _new_conn
urllib3.exceptions.ConnectTimeoutError: (<urllib3.connection.HTTPSConnection object at 0x000001ED2592AD50>, 'Connection to api.github.com timed out. (connect timeout=None)')

The above exception was the direct cause of the following exception:

Traceback (most recent call last):
  File "requests\adapters.py", line 667, in send
  File "urllib3\connectionpool.py", line 841, in urlopen
  File "urllib3\util\retry.py", line 519, in increment
urllib3.exceptions.MaxRetryError: HTTPSConnectionPool(host='api.github.com', port=443): Max retries exceeded with url: /repos/Ilikectrlmusic/auto_ip/contents/781_result/2025-02-19.txt (Caused by ConnectTimeoutError(<urllib3.connection.HTTPSConnection object at 0x000001ED2592AD50>, 'Connection to api.github.com timed out. (connect timeout=None)'))

During handling of the above exception, another exception occurred:

Traceback (most recent call last):
  File "main.py", line 339, in <module>
  File "main.py", line 307, in upload_result
  File "requests\api.py", line 130, in put
  File "requests\api.py", line 59, in request
  File "requests\sessions.py", line 589, in request
  File "requests\sessions.py", line 703, in send
  File "requests\adapters.py", line 688, in send
requests.exceptions.ConnectTimeout: HTTPSConnectionPool(host='api.github.com', port=443): Max retries exceeded with url: /repos/Ilikectrlmusic/auto_ip/contents/781_result/2025-02-19.txt (Caused by ConnectTimeoutError(<urllib3.connection.HTTPSConnection object at 0x000001ED2592AD50>, 'Connection to api.github.com timed out. (connect timeout=None)'))

Error during execution: Traceback (most recent call last):
  File "urllib3\connection.py", line 198, in _new_conn
  File "urllib3\util\connection.py", line 85, in create_connection
  File "urllib3\util\connection.py", line 73, in create_connection
TimeoutError: [WinError 10060] 由于连接方在一段时间后没有正确答复或连接的主机没有反应，连接尝试失败。

The above exception was the direct cause of the following exception:

Traceback (most recent call last):
  File "urllib3\connectionpool.py", line 787, in urlopen
  File "urllib3\connectionpool.py", line 488, in _make_request
  File "urllib3\connectionpool.py", line 464, in _make_request
  File "urllib3\connectionpool.py", line 1093, in _validate_conn
  File "urllib3\connection.py", line 704, in connect
  File "urllib3\connection.py", line 207, in _new_conn
urllib3.exceptions.ConnectTimeoutError: (<urllib3.connection.HTTPSConnection object at 0x000001ED258F2C60>, 'Connection to api.github.com timed out. (connect timeout=None)')

The above exception was the direct cause of the following exception:

Traceback (most recent call last):
  File "requests\adapters.py", line 667, in send
  File "urllib3\connectionpool.py", line 841, in urlopen
  File "urllib3\util\retry.py", line 519, in increment
urllib3.exceptions.MaxRetryError: HTTPSConnectionPool(host='api.github.com', port=443): Max retries exceeded with url: /repos/Ilikectrlmusic/auto_ip/contents/781_result/2025-02-19.txt (Caused by ConnectTimeoutError(<urllib3.connection.HTTPSConnection object at 0x000001ED258F2C60>, 'Connection to api.github.com timed out. (connect timeout=None)'))

During handling of the above exception, another exception occurred:

Traceback (most recent call last):
  File "main.py", line 339, in <module>
  File "main.py", line 307, in upload_result
  File "requests\api.py", line 130, in put
  File "requests\api.py", line 59, in request
  File "requests\sessions.py", line 589, in request
  File "requests\sessions.py", line 703, in send
  File "requests\adapters.py", line 688, in send
requests.exceptions.ConnectTimeout: HTTPSConnectionPool(host='api.github.com', port=443): Max retries exceeded with url: /repos/Ilikectrlmusic/auto_ip/contents/781_result/2025-02-19.txt (Caused by ConnectTimeoutError(<urllib3.connection.HTTPSConnection object at 0x000001ED258F2C60>, 'Connection to api.github.com timed out. (connect timeout=None)'))

Error during execution: Traceback (most recent call last):
  File "urllib3\connection.py", line 198, in _new_conn
  File "urllib3\util\connection.py", line 85, in create_connection
  File "urllib3\util\connection.py", line 73, in create_connection
TimeoutError: [WinError 10060] 由于连接方在一段时间后没有正确答复或连接的主机没有反应，连接尝试失败。

The above exception was the direct cause of the following exception:

Traceback (most recent call last):
  File "urllib3\connectionpool.py", line 787, in urlopen
  File "urllib3\connectionpool.py", line 488, in _make_request
  File "urllib3\connectionpool.py", line 464, in _make_request
  File "urllib3\connectionpool.py", line 1093, in _validate_conn
  File "urllib3\connection.py", line 704, in connect
  File "urllib3\connection.py", line 207, in _new_conn
urllib3.exceptions.ConnectTimeoutError: (<urllib3.connection.HTTPSConnection object at 0x000001ED2592B170>, 'Connection to api.github.com timed out. (connect timeout=None)')

The above exception was the direct cause of the following exception:

Traceback (most recent call last):
  File "requests\adapters.py", line 667, in send
  File "urllib3\connectionpool.py", line 841, in urlopen
  File "urllib3\util\retry.py", line 519, in increment
urllib3.exceptions.MaxRetryError: HTTPSConnectionPool(host='api.github.com', port=443): Max retries exceeded with url: /repos/Ilikectrlmusic/auto_ip/contents/781_result/2025-02-19.txt (Caused by ConnectTimeoutError(<urllib3.connection.HTTPSConnection object at 0x000001ED2592B170>, 'Connection to api.github.com timed out. (connect timeout=None)'))

During handling of the above exception, another exception occurred:

Traceback (most recent call last):
  File "main.py", line 339, in <module>
  File "main.py", line 288, in upload_result
  File "requests\api.py", line 73, in get
  File "requests\api.py", line 59, in request
  File "requests\sessions.py", line 589, in request
  File "requests\sessions.py", line 703, in send
  File "requests\adapters.py", line 688, in send
requests.exceptions.ConnectTimeout: HTTPSConnectionPool(host='api.github.com', port=443): Max retries exceeded with url: /repos/Ilikectrlmusic/auto_ip/contents/781_result/2025-02-19.txt (Caused by ConnectTimeoutError(<urllib3.connection.HTTPSConnection object at 0x000001ED2592B170>, 'Connection to api.github.com timed out. (connect timeout=None)'))

Error during execution: Traceback (most recent call last):
  File "urllib3\connection.py", line 198, in _new_conn
  File "urllib3\util\connection.py", line 85, in create_connection
  File "urllib3\util\connection.py", line 73, in create_connection
TimeoutError: [WinError 10060] 由于连接方在一段时间后没有正确答复或连接的主机没有反应，连接尝试失败。

The above exception was the direct cause of the following exception:

Traceback (most recent call last):
  File "urllib3\connectionpool.py", line 787, in urlopen
  File "urllib3\connectionpool.py", line 488, in _make_request
  File "urllib3\connectionpool.py", line 464, in _make_request
  File "urllib3\connectionpool.py", line 1093, in _validate_conn
  File "urllib3\connection.py", line 704, in connect
  File "urllib3\connection.py", line 207, in _new_conn
urllib3.exceptions.ConnectTimeoutError: (<urllib3.connection.HTTPSConnection object at 0x000001ED258F3320>, 'Connection to api.github.com timed out. (connect timeout=None)')

The above exception was the direct cause of the following exception:

Traceback (most recent call last):
  File "requests\adapters.py", line 667, in send
  File "urllib3\connectionpool.py", line 841, in urlopen
  File "urllib3\util\retry.py", line 519, in increment
urllib3.exceptions.MaxRetryError: HTTPSConnectionPool(host='api.github.com', port=443): Max retries exceeded with url: /repos/Ilikectrlmusic/auto_ip/contents/781_result/2025-02-19.txt (Caused by ConnectTimeoutError(<urllib3.connection.HTTPSConnection object at 0x000001ED258F3320>, 'Connection to api.github.com timed out. (connect timeout=None)'))

During handling of the above exception, another exception occurred:

Traceback (most recent call last):
  File "main.py", line 339, in <module>
  File "main.py", line 307, in upload_result
  File "requests\api.py", line 130, in put
  File "requests\api.py", line 59, in request
  File "requests\sessions.py", line 589, in request
  File "requests\sessions.py", line 703, in send
  File "requests\adapters.py", line 688, in send
requests.exceptions.ConnectTimeout: HTTPSConnectionPool(host='api.github.com', port=443): Max retries exceeded with url: /repos/Ilikectrlmusic/auto_ip/contents/781_result/2025-02-19.txt (Caused by ConnectTimeoutError(<urllib3.connection.HTTPSConnection object at 0x000001ED258F3320>, 'Connection to api.github.com timed out. (connect timeout=None)'))

Error during execution: Traceback (most recent call last):
  File "urllib3\connection.py", line 198, in _new_conn
  File "urllib3\util\connection.py", line 85, in create_connection
  File "urllib3\util\connection.py", line 73, in create_connection
TimeoutError: [WinError 10060] 由于连接方在一段时间后没有正确答复或连接的主机没有反应，连接尝试失败。

The above exception was the direct cause of the following exception:

Traceback (most recent call last):
  File "urllib3\connectionpool.py", line 787, in urlopen
  File "urllib3\connectionpool.py", line 488, in _make_request
  File "urllib3\connectionpool.py", line 464, in _make_request
  File "urllib3\connectionpool.py", line 1093, in _validate_conn
  File "urllib3\connection.py", line 704, in connect
  File "urllib3\connection.py", line 207, in _new_conn
urllib3.exceptions.ConnectTimeoutError: (<urllib3.connection.HTTPSConnection object at 0x000001ED2592AB10>, 'Connection to api.github.com timed out. (connect timeout=None)')

The above exception was the direct cause of the following exception:

Traceback (most recent call last):
  File "requests\adapters.py", line 667, in send
  File "urllib3\connectionpool.py", line 841, in urlopen
  File "urllib3\util\retry.py", line 519, in increment
urllib3.exceptions.MaxRetryError: HTTPSConnectionPool(host='api.github.com', port=443): Max retries exceeded with url: /repos/Ilikectrlmusic/auto_ip/contents/781_result/2025-02-19.txt (Caused by ConnectTimeoutError(<urllib3.connection.HTTPSConnection object at 0x000001ED2592AB10>, 'Connection to api.github.com timed out. (connect timeout=None)'))

During handling of the above exception, another exception occurred:

Traceback (most recent call last):
  File "main.py", line 339, in <module>
  File "main.py", line 307, in upload_result
  File "requests\api.py", line 130, in put
  File "requests\api.py", line 59, in request
  File "requests\sessions.py", line 589, in request
  File "requests\sessions.py", line 703, in send
  File "requests\adapters.py", line 688, in send
requests.exceptions.ConnectTimeout: HTTPSConnectionPool(host='api.github.com', port=443): Max retries exceeded with url: /repos/Ilikectrlmusic/auto_ip/contents/781_result/2025-02-19.txt (Caused by ConnectTimeoutError(<urllib3.connection.HTTPSConnection object at 0x000001ED2592AB10>, 'Connection to api.github.com timed out. (connect timeout=None)'))

