Error during execution: Traceback (most recent call last):
  File "E:\program data\pythonProject\auto_ip\main.py", line 337, in <module>
    read_config()  # 读取配置
    ^^^^^^^^^^^^^
  File "E:\program data\pythonProject\auto_ip\main.py", line 135, in read_config
    config.read('config.ini')
  File "E:\program files\python\Lib\configparser.py", line 684, in read
    self._read(fp, filename)
  File "E:\program files\python\Lib\configparser.py", line 999, in _read
    for lineno, line in enumerate(fp, start=1):
                        ^^^^^^^^^^^^^^^^^^^^^^
UnicodeDecodeError: 'gbk' codec can't decode byte 0x9c in position 138: illegal multibyte sequence

Error during execution: Traceback (most recent call last):
  File "E:\program data\pythonProject\auto_ip\main.py", line 337, in <module>
    read_config()  # 读取配置
    ^^^^^^^^^^^^^
  File "E:\program data\pythonProject\auto_ip\main.py", line 135, in read_config
    config.read('config.ini')
  File "E:\program files\python\Lib\configparser.py", line 684, in read
    self._read(fp, filename)
  File "E:\program files\python\Lib\configparser.py", line 999, in _read
    for lineno, line in enumerate(fp, start=1):
                        ^^^^^^^^^^^^^^^^^^^^^^
UnicodeDecodeError: 'gbk' codec can't decode byte 0x9c in position 138: illegal multibyte sequence

