Error during execution: Traceback (most recent call last):
  File "urllib3\connection.py", line 198, in _new_conn
  File "urllib3\util\connection.py", line 85, in create_connection
  File "urllib3\util\connection.py", line 73, in create_connection
TimeoutError: [WinError 10060] 由于连接方在一段时间后没有正确答复或连接的主机没有反应，连接尝试失败。

The above exception was the direct cause of the following exception:

Traceback (most recent call last):
  File "urllib3\connectionpool.py", line 787, in urlopen
  File "urllib3\connectionpool.py", line 488, in _make_request
  File "urllib3\connectionpool.py", line 464, in _make_request
  File "urllib3\connectionpool.py", line 1093, in _validate_conn
  File "urllib3\connection.py", line 704, in connect
  File "urllib3\connection.py", line 207, in _new_conn
urllib3.exceptions.ConnectTimeoutError: (<urllib3.connection.HTTPSConnection object at 0x000001A378F4C260>, 'Connection to api.github.com timed out. (connect timeout=None)')

The above exception was the direct cause of the following exception:

Traceback (most recent call last):
  File "requests\adapters.py", line 667, in send
  File "urllib3\connectionpool.py", line 841, in urlopen
  File "urllib3\util\retry.py", line 519, in increment
urllib3.exceptions.MaxRetryError: HTTPSConnectionPool(host='api.github.com', port=443): Max retries exceeded with url: /repos/Ilikectrlmusic/auto_ip/contents/781_result/2025-03-21.txt (Caused by ConnectTimeoutError(<urllib3.connection.HTTPSConnection object at 0x000001A378F4C260>, 'Connection to api.github.com timed out. (connect timeout=None)'))

During handling of the above exception, another exception occurred:

Traceback (most recent call last):
  File "main.py", line 339, in <module>
  File "main.py", line 307, in upload_result
  File "requests\api.py", line 130, in put
  File "requests\api.py", line 59, in request
  File "requests\sessions.py", line 589, in request
  File "requests\sessions.py", line 703, in send
  File "requests\adapters.py", line 688, in send
requests.exceptions.ConnectTimeout: HTTPSConnectionPool(host='api.github.com', port=443): Max retries exceeded with url: /repos/Ilikectrlmusic/auto_ip/contents/781_result/2025-03-21.txt (Caused by ConnectTimeoutError(<urllib3.connection.HTTPSConnection object at 0x000001A378F4C260>, 'Connection to api.github.com timed out. (connect timeout=None)'))

Error uploading log: HTTPSConnectionPool(host='api.github.com', port=443): Max retries exceeded with url: /repos/Ilikectrlmusic/auto_ip/contents/log/2025-03-21.log (Caused by ConnectTimeoutError(<urllib3.connection.HTTPSConnection object at 0x000001A378F4C6B0>, 'Connection to api.github.com timed out. (connect timeout=None)'))
Error during execution: Traceback (most recent call last):
  File "urllib3\connection.py", line 198, in _new_conn
  File "urllib3\util\connection.py", line 85, in create_connection
  File "urllib3\util\connection.py", line 73, in create_connection
TimeoutError: [WinError 10060] 由于连接方在一段时间后没有正确答复或连接的主机没有反应，连接尝试失败。

The above exception was the direct cause of the following exception:

Traceback (most recent call last):
  File "urllib3\connectionpool.py", line 787, in urlopen
  File "urllib3\connectionpool.py", line 488, in _make_request
  File "urllib3\connectionpool.py", line 464, in _make_request
  File "urllib3\connectionpool.py", line 1093, in _validate_conn
  File "urllib3\connection.py", line 704, in connect
  File "urllib3\connection.py", line 207, in _new_conn
urllib3.exceptions.ConnectTimeoutError: (<urllib3.connection.HTTPSConnection object at 0x000001A378F4D250>, 'Connection to api.github.com timed out. (connect timeout=None)')

The above exception was the direct cause of the following exception:

Traceback (most recent call last):
  File "requests\adapters.py", line 667, in send
  File "urllib3\connectionpool.py", line 841, in urlopen
  File "urllib3\util\retry.py", line 519, in increment
urllib3.exceptions.MaxRetryError: HTTPSConnectionPool(host='api.github.com', port=443): Max retries exceeded with url: /repos/Ilikectrlmusic/auto_ip/contents/781_result/2025-03-21.txt (Caused by ConnectTimeoutError(<urllib3.connection.HTTPSConnection object at 0x000001A378F4D250>, 'Connection to api.github.com timed out. (connect timeout=None)'))

During handling of the above exception, another exception occurred:

Traceback (most recent call last):
  File "main.py", line 339, in <module>
  File "main.py", line 288, in upload_result
  File "requests\api.py", line 73, in get
  File "requests\api.py", line 59, in request
  File "requests\sessions.py", line 589, in request
  File "requests\sessions.py", line 703, in send
  File "requests\adapters.py", line 688, in send
requests.exceptions.ConnectTimeout: HTTPSConnectionPool(host='api.github.com', port=443): Max retries exceeded with url: /repos/Ilikectrlmusic/auto_ip/contents/781_result/2025-03-21.txt (Caused by ConnectTimeoutError(<urllib3.connection.HTTPSConnection object at 0x000001A378F4D250>, 'Connection to api.github.com timed out. (connect timeout=None)'))

Error uploading log: HTTPSConnectionPool(host='api.github.com', port=443): Max retries exceeded with url: /repos/Ilikectrlmusic/auto_ip/contents/log/2025-03-21.log (Caused by ConnectTimeoutError(<urllib3.connection.HTTPSConnection object at 0x000001A378F4DC10>, 'Connection to api.github.com timed out. (connect timeout=None)'))
Error during execution: Traceback (most recent call last):
  File "urllib3\connection.py", line 198, in _new_conn
  File "urllib3\util\connection.py", line 85, in create_connection
  File "urllib3\util\connection.py", line 73, in create_connection
TimeoutError: [WinError 10060] 由于连接方在一段时间后没有正确答复或连接的主机没有反应，连接尝试失败。

The above exception was the direct cause of the following exception:

Traceback (most recent call last):
  File "urllib3\connectionpool.py", line 787, in urlopen
  File "urllib3\connectionpool.py", line 488, in _make_request
  File "urllib3\connectionpool.py", line 464, in _make_request
  File "urllib3\connectionpool.py", line 1093, in _validate_conn
  File "urllib3\connection.py", line 704, in connect
  File "urllib3\connection.py", line 207, in _new_conn
urllib3.exceptions.ConnectTimeoutError: (<urllib3.connection.HTTPSConnection object at 0x000001A378F4DB80>, 'Connection to api.github.com timed out. (connect timeout=None)')

The above exception was the direct cause of the following exception:

Traceback (most recent call last):
  File "requests\adapters.py", line 667, in send
  File "urllib3\connectionpool.py", line 841, in urlopen
  File "urllib3\util\retry.py", line 519, in increment
urllib3.exceptions.MaxRetryError: HTTPSConnectionPool(host='api.github.com', port=443): Max retries exceeded with url: /repos/Ilikectrlmusic/auto_ip/contents/781_result/2025-03-21.txt (Caused by ConnectTimeoutError(<urllib3.connection.HTTPSConnection object at 0x000001A378F4DB80>, 'Connection to api.github.com timed out. (connect timeout=None)'))

During handling of the above exception, another exception occurred:

Traceback (most recent call last):
  File "main.py", line 339, in <module>
  File "main.py", line 307, in upload_result
  File "requests\api.py", line 130, in put
  File "requests\api.py", line 59, in request
  File "requests\sessions.py", line 589, in request
  File "requests\sessions.py", line 703, in send
  File "requests\adapters.py", line 688, in send
requests.exceptions.ConnectTimeout: HTTPSConnectionPool(host='api.github.com', port=443): Max retries exceeded with url: /repos/Ilikectrlmusic/auto_ip/contents/781_result/2025-03-21.txt (Caused by ConnectTimeoutError(<urllib3.connection.HTTPSConnection object at 0x000001A378F4DB80>, 'Connection to api.github.com timed out. (connect timeout=None)'))

Error uploading log: HTTPSConnectionPool(host='api.github.com', port=443): Max retries exceeded with url: /repos/Ilikectrlmusic/auto_ip/contents/log/2025-03-21.log (Caused by ConnectTimeoutError(<urllib3.connection.HTTPSConnection object at 0x000001A378F4D2B0>, 'Connection to api.github.com timed out. (connect timeout=None)'))
Error during execution: Traceback (most recent call last):
  File "urllib3\connection.py", line 198, in _new_conn
  File "urllib3\util\connection.py", line 85, in create_connection
  File "urllib3\util\connection.py", line 73, in create_connection
TimeoutError: [WinError 10060] 由于连接方在一段时间后没有正确答复或连接的主机没有反应，连接尝试失败。

The above exception was the direct cause of the following exception:

Traceback (most recent call last):
  File "urllib3\connectionpool.py", line 787, in urlopen
  File "urllib3\connectionpool.py", line 488, in _make_request
  File "urllib3\connectionpool.py", line 464, in _make_request
  File "urllib3\connectionpool.py", line 1093, in _validate_conn
  File "urllib3\connection.py", line 704, in connect
  File "urllib3\connection.py", line 207, in _new_conn
urllib3.exceptions.ConnectTimeoutError: (<urllib3.connection.HTTPSConnection object at 0x000001A378F4CD70>, 'Connection to api.github.com timed out. (connect timeout=None)')

The above exception was the direct cause of the following exception:

Traceback (most recent call last):
  File "requests\adapters.py", line 667, in send
  File "urllib3\connectionpool.py", line 841, in urlopen
  File "urllib3\util\retry.py", line 519, in increment
urllib3.exceptions.MaxRetryError: HTTPSConnectionPool(host='api.github.com', port=443): Max retries exceeded with url: /repos/Ilikectrlmusic/auto_ip/contents/781_result/2025-03-21.txt (Caused by ConnectTimeoutError(<urllib3.connection.HTTPSConnection object at 0x000001A378F4CD70>, 'Connection to api.github.com timed out. (connect timeout=None)'))

During handling of the above exception, another exception occurred:

Traceback (most recent call last):
  File "main.py", line 339, in <module>
  File "main.py", line 288, in upload_result
  File "requests\api.py", line 73, in get
  File "requests\api.py", line 59, in request
  File "requests\sessions.py", line 589, in request
  File "requests\sessions.py", line 703, in send
  File "requests\adapters.py", line 688, in send
requests.exceptions.ConnectTimeout: HTTPSConnectionPool(host='api.github.com', port=443): Max retries exceeded with url: /repos/Ilikectrlmusic/auto_ip/contents/781_result/2025-03-21.txt (Caused by ConnectTimeoutError(<urllib3.connection.HTTPSConnection object at 0x000001A378F4CD70>, 'Connection to api.github.com timed out. (connect timeout=None)'))

Error uploading log: HTTPSConnectionPool(host='api.github.com', port=443): Max retries exceeded with url: /repos/Ilikectrlmusic/auto_ip/contents/log/2025-03-21.log (Caused by ConnectTimeoutError(<urllib3.connection.HTTPSConnection object at 0x000001A378F4D040>, 'Connection to api.github.com timed out. (connect timeout=None)'))
Error during execution: Traceback (most recent call last):
  File "urllib3\connection.py", line 198, in _new_conn
  File "urllib3\util\connection.py", line 85, in create_connection
  File "urllib3\util\connection.py", line 73, in create_connection
TimeoutError: [WinError 10060] 由于连接方在一段时间后没有正确答复或连接的主机没有反应，连接尝试失败。

The above exception was the direct cause of the following exception:

Traceback (most recent call last):
  File "urllib3\connectionpool.py", line 787, in urlopen
  File "urllib3\connectionpool.py", line 488, in _make_request
  File "urllib3\connectionpool.py", line 464, in _make_request
  File "urllib3\connectionpool.py", line 1093, in _validate_conn
  File "urllib3\connection.py", line 704, in connect
  File "urllib3\connection.py", line 207, in _new_conn
urllib3.exceptions.ConnectTimeoutError: (<urllib3.connection.HTTPSConnection object at 0x000001A378BDCA70>, 'Connection to api.github.com timed out. (connect timeout=None)')

The above exception was the direct cause of the following exception:

Traceback (most recent call last):
  File "requests\adapters.py", line 667, in send
  File "urllib3\connectionpool.py", line 841, in urlopen
  File "urllib3\util\retry.py", line 519, in increment
urllib3.exceptions.MaxRetryError: HTTPSConnectionPool(host='api.github.com', port=443): Max retries exceeded with url: /repos/Ilikectrlmusic/auto_ip/contents/781_result/2025-03-21.txt (Caused by ConnectTimeoutError(<urllib3.connection.HTTPSConnection object at 0x000001A378BDCA70>, 'Connection to api.github.com timed out. (connect timeout=None)'))

During handling of the above exception, another exception occurred:

Traceback (most recent call last):
  File "main.py", line 339, in <module>
  File "main.py", line 307, in upload_result
  File "requests\api.py", line 130, in put
  File "requests\api.py", line 59, in request
  File "requests\sessions.py", line 589, in request
  File "requests\sessions.py", line 703, in send
  File "requests\adapters.py", line 688, in send
requests.exceptions.ConnectTimeout: HTTPSConnectionPool(host='api.github.com', port=443): Max retries exceeded with url: /repos/Ilikectrlmusic/auto_ip/contents/781_result/2025-03-21.txt (Caused by ConnectTimeoutError(<urllib3.connection.HTTPSConnection object at 0x000001A378BDCA70>, 'Connection to api.github.com timed out. (connect timeout=None)'))

Error uploading log: HTTPSConnectionPool(host='api.github.com', port=443): Max retries exceeded with url: /repos/Ilikectrlmusic/auto_ip/contents/log/2025-03-21.log (Caused by ConnectTimeoutError(<urllib3.connection.HTTPSConnection object at 0x000001A378F74A40>, 'Connection to api.github.com timed out. (connect timeout=None)'))
Error during execution: Traceback (most recent call last):
  File "urllib3\connection.py", line 198, in _new_conn
  File "urllib3\util\connection.py", line 85, in create_connection
  File "urllib3\util\connection.py", line 73, in create_connection
TimeoutError: [WinError 10060] 由于连接方在一段时间后没有正确答复或连接的主机没有反应，连接尝试失败。

The above exception was the direct cause of the following exception:

Traceback (most recent call last):
  File "urllib3\connectionpool.py", line 787, in urlopen
  File "urllib3\connectionpool.py", line 488, in _make_request
  File "urllib3\connectionpool.py", line 464, in _make_request
  File "urllib3\connectionpool.py", line 1093, in _validate_conn
  File "urllib3\connection.py", line 704, in connect
  File "urllib3\connection.py", line 207, in _new_conn
urllib3.exceptions.ConnectTimeoutError: (<urllib3.connection.HTTPSConnection object at 0x000001A378F4FE00>, 'Connection to api.github.com timed out. (connect timeout=None)')

The above exception was the direct cause of the following exception:

Traceback (most recent call last):
  File "requests\adapters.py", line 667, in send
  File "urllib3\connectionpool.py", line 841, in urlopen
  File "urllib3\util\retry.py", line 519, in increment
urllib3.exceptions.MaxRetryError: HTTPSConnectionPool(host='api.github.com', port=443): Max retries exceeded with url: /repos/Ilikectrlmusic/auto_ip/contents/781_result/2025-03-21.txt (Caused by ConnectTimeoutError(<urllib3.connection.HTTPSConnection object at 0x000001A378F4FE00>, 'Connection to api.github.com timed out. (connect timeout=None)'))

During handling of the above exception, another exception occurred:

Traceback (most recent call last):
  File "main.py", line 339, in <module>
  File "main.py", line 288, in upload_result
  File "requests\api.py", line 73, in get
  File "requests\api.py", line 59, in request
  File "requests\sessions.py", line 589, in request
  File "requests\sessions.py", line 703, in send
  File "requests\adapters.py", line 688, in send
requests.exceptions.ConnectTimeout: HTTPSConnectionPool(host='api.github.com', port=443): Max retries exceeded with url: /repos/Ilikectrlmusic/auto_ip/contents/781_result/2025-03-21.txt (Caused by ConnectTimeoutError(<urllib3.connection.HTTPSConnection object at 0x000001A378F4FE00>, 'Connection to api.github.com timed out. (connect timeout=None)'))

Error uploading log: HTTPSConnectionPool(host='api.github.com', port=443): Max retries exceeded with url: /repos/Ilikectrlmusic/auto_ip/contents/log/2025-03-21.log (Caused by ConnectTimeoutError(<urllib3.connection.HTTPSConnection object at 0x000001A378F745C0>, 'Connection to api.github.com timed out. (connect timeout=None)'))
Error during execution: Traceback (most recent call last):
  File "urllib3\connection.py", line 198, in _new_conn
  File "urllib3\util\connection.py", line 85, in create_connection
  File "urllib3\util\connection.py", line 73, in create_connection
TimeoutError: [WinError 10060] 由于连接方在一段时间后没有正确答复或连接的主机没有反应，连接尝试失败。

The above exception was the direct cause of the following exception:

Traceback (most recent call last):
  File "urllib3\connectionpool.py", line 787, in urlopen
  File "urllib3\connectionpool.py", line 488, in _make_request
  File "urllib3\connectionpool.py", line 464, in _make_request
  File "urllib3\connectionpool.py", line 1093, in _validate_conn
  File "urllib3\connection.py", line 704, in connect
  File "urllib3\connection.py", line 207, in _new_conn
urllib3.exceptions.ConnectTimeoutError: (<urllib3.connection.HTTPSConnection object at 0x000001A378BDED80>, 'Connection to api.github.com timed out. (connect timeout=None)')

The above exception was the direct cause of the following exception:

Traceback (most recent call last):
  File "requests\adapters.py", line 667, in send
  File "urllib3\connectionpool.py", line 841, in urlopen
  File "urllib3\util\retry.py", line 519, in increment
urllib3.exceptions.MaxRetryError: HTTPSConnectionPool(host='api.github.com', port=443): Max retries exceeded with url: /repos/Ilikectrlmusic/auto_ip/contents/781_result/2025-03-21.txt (Caused by ConnectTimeoutError(<urllib3.connection.HTTPSConnection object at 0x000001A378BDED80>, 'Connection to api.github.com timed out. (connect timeout=None)'))

During handling of the above exception, another exception occurred:

Traceback (most recent call last):
  File "main.py", line 339, in <module>
  File "main.py", line 307, in upload_result
  File "requests\api.py", line 130, in put
  File "requests\api.py", line 59, in request
  File "requests\sessions.py", line 589, in request
  File "requests\sessions.py", line 703, in send
  File "requests\adapters.py", line 688, in send
requests.exceptions.ConnectTimeout: HTTPSConnectionPool(host='api.github.com', port=443): Max retries exceeded with url: /repos/Ilikectrlmusic/auto_ip/contents/781_result/2025-03-21.txt (Caused by ConnectTimeoutError(<urllib3.connection.HTTPSConnection object at 0x000001A378BDED80>, 'Connection to api.github.com timed out. (connect timeout=None)'))

Error uploading log: HTTPSConnectionPool(host='api.github.com', port=443): Max retries exceeded with url: /repos/Ilikectrlmusic/auto_ip/contents/log/2025-03-21.log (Caused by ConnectTimeoutError(<urllib3.connection.HTTPSConnection object at 0x000001A378F4EF90>, 'Connection to api.github.com timed out. (connect timeout=None)'))
Error during execution: Traceback (most recent call last):
  File "urllib3\connection.py", line 198, in _new_conn
  File "urllib3\util\connection.py", line 85, in create_connection
  File "urllib3\util\connection.py", line 73, in create_connection
TimeoutError: [WinError 10060] 由于连接方在一段时间后没有正确答复或连接的主机没有反应，连接尝试失败。

The above exception was the direct cause of the following exception:

Traceback (most recent call last):
  File "urllib3\connectionpool.py", line 787, in urlopen
  File "urllib3\connectionpool.py", line 488, in _make_request
  File "urllib3\connectionpool.py", line 464, in _make_request
  File "urllib3\connectionpool.py", line 1093, in _validate_conn
  File "urllib3\connection.py", line 704, in connect
  File "urllib3\connection.py", line 207, in _new_conn
urllib3.exceptions.ConnectTimeoutError: (<urllib3.connection.HTTPSConnection object at 0x000001A378F4C650>, 'Connection to api.github.com timed out. (connect timeout=None)')

The above exception was the direct cause of the following exception:

Traceback (most recent call last):
  File "requests\adapters.py", line 667, in send
  File "urllib3\connectionpool.py", line 841, in urlopen
  File "urllib3\util\retry.py", line 519, in increment
urllib3.exceptions.MaxRetryError: HTTPSConnectionPool(host='api.github.com', port=443): Max retries exceeded with url: /repos/Ilikectrlmusic/auto_ip/contents/781_result/2025-03-21.txt (Caused by ConnectTimeoutError(<urllib3.connection.HTTPSConnection object at 0x000001A378F4C650>, 'Connection to api.github.com timed out. (connect timeout=None)'))

During handling of the above exception, another exception occurred:

Traceback (most recent call last):
  File "main.py", line 339, in <module>
  File "main.py", line 288, in upload_result
  File "requests\api.py", line 73, in get
  File "requests\api.py", line 59, in request
  File "requests\sessions.py", line 589, in request
  File "requests\sessions.py", line 703, in send
  File "requests\adapters.py", line 688, in send
requests.exceptions.ConnectTimeout: HTTPSConnectionPool(host='api.github.com', port=443): Max retries exceeded with url: /repos/Ilikectrlmusic/auto_ip/contents/781_result/2025-03-21.txt (Caused by ConnectTimeoutError(<urllib3.connection.HTTPSConnection object at 0x000001A378F4C650>, 'Connection to api.github.com timed out. (connect timeout=None)'))

Error during execution: Traceback (most recent call last):
  File "urllib3\connection.py", line 198, in _new_conn
  File "urllib3\util\connection.py", line 85, in create_connection
  File "urllib3\util\connection.py", line 73, in create_connection
TimeoutError: [WinError 10060] 由于连接方在一段时间后没有正确答复或连接的主机没有反应，连接尝试失败。

The above exception was the direct cause of the following exception:

Traceback (most recent call last):
  File "urllib3\connectionpool.py", line 787, in urlopen
  File "urllib3\connectionpool.py", line 488, in _make_request
  File "urllib3\connectionpool.py", line 464, in _make_request
  File "urllib3\connectionpool.py", line 1093, in _validate_conn
  File "urllib3\connection.py", line 704, in connect
  File "urllib3\connection.py", line 207, in _new_conn
urllib3.exceptions.ConnectTimeoutError: (<urllib3.connection.HTTPSConnection object at 0x000001A378F76AE0>, 'Connection to api.github.com timed out. (connect timeout=None)')

The above exception was the direct cause of the following exception:

Traceback (most recent call last):
  File "requests\adapters.py", line 667, in send
  File "urllib3\connectionpool.py", line 841, in urlopen
  File "urllib3\util\retry.py", line 519, in increment
urllib3.exceptions.MaxRetryError: HTTPSConnectionPool(host='api.github.com', port=443): Max retries exceeded with url: /repos/Ilikectrlmusic/auto_ip/contents/781_result/2025-03-21.txt (Caused by ConnectTimeoutError(<urllib3.connection.HTTPSConnection object at 0x000001A378F76AE0>, 'Connection to api.github.com timed out. (connect timeout=None)'))

During handling of the above exception, another exception occurred:

Traceback (most recent call last):
  File "main.py", line 339, in <module>
  File "main.py", line 307, in upload_result
  File "requests\api.py", line 130, in put
  File "requests\api.py", line 59, in request
  File "requests\sessions.py", line 589, in request
  File "requests\sessions.py", line 703, in send
  File "requests\adapters.py", line 688, in send
requests.exceptions.ConnectTimeout: HTTPSConnectionPool(host='api.github.com', port=443): Max retries exceeded with url: /repos/Ilikectrlmusic/auto_ip/contents/781_result/2025-03-21.txt (Caused by ConnectTimeoutError(<urllib3.connection.HTTPSConnection object at 0x000001A378F76AE0>, 'Connection to api.github.com timed out. (connect timeout=None)'))

Error uploading log: HTTPSConnectionPool(host='api.github.com', port=443): Max retries exceeded with url: /repos/Ilikectrlmusic/auto_ip/contents/log/2025-03-21.log (Caused by ConnectTimeoutError(<urllib3.connection.HTTPSConnection object at 0x000001A378F75040>, 'Connection to api.github.com timed out. (connect timeout=None)'))
Error during execution: Traceback (most recent call last):
  File "urllib3\connection.py", line 198, in _new_conn
  File "urllib3\util\connection.py", line 85, in create_connection
  File "urllib3\util\connection.py", line 73, in create_connection
TimeoutError: [WinError 10060] 由于连接方在一段时间后没有正确答复或连接的主机没有反应，连接尝试失败。

The above exception was the direct cause of the following exception:

Traceback (most recent call last):
  File "urllib3\connectionpool.py", line 787, in urlopen
  File "urllib3\connectionpool.py", line 488, in _make_request
  File "urllib3\connectionpool.py", line 464, in _make_request
  File "urllib3\connectionpool.py", line 1093, in _validate_conn
  File "urllib3\connection.py", line 704, in connect
  File "urllib3\connection.py", line 207, in _new_conn
urllib3.exceptions.ConnectTimeoutError: (<urllib3.connection.HTTPSConnection object at 0x000001A378F75F10>, 'Connection to api.github.com timed out. (connect timeout=None)')

The above exception was the direct cause of the following exception:

Traceback (most recent call last):
  File "requests\adapters.py", line 667, in send
  File "urllib3\connectionpool.py", line 841, in urlopen
  File "urllib3\util\retry.py", line 519, in increment
urllib3.exceptions.MaxRetryError: HTTPSConnectionPool(host='api.github.com', port=443): Max retries exceeded with url: /repos/Ilikectrlmusic/auto_ip/contents/781_result/2025-03-21.txt (Caused by ConnectTimeoutError(<urllib3.connection.HTTPSConnection object at 0x000001A378F75F10>, 'Connection to api.github.com timed out. (connect timeout=None)'))

During handling of the above exception, another exception occurred:

Traceback (most recent call last):
  File "main.py", line 339, in <module>
  File "main.py", line 307, in upload_result
  File "requests\api.py", line 130, in put
  File "requests\api.py", line 59, in request
  File "requests\sessions.py", line 589, in request
  File "requests\sessions.py", line 703, in send
  File "requests\adapters.py", line 688, in send
requests.exceptions.ConnectTimeout: HTTPSConnectionPool(host='api.github.com', port=443): Max retries exceeded with url: /repos/Ilikectrlmusic/auto_ip/contents/781_result/2025-03-21.txt (Caused by ConnectTimeoutError(<urllib3.connection.HTTPSConnection object at 0x000001A378F75F10>, 'Connection to api.github.com timed out. (connect timeout=None)'))

Error during execution: Traceback (most recent call last):
  File "urllib3\connection.py", line 198, in _new_conn
  File "urllib3\util\connection.py", line 85, in create_connection
  File "urllib3\util\connection.py", line 73, in create_connection
TimeoutError: [WinError 10060] 由于连接方在一段时间后没有正确答复或连接的主机没有反应，连接尝试失败。

The above exception was the direct cause of the following exception:

Traceback (most recent call last):
  File "urllib3\connectionpool.py", line 787, in urlopen
  File "urllib3\connectionpool.py", line 488, in _make_request
  File "urllib3\connectionpool.py", line 464, in _make_request
  File "urllib3\connectionpool.py", line 1093, in _validate_conn
  File "urllib3\connection.py", line 704, in connect
  File "urllib3\connection.py", line 207, in _new_conn
urllib3.exceptions.ConnectTimeoutError: (<urllib3.connection.HTTPSConnection object at 0x000001A378F4EA20>, 'Connection to api.github.com timed out. (connect timeout=None)')

The above exception was the direct cause of the following exception:

Traceback (most recent call last):
  File "requests\adapters.py", line 667, in send
  File "urllib3\connectionpool.py", line 841, in urlopen
  File "urllib3\util\retry.py", line 519, in increment
urllib3.exceptions.MaxRetryError: HTTPSConnectionPool(host='api.github.com', port=443): Max retries exceeded with url: /repos/Ilikectrlmusic/auto_ip/contents/781_result/2025-03-21.txt (Caused by ConnectTimeoutError(<urllib3.connection.HTTPSConnection object at 0x000001A378F4EA20>, 'Connection to api.github.com timed out. (connect timeout=None)'))

During handling of the above exception, another exception occurred:

Traceback (most recent call last):
  File "main.py", line 339, in <module>
  File "main.py", line 307, in upload_result
  File "requests\api.py", line 130, in put
  File "requests\api.py", line 59, in request
  File "requests\sessions.py", line 589, in request
  File "requests\sessions.py", line 703, in send
  File "requests\adapters.py", line 688, in send
requests.exceptions.ConnectTimeout: HTTPSConnectionPool(host='api.github.com', port=443): Max retries exceeded with url: /repos/Ilikectrlmusic/auto_ip/contents/781_result/2025-03-21.txt (Caused by ConnectTimeoutError(<urllib3.connection.HTTPSConnection object at 0x000001A378F4EA20>, 'Connection to api.github.com timed out. (connect timeout=None)'))

