Error during execution: Traceback (most recent call last):
  File "urllib3\connection.py", line 198, in _new_conn
  File "urllib3\util\connection.py", line 85, in create_connection
  File "urllib3\util\connection.py", line 73, in create_connection
TimeoutError: [WinError 10060] 由于连接方在一段时间后没有正确答复或连接的主机没有反应，连接尝试失败。

The above exception was the direct cause of the following exception:

Traceback (most recent call last):
  File "urllib3\connectionpool.py", line 787, in urlopen
  File "urllib3\connectionpool.py", line 488, in _make_request
  File "urllib3\connectionpool.py", line 464, in _make_request
  File "urllib3\connectionpool.py", line 1093, in _validate_conn
  File "urllib3\connection.py", line 704, in connect
  File "urllib3\connection.py", line 207, in _new_conn
urllib3.exceptions.ConnectTimeoutError: (<urllib3.connection.HTTPSConnection object at 0x0000023F6CB60E90>, 'Connection to api.github.com timed out. (connect timeout=None)')

The above exception was the direct cause of the following exception:

Traceback (most recent call last):
  File "requests\adapters.py", line 667, in send
  File "urllib3\connectionpool.py", line 841, in urlopen
  File "urllib3\util\retry.py", line 519, in increment
urllib3.exceptions.MaxRetryError: HTTPSConnectionPool(host='api.github.com', port=443): Max retries exceeded with url: /repos/Ilikectrlmusic/auto_ip/contents/781_result/2025-02-14.txt (Caused by ConnectTimeoutError(<urllib3.connection.HTTPSConnection object at 0x0000023F6CB60E90>, 'Connection to api.github.com timed out. (connect timeout=None)'))

During handling of the above exception, another exception occurred:

Traceback (most recent call last):
  File "main.py", line 339, in <module>
  File "main.py", line 288, in upload_result
  File "requests\api.py", line 73, in get
  File "requests\api.py", line 59, in request
  File "requests\sessions.py", line 589, in request
  File "requests\sessions.py", line 703, in send
  File "requests\adapters.py", line 688, in send
requests.exceptions.ConnectTimeout: HTTPSConnectionPool(host='api.github.com', port=443): Max retries exceeded with url: /repos/Ilikectrlmusic/auto_ip/contents/781_result/2025-02-14.txt (Caused by ConnectTimeoutError(<urllib3.connection.HTTPSConnection object at 0x0000023F6CB60E90>, 'Connection to api.github.com timed out. (connect timeout=None)'))

Error during execution: Traceback (most recent call last):
  File "urllib3\connection.py", line 198, in _new_conn
  File "urllib3\util\connection.py", line 85, in create_connection
  File "urllib3\util\connection.py", line 73, in create_connection
TimeoutError: [WinError 10060] 由于连接方在一段时间后没有正确答复或连接的主机没有反应，连接尝试失败。

The above exception was the direct cause of the following exception:

Traceback (most recent call last):
  File "urllib3\connectionpool.py", line 787, in urlopen
  File "urllib3\connectionpool.py", line 488, in _make_request
  File "urllib3\connectionpool.py", line 464, in _make_request
  File "urllib3\connectionpool.py", line 1093, in _validate_conn
  File "urllib3\connection.py", line 704, in connect
  File "urllib3\connection.py", line 207, in _new_conn
urllib3.exceptions.ConnectTimeoutError: (<urllib3.connection.HTTPSConnection object at 0x0000023F6CB63AD0>, 'Connection to api.github.com timed out. (connect timeout=None)')

The above exception was the direct cause of the following exception:

Traceback (most recent call last):
  File "requests\adapters.py", line 667, in send
  File "urllib3\connectionpool.py", line 841, in urlopen
  File "urllib3\util\retry.py", line 519, in increment
urllib3.exceptions.MaxRetryError: HTTPSConnectionPool(host='api.github.com', port=443): Max retries exceeded with url: /repos/Ilikectrlmusic/auto_ip/contents/781_result/2025-02-14.txt (Caused by ConnectTimeoutError(<urllib3.connection.HTTPSConnection object at 0x0000023F6CB63AD0>, 'Connection to api.github.com timed out. (connect timeout=None)'))

During handling of the above exception, another exception occurred:

Traceback (most recent call last):
  File "main.py", line 339, in <module>
  File "main.py", line 288, in upload_result
  File "requests\api.py", line 73, in get
  File "requests\api.py", line 59, in request
  File "requests\sessions.py", line 589, in request
  File "requests\sessions.py", line 703, in send
  File "requests\adapters.py", line 688, in send
requests.exceptions.ConnectTimeout: HTTPSConnectionPool(host='api.github.com', port=443): Max retries exceeded with url: /repos/Ilikectrlmusic/auto_ip/contents/781_result/2025-02-14.txt (Caused by ConnectTimeoutError(<urllib3.connection.HTTPSConnection object at 0x0000023F6CB63AD0>, 'Connection to api.github.com timed out. (connect timeout=None)'))

Error during execution: Traceback (most recent call last):
  File "urllib3\connection.py", line 198, in _new_conn
  File "urllib3\util\connection.py", line 85, in create_connection
  File "urllib3\util\connection.py", line 73, in create_connection
TimeoutError: [WinError 10060] 由于连接方在一段时间后没有正确答复或连接的主机没有反应，连接尝试失败。

The above exception was the direct cause of the following exception:

Traceback (most recent call last):
  File "urllib3\connectionpool.py", line 787, in urlopen
  File "urllib3\connectionpool.py", line 488, in _make_request
  File "urllib3\connectionpool.py", line 464, in _make_request
  File "urllib3\connectionpool.py", line 1093, in _validate_conn
  File "urllib3\connection.py", line 704, in connect
  File "urllib3\connection.py", line 207, in _new_conn
urllib3.exceptions.ConnectTimeoutError: (<urllib3.connection.HTTPSConnection object at 0x0000023F6CBA0CB0>, 'Connection to api.github.com timed out. (connect timeout=None)')

The above exception was the direct cause of the following exception:

Traceback (most recent call last):
  File "requests\adapters.py", line 667, in send
  File "urllib3\connectionpool.py", line 841, in urlopen
  File "urllib3\util\retry.py", line 519, in increment
urllib3.exceptions.MaxRetryError: HTTPSConnectionPool(host='api.github.com', port=443): Max retries exceeded with url: /repos/Ilikectrlmusic/auto_ip/contents/781_result/2025-02-14.txt (Caused by ConnectTimeoutError(<urllib3.connection.HTTPSConnection object at 0x0000023F6CBA0CB0>, 'Connection to api.github.com timed out. (connect timeout=None)'))

During handling of the above exception, another exception occurred:

Traceback (most recent call last):
  File "main.py", line 339, in <module>
  File "main.py", line 307, in upload_result
  File "requests\api.py", line 130, in put
  File "requests\api.py", line 59, in request
  File "requests\sessions.py", line 589, in request
  File "requests\sessions.py", line 703, in send
  File "requests\adapters.py", line 688, in send
requests.exceptions.ConnectTimeout: HTTPSConnectionPool(host='api.github.com', port=443): Max retries exceeded with url: /repos/Ilikectrlmusic/auto_ip/contents/781_result/2025-02-14.txt (Caused by ConnectTimeoutError(<urllib3.connection.HTTPSConnection object at 0x0000023F6CBA0CB0>, 'Connection to api.github.com timed out. (connect timeout=None)'))

Error during execution: Traceback (most recent call last):
  File "urllib3\connection.py", line 198, in _new_conn
  File "urllib3\util\connection.py", line 85, in create_connection
  File "urllib3\util\connection.py", line 73, in create_connection
TimeoutError: [WinError 10060] 由于连接方在一段时间后没有正确答复或连接的主机没有反应，连接尝试失败。

The above exception was the direct cause of the following exception:

Traceback (most recent call last):
  File "urllib3\connectionpool.py", line 787, in urlopen
  File "urllib3\connectionpool.py", line 488, in _make_request
  File "urllib3\connectionpool.py", line 464, in _make_request
  File "urllib3\connectionpool.py", line 1093, in _validate_conn
  File "urllib3\connection.py", line 704, in connect
  File "urllib3\connection.py", line 207, in _new_conn
urllib3.exceptions.ConnectTimeoutError: (<urllib3.connection.HTTPSConnection object at 0x0000023F6CB940B0>, 'Connection to api.github.com timed out. (connect timeout=None)')

The above exception was the direct cause of the following exception:

Traceback (most recent call last):
  File "requests\adapters.py", line 667, in send
  File "urllib3\connectionpool.py", line 841, in urlopen
  File "urllib3\util\retry.py", line 519, in increment
urllib3.exceptions.MaxRetryError: HTTPSConnectionPool(host='api.github.com', port=443): Max retries exceeded with url: /repos/Ilikectrlmusic/auto_ip/contents/781_result/2025-02-14.txt (Caused by ConnectTimeoutError(<urllib3.connection.HTTPSConnection object at 0x0000023F6CB940B0>, 'Connection to api.github.com timed out. (connect timeout=None)'))

During handling of the above exception, another exception occurred:

Traceback (most recent call last):
  File "main.py", line 339, in <module>
  File "main.py", line 288, in upload_result
  File "requests\api.py", line 73, in get
  File "requests\api.py", line 59, in request
  File "requests\sessions.py", line 589, in request
  File "requests\sessions.py", line 703, in send
  File "requests\adapters.py", line 688, in send
requests.exceptions.ConnectTimeout: HTTPSConnectionPool(host='api.github.com', port=443): Max retries exceeded with url: /repos/Ilikectrlmusic/auto_ip/contents/781_result/2025-02-14.txt (Caused by ConnectTimeoutError(<urllib3.connection.HTTPSConnection object at 0x0000023F6CB940B0>, 'Connection to api.github.com timed out. (connect timeout=None)'))

Error during execution: Traceback (most recent call last):
  File "urllib3\connection.py", line 198, in _new_conn
  File "urllib3\util\connection.py", line 85, in create_connection
  File "urllib3\util\connection.py", line 73, in create_connection
TimeoutError: [WinError 10060] 由于连接方在一段时间后没有正确答复或连接的主机没有反应，连接尝试失败。

The above exception was the direct cause of the following exception:

Traceback (most recent call last):
  File "urllib3\connectionpool.py", line 787, in urlopen
  File "urllib3\connectionpool.py", line 488, in _make_request
  File "urllib3\connectionpool.py", line 464, in _make_request
  File "urllib3\connectionpool.py", line 1093, in _validate_conn
  File "urllib3\connection.py", line 704, in connect
  File "urllib3\connection.py", line 207, in _new_conn
urllib3.exceptions.ConnectTimeoutError: (<urllib3.connection.HTTPSConnection object at 0x0000023F6CBBCB60>, 'Connection to api.github.com timed out. (connect timeout=None)')

The above exception was the direct cause of the following exception:

Traceback (most recent call last):
  File "requests\adapters.py", line 667, in send
  File "urllib3\connectionpool.py", line 841, in urlopen
  File "urllib3\util\retry.py", line 519, in increment
urllib3.exceptions.MaxRetryError: HTTPSConnectionPool(host='api.github.com', port=443): Max retries exceeded with url: /repos/Ilikectrlmusic/auto_ip/contents/781_result/2025-02-14.txt (Caused by ConnectTimeoutError(<urllib3.connection.HTTPSConnection object at 0x0000023F6CBBCB60>, 'Connection to api.github.com timed out. (connect timeout=None)'))

During handling of the above exception, another exception occurred:

Traceback (most recent call last):
  File "main.py", line 339, in <module>
  File "main.py", line 307, in upload_result
  File "requests\api.py", line 130, in put
  File "requests\api.py", line 59, in request
  File "requests\sessions.py", line 589, in request
  File "requests\sessions.py", line 703, in send
  File "requests\adapters.py", line 688, in send
requests.exceptions.ConnectTimeout: HTTPSConnectionPool(host='api.github.com', port=443): Max retries exceeded with url: /repos/Ilikectrlmusic/auto_ip/contents/781_result/2025-02-14.txt (Caused by ConnectTimeoutError(<urllib3.connection.HTTPSConnection object at 0x0000023F6CBBCB60>, 'Connection to api.github.com timed out. (connect timeout=None)'))

Error during execution: Traceback (most recent call last):
  File "urllib3\connection.py", line 198, in _new_conn
  File "urllib3\util\connection.py", line 85, in create_connection
  File "urllib3\util\connection.py", line 73, in create_connection
TimeoutError: [WinError 10060] 由于连接方在一段时间后没有正确答复或连接的主机没有反应，连接尝试失败。

The above exception was the direct cause of the following exception:

Traceback (most recent call last):
  File "urllib3\connectionpool.py", line 787, in urlopen
  File "urllib3\connectionpool.py", line 488, in _make_request
  File "urllib3\connectionpool.py", line 464, in _make_request
  File "urllib3\connectionpool.py", line 1093, in _validate_conn
  File "urllib3\connection.py", line 704, in connect
  File "urllib3\connection.py", line 207, in _new_conn
urllib3.exceptions.ConnectTimeoutError: (<urllib3.connection.HTTPSConnection object at 0x0000023F6CB95BE0>, 'Connection to api.github.com timed out. (connect timeout=None)')

The above exception was the direct cause of the following exception:

Traceback (most recent call last):
  File "requests\adapters.py", line 667, in send
  File "urllib3\connectionpool.py", line 841, in urlopen
  File "urllib3\util\retry.py", line 519, in increment
urllib3.exceptions.MaxRetryError: HTTPSConnectionPool(host='api.github.com', port=443): Max retries exceeded with url: /repos/Ilikectrlmusic/auto_ip/contents/781_result/2025-02-14.txt (Caused by ConnectTimeoutError(<urllib3.connection.HTTPSConnection object at 0x0000023F6CB95BE0>, 'Connection to api.github.com timed out. (connect timeout=None)'))

During handling of the above exception, another exception occurred:

Traceback (most recent call last):
  File "main.py", line 339, in <module>
  File "main.py", line 288, in upload_result
  File "requests\api.py", line 73, in get
  File "requests\api.py", line 59, in request
  File "requests\sessions.py", line 589, in request
  File "requests\sessions.py", line 703, in send
  File "requests\adapters.py", line 688, in send
requests.exceptions.ConnectTimeout: HTTPSConnectionPool(host='api.github.com', port=443): Max retries exceeded with url: /repos/Ilikectrlmusic/auto_ip/contents/781_result/2025-02-14.txt (Caused by ConnectTimeoutError(<urllib3.connection.HTTPSConnection object at 0x0000023F6CB95BE0>, 'Connection to api.github.com timed out. (connect timeout=None)'))

Error during execution: Traceback (most recent call last):
  File "urllib3\connection.py", line 198, in _new_conn
  File "urllib3\util\connection.py", line 85, in create_connection
  File "urllib3\util\connection.py", line 73, in create_connection
TimeoutError: [WinError 10060] 由于连接方在一段时间后没有正确答复或连接的主机没有反应，连接尝试失败。

The above exception was the direct cause of the following exception:

Traceback (most recent call last):
  File "urllib3\connectionpool.py", line 787, in urlopen
  File "urllib3\connectionpool.py", line 488, in _make_request
  File "urllib3\connectionpool.py", line 464, in _make_request
  File "urllib3\connectionpool.py", line 1093, in _validate_conn
  File "urllib3\connection.py", line 704, in connect
  File "urllib3\connection.py", line 207, in _new_conn
urllib3.exceptions.ConnectTimeoutError: (<urllib3.connection.HTTPSConnection object at 0x0000023F6CB977A0>, 'Connection to api.github.com timed out. (connect timeout=None)')

The above exception was the direct cause of the following exception:

Traceback (most recent call last):
  File "requests\adapters.py", line 667, in send
  File "urllib3\connectionpool.py", line 841, in urlopen
  File "urllib3\util\retry.py", line 519, in increment
urllib3.exceptions.MaxRetryError: HTTPSConnectionPool(host='api.github.com', port=443): Max retries exceeded with url: /repos/Ilikectrlmusic/auto_ip/contents/781_result/2025-02-14.txt (Caused by ConnectTimeoutError(<urllib3.connection.HTTPSConnection object at 0x0000023F6CB977A0>, 'Connection to api.github.com timed out. (connect timeout=None)'))

During handling of the above exception, another exception occurred:

Traceback (most recent call last):
  File "main.py", line 339, in <module>
  File "main.py", line 307, in upload_result
  File "requests\api.py", line 130, in put
  File "requests\api.py", line 59, in request
  File "requests\sessions.py", line 589, in request
  File "requests\sessions.py", line 703, in send
  File "requests\adapters.py", line 688, in send
requests.exceptions.ConnectTimeout: HTTPSConnectionPool(host='api.github.com', port=443): Max retries exceeded with url: /repos/Ilikectrlmusic/auto_ip/contents/781_result/2025-02-14.txt (Caused by ConnectTimeoutError(<urllib3.connection.HTTPSConnection object at 0x0000023F6CB977A0>, 'Connection to api.github.com timed out. (connect timeout=None)'))

Error during execution: Traceback (most recent call last):
  File "urllib3\connection.py", line 198, in _new_conn
  File "urllib3\util\connection.py", line 85, in create_connection
  File "urllib3\util\connection.py", line 73, in create_connection
TimeoutError: [WinError 10060] 由于连接方在一段时间后没有正确答复或连接的主机没有反应，连接尝试失败。

The above exception was the direct cause of the following exception:

Traceback (most recent call last):
  File "urllib3\connectionpool.py", line 787, in urlopen
  File "urllib3\connectionpool.py", line 488, in _make_request
  File "urllib3\connectionpool.py", line 464, in _make_request
  File "urllib3\connectionpool.py", line 1093, in _validate_conn
  File "urllib3\connection.py", line 704, in connect
  File "urllib3\connection.py", line 207, in _new_conn
urllib3.exceptions.ConnectTimeoutError: (<urllib3.connection.HTTPSConnection object at 0x0000023F6CB63380>, 'Connection to api.github.com timed out. (connect timeout=None)')

The above exception was the direct cause of the following exception:

Traceback (most recent call last):
  File "requests\adapters.py", line 667, in send
  File "urllib3\connectionpool.py", line 841, in urlopen
  File "urllib3\util\retry.py", line 519, in increment
urllib3.exceptions.MaxRetryError: HTTPSConnectionPool(host='api.github.com', port=443): Max retries exceeded with url: /repos/Ilikectrlmusic/auto_ip/contents/781_result/2025-02-14.txt (Caused by ConnectTimeoutError(<urllib3.connection.HTTPSConnection object at 0x0000023F6CB63380>, 'Connection to api.github.com timed out. (connect timeout=None)'))

During handling of the above exception, another exception occurred:

Traceback (most recent call last):
  File "main.py", line 339, in <module>
  File "main.py", line 307, in upload_result
  File "requests\api.py", line 130, in put
  File "requests\api.py", line 59, in request
  File "requests\sessions.py", line 589, in request
  File "requests\sessions.py", line 703, in send
  File "requests\adapters.py", line 688, in send
requests.exceptions.ConnectTimeout: HTTPSConnectionPool(host='api.github.com', port=443): Max retries exceeded with url: /repos/Ilikectrlmusic/auto_ip/contents/781_result/2025-02-14.txt (Caused by ConnectTimeoutError(<urllib3.connection.HTTPSConnection object at 0x0000023F6CB63380>, 'Connection to api.github.com timed out. (connect timeout=None)'))

Error during execution: Traceback (most recent call last):
  File "urllib3\connection.py", line 198, in _new_conn
  File "urllib3\util\connection.py", line 85, in create_connection
  File "urllib3\util\connection.py", line 73, in create_connection
TimeoutError: [WinError 10060] 由于连接方在一段时间后没有正确答复或连接的主机没有反应，连接尝试失败。

The above exception was the direct cause of the following exception:

Traceback (most recent call last):
  File "urllib3\connectionpool.py", line 787, in urlopen
  File "urllib3\connectionpool.py", line 488, in _make_request
  File "urllib3\connectionpool.py", line 464, in _make_request
  File "urllib3\connectionpool.py", line 1093, in _validate_conn
  File "urllib3\connection.py", line 704, in connect
  File "urllib3\connection.py", line 207, in _new_conn
urllib3.exceptions.ConnectTimeoutError: (<urllib3.connection.HTTPSConnection object at 0x0000023F6CBA2180>, 'Connection to api.github.com timed out. (connect timeout=None)')

The above exception was the direct cause of the following exception:

Traceback (most recent call last):
  File "requests\adapters.py", line 667, in send
  File "urllib3\connectionpool.py", line 841, in urlopen
  File "urllib3\util\retry.py", line 519, in increment
urllib3.exceptions.MaxRetryError: HTTPSConnectionPool(host='api.github.com', port=443): Max retries exceeded with url: /repos/Ilikectrlmusic/auto_ip/contents/781_result/2025-02-14.txt (Caused by ConnectTimeoutError(<urllib3.connection.HTTPSConnection object at 0x0000023F6CBA2180>, 'Connection to api.github.com timed out. (connect timeout=None)'))

During handling of the above exception, another exception occurred:

Traceback (most recent call last):
  File "main.py", line 339, in <module>
  File "main.py", line 307, in upload_result
  File "requests\api.py", line 130, in put
  File "requests\api.py", line 59, in request
  File "requests\sessions.py", line 589, in request
  File "requests\sessions.py", line 703, in send
  File "requests\adapters.py", line 688, in send
requests.exceptions.ConnectTimeout: HTTPSConnectionPool(host='api.github.com', port=443): Max retries exceeded with url: /repos/Ilikectrlmusic/auto_ip/contents/781_result/2025-02-14.txt (Caused by ConnectTimeoutError(<urllib3.connection.HTTPSConnection object at 0x0000023F6CBA2180>, 'Connection to api.github.com timed out. (connect timeout=None)'))

Error during execution: Traceback (most recent call last):
  File "urllib3\connection.py", line 198, in _new_conn
  File "urllib3\util\connection.py", line 85, in create_connection
  File "urllib3\util\connection.py", line 73, in create_connection
TimeoutError: [WinError 10060] 由于连接方在一段时间后没有正确答复或连接的主机没有反应，连接尝试失败。

The above exception was the direct cause of the following exception:

Traceback (most recent call last):
  File "urllib3\connectionpool.py", line 787, in urlopen
  File "urllib3\connectionpool.py", line 488, in _make_request
  File "urllib3\connectionpool.py", line 464, in _make_request
  File "urllib3\connectionpool.py", line 1093, in _validate_conn
  File "urllib3\connection.py", line 704, in connect
  File "urllib3\connection.py", line 207, in _new_conn
urllib3.exceptions.ConnectTimeoutError: (<urllib3.connection.HTTPSConnection object at 0x0000023F6CBCC530>, 'Connection to api.github.com timed out. (connect timeout=None)')

The above exception was the direct cause of the following exception:

Traceback (most recent call last):
  File "requests\adapters.py", line 667, in send
  File "urllib3\connectionpool.py", line 841, in urlopen
  File "urllib3\util\retry.py", line 519, in increment
urllib3.exceptions.MaxRetryError: HTTPSConnectionPool(host='api.github.com', port=443): Max retries exceeded with url: /repos/Ilikectrlmusic/auto_ip/contents/781_result/2025-02-14.txt (Caused by ConnectTimeoutError(<urllib3.connection.HTTPSConnection object at 0x0000023F6CBCC530>, 'Connection to api.github.com timed out. (connect timeout=None)'))

During handling of the above exception, another exception occurred:

Traceback (most recent call last):
  File "main.py", line 339, in <module>
  File "main.py", line 307, in upload_result
  File "requests\api.py", line 130, in put
  File "requests\api.py", line 59, in request
  File "requests\sessions.py", line 589, in request
  File "requests\sessions.py", line 703, in send
  File "requests\adapters.py", line 688, in send
requests.exceptions.ConnectTimeout: HTTPSConnectionPool(host='api.github.com', port=443): Max retries exceeded with url: /repos/Ilikectrlmusic/auto_ip/contents/781_result/2025-02-14.txt (Caused by ConnectTimeoutError(<urllib3.connection.HTTPSConnection object at 0x0000023F6CBCC530>, 'Connection to api.github.com timed out. (connect timeout=None)'))

Error during execution: Traceback (most recent call last):
  File "urllib3\connection.py", line 198, in _new_conn
  File "urllib3\util\connection.py", line 85, in create_connection
  File "urllib3\util\connection.py", line 73, in create_connection
TimeoutError: [WinError 10060] 由于连接方在一段时间后没有正确答复或连接的主机没有反应，连接尝试失败。

The above exception was the direct cause of the following exception:

Traceback (most recent call last):
  File "urllib3\connectionpool.py", line 787, in urlopen
  File "urllib3\connectionpool.py", line 488, in _make_request
  File "urllib3\connectionpool.py", line 464, in _make_request
  File "urllib3\connectionpool.py", line 1093, in _validate_conn
  File "urllib3\connection.py", line 704, in connect
  File "urllib3\connection.py", line 207, in _new_conn
urllib3.exceptions.ConnectTimeoutError: (<urllib3.connection.HTTPSConnection object at 0x0000023F6CBBF290>, 'Connection to api.github.com timed out. (connect timeout=None)')

The above exception was the direct cause of the following exception:

Traceback (most recent call last):
  File "requests\adapters.py", line 667, in send
  File "urllib3\connectionpool.py", line 841, in urlopen
  File "urllib3\util\retry.py", line 519, in increment
urllib3.exceptions.MaxRetryError: HTTPSConnectionPool(host='api.github.com', port=443): Max retries exceeded with url: /repos/Ilikectrlmusic/auto_ip/contents/781_result/2025-02-14.txt (Caused by ConnectTimeoutError(<urllib3.connection.HTTPSConnection object at 0x0000023F6CBBF290>, 'Connection to api.github.com timed out. (connect timeout=None)'))

During handling of the above exception, another exception occurred:

Traceback (most recent call last):
  File "main.py", line 339, in <module>
  File "main.py", line 307, in upload_result
  File "requests\api.py", line 130, in put
  File "requests\api.py", line 59, in request
  File "requests\sessions.py", line 589, in request
  File "requests\sessions.py", line 703, in send
  File "requests\adapters.py", line 688, in send
requests.exceptions.ConnectTimeout: HTTPSConnectionPool(host='api.github.com', port=443): Max retries exceeded with url: /repos/Ilikectrlmusic/auto_ip/contents/781_result/2025-02-14.txt (Caused by ConnectTimeoutError(<urllib3.connection.HTTPSConnection object at 0x0000023F6CBBF290>, 'Connection to api.github.com timed out. (connect timeout=None)'))

Error during execution: Traceback (most recent call last):
  File "urllib3\connection.py", line 198, in _new_conn
  File "urllib3\util\connection.py", line 85, in create_connection
  File "urllib3\util\connection.py", line 73, in create_connection
TimeoutError: [WinError 10060] 由于连接方在一段时间后没有正确答复或连接的主机没有反应，连接尝试失败。

The above exception was the direct cause of the following exception:

Traceback (most recent call last):
  File "urllib3\connectionpool.py", line 787, in urlopen
  File "urllib3\connectionpool.py", line 488, in _make_request
  File "urllib3\connectionpool.py", line 464, in _make_request
  File "urllib3\connectionpool.py", line 1093, in _validate_conn
  File "urllib3\connection.py", line 704, in connect
  File "urllib3\connection.py", line 207, in _new_conn
urllib3.exceptions.ConnectTimeoutError: (<urllib3.connection.HTTPSConnection object at 0x0000023F6CBBDC40>, 'Connection to api.github.com timed out. (connect timeout=None)')

The above exception was the direct cause of the following exception:

Traceback (most recent call last):
  File "requests\adapters.py", line 667, in send
  File "urllib3\connectionpool.py", line 841, in urlopen
  File "urllib3\util\retry.py", line 519, in increment
urllib3.exceptions.MaxRetryError: HTTPSConnectionPool(host='api.github.com', port=443): Max retries exceeded with url: /repos/Ilikectrlmusic/auto_ip/contents/781_result/2025-02-14.txt (Caused by ConnectTimeoutError(<urllib3.connection.HTTPSConnection object at 0x0000023F6CBBDC40>, 'Connection to api.github.com timed out. (connect timeout=None)'))

During handling of the above exception, another exception occurred:

Traceback (most recent call last):
  File "main.py", line 339, in <module>
  File "main.py", line 288, in upload_result
  File "requests\api.py", line 73, in get
  File "requests\api.py", line 59, in request
  File "requests\sessions.py", line 589, in request
  File "requests\sessions.py", line 703, in send
  File "requests\adapters.py", line 688, in send
requests.exceptions.ConnectTimeout: HTTPSConnectionPool(host='api.github.com', port=443): Max retries exceeded with url: /repos/Ilikectrlmusic/auto_ip/contents/781_result/2025-02-14.txt (Caused by ConnectTimeoutError(<urllib3.connection.HTTPSConnection object at 0x0000023F6CBBDC40>, 'Connection to api.github.com timed out. (connect timeout=None)'))

Error during execution: Traceback (most recent call last):
  File "urllib3\connection.py", line 198, in _new_conn
  File "urllib3\util\connection.py", line 85, in create_connection
  File "urllib3\util\connection.py", line 73, in create_connection
TimeoutError: [WinError 10060] 由于连接方在一段时间后没有正确答复或连接的主机没有反应，连接尝试失败。

The above exception was the direct cause of the following exception:

Traceback (most recent call last):
  File "urllib3\connectionpool.py", line 787, in urlopen
  File "urllib3\connectionpool.py", line 488, in _make_request
  File "urllib3\connectionpool.py", line 464, in _make_request
  File "urllib3\connectionpool.py", line 1093, in _validate_conn
  File "urllib3\connection.py", line 704, in connect
  File "urllib3\connection.py", line 207, in _new_conn
urllib3.exceptions.ConnectTimeoutError: (<urllib3.connection.HTTPSConnection object at 0x0000023F6CBBF980>, 'Connection to api.github.com timed out. (connect timeout=None)')

The above exception was the direct cause of the following exception:

Traceback (most recent call last):
  File "requests\adapters.py", line 667, in send
  File "urllib3\connectionpool.py", line 841, in urlopen
  File "urllib3\util\retry.py", line 519, in increment
urllib3.exceptions.MaxRetryError: HTTPSConnectionPool(host='api.github.com', port=443): Max retries exceeded with url: /repos/Ilikectrlmusic/auto_ip/contents/781_result/2025-02-14.txt (Caused by ConnectTimeoutError(<urllib3.connection.HTTPSConnection object at 0x0000023F6CBBF980>, 'Connection to api.github.com timed out. (connect timeout=None)'))

During handling of the above exception, another exception occurred:

Traceback (most recent call last):
  File "main.py", line 339, in <module>
  File "main.py", line 307, in upload_result
  File "requests\api.py", line 130, in put
  File "requests\api.py", line 59, in request
  File "requests\sessions.py", line 589, in request
  File "requests\sessions.py", line 703, in send
  File "requests\adapters.py", line 688, in send
requests.exceptions.ConnectTimeout: HTTPSConnectionPool(host='api.github.com', port=443): Max retries exceeded with url: /repos/Ilikectrlmusic/auto_ip/contents/781_result/2025-02-14.txt (Caused by ConnectTimeoutError(<urllib3.connection.HTTPSConnection object at 0x0000023F6CBBF980>, 'Connection to api.github.com timed out. (connect timeout=None)'))

Error during execution: Traceback (most recent call last):
  File "urllib3\connection.py", line 198, in _new_conn
  File "urllib3\util\connection.py", line 85, in create_connection
  File "urllib3\util\connection.py", line 73, in create_connection
TimeoutError: [WinError 10060] 由于连接方在一段时间后没有正确答复或连接的主机没有反应，连接尝试失败。

The above exception was the direct cause of the following exception:

Traceback (most recent call last):
  File "urllib3\connectionpool.py", line 787, in urlopen
  File "urllib3\connectionpool.py", line 488, in _make_request
  File "urllib3\connectionpool.py", line 464, in _make_request
  File "urllib3\connectionpool.py", line 1093, in _validate_conn
  File "urllib3\connection.py", line 704, in connect
  File "urllib3\connection.py", line 207, in _new_conn
urllib3.exceptions.ConnectTimeoutError: (<urllib3.connection.HTTPSConnection object at 0x0000023F6CBA3DD0>, 'Connection to api.github.com timed out. (connect timeout=None)')

The above exception was the direct cause of the following exception:

Traceback (most recent call last):
  File "requests\adapters.py", line 667, in send
  File "urllib3\connectionpool.py", line 841, in urlopen
  File "urllib3\util\retry.py", line 519, in increment
urllib3.exceptions.MaxRetryError: HTTPSConnectionPool(host='api.github.com', port=443): Max retries exceeded with url: /repos/Ilikectrlmusic/auto_ip/contents/781_result/2025-02-14.txt (Caused by ConnectTimeoutError(<urllib3.connection.HTTPSConnection object at 0x0000023F6CBA3DD0>, 'Connection to api.github.com timed out. (connect timeout=None)'))

During handling of the above exception, another exception occurred:

Traceback (most recent call last):
  File "main.py", line 339, in <module>
  File "main.py", line 307, in upload_result
  File "requests\api.py", line 130, in put
  File "requests\api.py", line 59, in request
  File "requests\sessions.py", line 589, in request
  File "requests\sessions.py", line 703, in send
  File "requests\adapters.py", line 688, in send
requests.exceptions.ConnectTimeout: HTTPSConnectionPool(host='api.github.com', port=443): Max retries exceeded with url: /repos/Ilikectrlmusic/auto_ip/contents/781_result/2025-02-14.txt (Caused by ConnectTimeoutError(<urllib3.connection.HTTPSConnection object at 0x0000023F6CBA3DD0>, 'Connection to api.github.com timed out. (connect timeout=None)'))

Error during execution: Traceback (most recent call last):
  File "urllib3\connection.py", line 198, in _new_conn
  File "urllib3\util\connection.py", line 85, in create_connection
  File "urllib3\util\connection.py", line 73, in create_connection
TimeoutError: [WinError 10060] 由于连接方在一段时间后没有正确答复或连接的主机没有反应，连接尝试失败。

The above exception was the direct cause of the following exception:

Traceback (most recent call last):
  File "urllib3\connectionpool.py", line 787, in urlopen
  File "urllib3\connectionpool.py", line 488, in _make_request
  File "urllib3\connectionpool.py", line 464, in _make_request
  File "urllib3\connectionpool.py", line 1093, in _validate_conn
  File "urllib3\connection.py", line 704, in connect
  File "urllib3\connection.py", line 207, in _new_conn
urllib3.exceptions.ConnectTimeoutError: (<urllib3.connection.HTTPSConnection object at 0x0000023F6CB94A10>, 'Connection to api.github.com timed out. (connect timeout=None)')

The above exception was the direct cause of the following exception:

Traceback (most recent call last):
  File "requests\adapters.py", line 667, in send
  File "urllib3\connectionpool.py", line 841, in urlopen
  File "urllib3\util\retry.py", line 519, in increment
urllib3.exceptions.MaxRetryError: HTTPSConnectionPool(host='api.github.com', port=443): Max retries exceeded with url: /repos/Ilikectrlmusic/auto_ip/contents/781_result/2025-02-14.txt (Caused by ConnectTimeoutError(<urllib3.connection.HTTPSConnection object at 0x0000023F6CB94A10>, 'Connection to api.github.com timed out. (connect timeout=None)'))

During handling of the above exception, another exception occurred:

Traceback (most recent call last):
  File "main.py", line 339, in <module>
  File "main.py", line 307, in upload_result
  File "requests\api.py", line 130, in put
  File "requests\api.py", line 59, in request
  File "requests\sessions.py", line 589, in request
  File "requests\sessions.py", line 703, in send
  File "requests\adapters.py", line 688, in send
requests.exceptions.ConnectTimeout: HTTPSConnectionPool(host='api.github.com', port=443): Max retries exceeded with url: /repos/Ilikectrlmusic/auto_ip/contents/781_result/2025-02-14.txt (Caused by ConnectTimeoutError(<urllib3.connection.HTTPSConnection object at 0x0000023F6CB94A10>, 'Connection to api.github.com timed out. (connect timeout=None)'))

Error during execution: Traceback (most recent call last):
  File "urllib3\connection.py", line 198, in _new_conn
  File "urllib3\util\connection.py", line 85, in create_connection
  File "urllib3\util\connection.py", line 73, in create_connection
TimeoutError: [WinError 10060] 由于连接方在一段时间后没有正确答复或连接的主机没有反应，连接尝试失败。

The above exception was the direct cause of the following exception:

Traceback (most recent call last):
  File "urllib3\connectionpool.py", line 787, in urlopen
  File "urllib3\connectionpool.py", line 488, in _make_request
  File "urllib3\connectionpool.py", line 464, in _make_request
  File "urllib3\connectionpool.py", line 1093, in _validate_conn
  File "urllib3\connection.py", line 704, in connect
  File "urllib3\connection.py", line 207, in _new_conn
urllib3.exceptions.ConnectTimeoutError: (<urllib3.connection.HTTPSConnection object at 0x0000023F6CB61160>, 'Connection to api.github.com timed out. (connect timeout=None)')

The above exception was the direct cause of the following exception:

Traceback (most recent call last):
  File "requests\adapters.py", line 667, in send
  File "urllib3\connectionpool.py", line 841, in urlopen
  File "urllib3\util\retry.py", line 519, in increment
urllib3.exceptions.MaxRetryError: HTTPSConnectionPool(host='api.github.com', port=443): Max retries exceeded with url: /repos/Ilikectrlmusic/auto_ip/contents/781_result/2025-02-14.txt (Caused by ConnectTimeoutError(<urllib3.connection.HTTPSConnection object at 0x0000023F6CB61160>, 'Connection to api.github.com timed out. (connect timeout=None)'))

During handling of the above exception, another exception occurred:

Traceback (most recent call last):
  File "main.py", line 339, in <module>
  File "main.py", line 288, in upload_result
  File "requests\api.py", line 73, in get
  File "requests\api.py", line 59, in request
  File "requests\sessions.py", line 589, in request
  File "requests\sessions.py", line 703, in send
  File "requests\adapters.py", line 688, in send
requests.exceptions.ConnectTimeout: HTTPSConnectionPool(host='api.github.com', port=443): Max retries exceeded with url: /repos/Ilikectrlmusic/auto_ip/contents/781_result/2025-02-14.txt (Caused by ConnectTimeoutError(<urllib3.connection.HTTPSConnection object at 0x0000023F6CB61160>, 'Connection to api.github.com timed out. (connect timeout=None)'))

Error during execution: Traceback (most recent call last):
  File "urllib3\connection.py", line 198, in _new_conn
  File "urllib3\util\connection.py", line 85, in create_connection
  File "urllib3\util\connection.py", line 73, in create_connection
TimeoutError: [WinError 10060] 由于连接方在一段时间后没有正确答复或连接的主机没有反应，连接尝试失败。

The above exception was the direct cause of the following exception:

Traceback (most recent call last):
  File "urllib3\connectionpool.py", line 787, in urlopen
  File "urllib3\connectionpool.py", line 488, in _make_request
  File "urllib3\connectionpool.py", line 464, in _make_request
  File "urllib3\connectionpool.py", line 1093, in _validate_conn
  File "urllib3\connection.py", line 704, in connect
  File "urllib3\connection.py", line 207, in _new_conn
urllib3.exceptions.ConnectTimeoutError: (<urllib3.connection.HTTPSConnection object at 0x0000023F6CBA1DC0>, 'Connection to api.github.com timed out. (connect timeout=None)')

The above exception was the direct cause of the following exception:

Traceback (most recent call last):
  File "requests\adapters.py", line 667, in send
  File "urllib3\connectionpool.py", line 841, in urlopen
  File "urllib3\util\retry.py", line 519, in increment
urllib3.exceptions.MaxRetryError: HTTPSConnectionPool(host='api.github.com', port=443): Max retries exceeded with url: /repos/Ilikectrlmusic/auto_ip/contents/781_result/2025-02-14.txt (Caused by ConnectTimeoutError(<urllib3.connection.HTTPSConnection object at 0x0000023F6CBA1DC0>, 'Connection to api.github.com timed out. (connect timeout=None)'))

During handling of the above exception, another exception occurred:

Traceback (most recent call last):
  File "main.py", line 339, in <module>
  File "main.py", line 288, in upload_result
  File "requests\api.py", line 73, in get
  File "requests\api.py", line 59, in request
  File "requests\sessions.py", line 589, in request
  File "requests\sessions.py", line 703, in send
  File "requests\adapters.py", line 688, in send
requests.exceptions.ConnectTimeout: HTTPSConnectionPool(host='api.github.com', port=443): Max retries exceeded with url: /repos/Ilikectrlmusic/auto_ip/contents/781_result/2025-02-14.txt (Caused by ConnectTimeoutError(<urllib3.connection.HTTPSConnection object at 0x0000023F6CBA1DC0>, 'Connection to api.github.com timed out. (connect timeout=None)'))

Error during execution: Traceback (most recent call last):
  File "urllib3\connection.py", line 198, in _new_conn
  File "urllib3\util\connection.py", line 85, in create_connection
  File "urllib3\util\connection.py", line 73, in create_connection
TimeoutError: [WinError 10060] 由于连接方在一段时间后没有正确答复或连接的主机没有反应，连接尝试失败。

The above exception was the direct cause of the following exception:

Traceback (most recent call last):
  File "urllib3\connectionpool.py", line 787, in urlopen
  File "urllib3\connectionpool.py", line 488, in _make_request
  File "urllib3\connectionpool.py", line 464, in _make_request
  File "urllib3\connectionpool.py", line 1093, in _validate_conn
  File "urllib3\connection.py", line 704, in connect
  File "urllib3\connection.py", line 207, in _new_conn
urllib3.exceptions.ConnectTimeoutError: (<urllib3.connection.HTTPSConnection object at 0x0000023F6CB956D0>, 'Connection to api.github.com timed out. (connect timeout=None)')

The above exception was the direct cause of the following exception:

Traceback (most recent call last):
  File "requests\adapters.py", line 667, in send
  File "urllib3\connectionpool.py", line 841, in urlopen
  File "urllib3\util\retry.py", line 519, in increment
urllib3.exceptions.MaxRetryError: HTTPSConnectionPool(host='api.github.com', port=443): Max retries exceeded with url: /repos/Ilikectrlmusic/auto_ip/contents/781_result/2025-02-14.txt (Caused by ConnectTimeoutError(<urllib3.connection.HTTPSConnection object at 0x0000023F6CB956D0>, 'Connection to api.github.com timed out. (connect timeout=None)'))

During handling of the above exception, another exception occurred:

Traceback (most recent call last):
  File "main.py", line 339, in <module>
  File "main.py", line 288, in upload_result
  File "requests\api.py", line 73, in get
  File "requests\api.py", line 59, in request
  File "requests\sessions.py", line 589, in request
  File "requests\sessions.py", line 703, in send
  File "requests\adapters.py", line 688, in send
requests.exceptions.ConnectTimeout: HTTPSConnectionPool(host='api.github.com', port=443): Max retries exceeded with url: /repos/Ilikectrlmusic/auto_ip/contents/781_result/2025-02-14.txt (Caused by ConnectTimeoutError(<urllib3.connection.HTTPSConnection object at 0x0000023F6CB956D0>, 'Connection to api.github.com timed out. (connect timeout=None)'))

Error during execution: Traceback (most recent call last):
  File "urllib3\connection.py", line 198, in _new_conn
  File "urllib3\util\connection.py", line 85, in create_connection
  File "urllib3\util\connection.py", line 73, in create_connection
TimeoutError: [WinError 10060] 由于连接方在一段时间后没有正确答复或连接的主机没有反应，连接尝试失败。

The above exception was the direct cause of the following exception:

Traceback (most recent call last):
  File "urllib3\connectionpool.py", line 787, in urlopen
  File "urllib3\connectionpool.py", line 488, in _make_request
  File "urllib3\connectionpool.py", line 464, in _make_request
  File "urllib3\connectionpool.py", line 1093, in _validate_conn
  File "urllib3\connection.py", line 704, in connect
  File "urllib3\connection.py", line 207, in _new_conn
urllib3.exceptions.ConnectTimeoutError: (<urllib3.connection.HTTPSConnection object at 0x0000023F6CBBF980>, 'Connection to api.github.com timed out. (connect timeout=None)')

The above exception was the direct cause of the following exception:

Traceback (most recent call last):
  File "requests\adapters.py", line 667, in send
  File "urllib3\connectionpool.py", line 841, in urlopen
  File "urllib3\util\retry.py", line 519, in increment
urllib3.exceptions.MaxRetryError: HTTPSConnectionPool(host='api.github.com', port=443): Max retries exceeded with url: /repos/Ilikectrlmusic/auto_ip/contents/781_result/2025-02-14.txt (Caused by ConnectTimeoutError(<urllib3.connection.HTTPSConnection object at 0x0000023F6CBBF980>, 'Connection to api.github.com timed out. (connect timeout=None)'))

During handling of the above exception, another exception occurred:

Traceback (most recent call last):
  File "main.py", line 339, in <module>
  File "main.py", line 288, in upload_result
  File "requests\api.py", line 73, in get
  File "requests\api.py", line 59, in request
  File "requests\sessions.py", line 589, in request
  File "requests\sessions.py", line 703, in send
  File "requests\adapters.py", line 688, in send
requests.exceptions.ConnectTimeout: HTTPSConnectionPool(host='api.github.com', port=443): Max retries exceeded with url: /repos/Ilikectrlmusic/auto_ip/contents/781_result/2025-02-14.txt (Caused by ConnectTimeoutError(<urllib3.connection.HTTPSConnection object at 0x0000023F6CBBF980>, 'Connection to api.github.com timed out. (connect timeout=None)'))

Error during execution: Traceback (most recent call last):
  File "urllib3\connection.py", line 198, in _new_conn
  File "urllib3\util\connection.py", line 85, in create_connection
  File "urllib3\util\connection.py", line 73, in create_connection
TimeoutError: [WinError 10060] 由于连接方在一段时间后没有正确答复或连接的主机没有反应，连接尝试失败。

The above exception was the direct cause of the following exception:

Traceback (most recent call last):
  File "urllib3\connectionpool.py", line 787, in urlopen
  File "urllib3\connectionpool.py", line 488, in _make_request
  File "urllib3\connectionpool.py", line 464, in _make_request
  File "urllib3\connectionpool.py", line 1093, in _validate_conn
  File "urllib3\connection.py", line 704, in connect
  File "urllib3\connection.py", line 207, in _new_conn
urllib3.exceptions.ConnectTimeoutError: (<urllib3.connection.HTTPSConnection object at 0x0000023F6CB97E30>, 'Connection to api.github.com timed out. (connect timeout=None)')

The above exception was the direct cause of the following exception:

Traceback (most recent call last):
  File "requests\adapters.py", line 667, in send
  File "urllib3\connectionpool.py", line 841, in urlopen
  File "urllib3\util\retry.py", line 519, in increment
urllib3.exceptions.MaxRetryError: HTTPSConnectionPool(host='api.github.com', port=443): Max retries exceeded with url: /repos/Ilikectrlmusic/auto_ip/contents/781_result/2025-02-14.txt (Caused by ConnectTimeoutError(<urllib3.connection.HTTPSConnection object at 0x0000023F6CB97E30>, 'Connection to api.github.com timed out. (connect timeout=None)'))

During handling of the above exception, another exception occurred:

Traceback (most recent call last):
  File "main.py", line 339, in <module>
  File "main.py", line 307, in upload_result
  File "requests\api.py", line 130, in put
  File "requests\api.py", line 59, in request
  File "requests\sessions.py", line 589, in request
  File "requests\sessions.py", line 703, in send
  File "requests\adapters.py", line 688, in send
requests.exceptions.ConnectTimeout: HTTPSConnectionPool(host='api.github.com', port=443): Max retries exceeded with url: /repos/Ilikectrlmusic/auto_ip/contents/781_result/2025-02-14.txt (Caused by ConnectTimeoutError(<urllib3.connection.HTTPSConnection object at 0x0000023F6CB97E30>, 'Connection to api.github.com timed out. (connect timeout=None)'))

Error during execution: Traceback (most recent call last):
  File "urllib3\connection.py", line 198, in _new_conn
  File "urllib3\util\connection.py", line 85, in create_connection
  File "urllib3\util\connection.py", line 73, in create_connection
TimeoutError: [WinError 10060] 由于连接方在一段时间后没有正确答复或连接的主机没有反应，连接尝试失败。

The above exception was the direct cause of the following exception:

Traceback (most recent call last):
  File "urllib3\connectionpool.py", line 787, in urlopen
  File "urllib3\connectionpool.py", line 488, in _make_request
  File "urllib3\connectionpool.py", line 464, in _make_request
  File "urllib3\connectionpool.py", line 1093, in _validate_conn
  File "urllib3\connection.py", line 704, in connect
  File "urllib3\connection.py", line 207, in _new_conn
urllib3.exceptions.ConnectTimeoutError: (<urllib3.connection.HTTPSConnection object at 0x0000023F6CBBFD70>, 'Connection to api.github.com timed out. (connect timeout=None)')

The above exception was the direct cause of the following exception:

Traceback (most recent call last):
  File "requests\adapters.py", line 667, in send
  File "urllib3\connectionpool.py", line 841, in urlopen
  File "urllib3\util\retry.py", line 519, in increment
urllib3.exceptions.MaxRetryError: HTTPSConnectionPool(host='api.github.com', port=443): Max retries exceeded with url: /repos/Ilikectrlmusic/auto_ip/contents/781_result/2025-02-14.txt (Caused by ConnectTimeoutError(<urllib3.connection.HTTPSConnection object at 0x0000023F6CBBFD70>, 'Connection to api.github.com timed out. (connect timeout=None)'))

During handling of the above exception, another exception occurred:

Traceback (most recent call last):
  File "main.py", line 339, in <module>
  File "main.py", line 288, in upload_result
  File "requests\api.py", line 73, in get
  File "requests\api.py", line 59, in request
  File "requests\sessions.py", line 589, in request
  File "requests\sessions.py", line 703, in send
  File "requests\adapters.py", line 688, in send
requests.exceptions.ConnectTimeout: HTTPSConnectionPool(host='api.github.com', port=443): Max retries exceeded with url: /repos/Ilikectrlmusic/auto_ip/contents/781_result/2025-02-14.txt (Caused by ConnectTimeoutError(<urllib3.connection.HTTPSConnection object at 0x0000023F6CBBFD70>, 'Connection to api.github.com timed out. (connect timeout=None)'))

Error during execution: Traceback (most recent call last):
  File "urllib3\connection.py", line 198, in _new_conn
  File "urllib3\util\connection.py", line 85, in create_connection
  File "urllib3\util\connection.py", line 73, in create_connection
TimeoutError: [WinError 10060] 由于连接方在一段时间后没有正确答复或连接的主机没有反应，连接尝试失败。

The above exception was the direct cause of the following exception:

Traceback (most recent call last):
  File "urllib3\connectionpool.py", line 787, in urlopen
  File "urllib3\connectionpool.py", line 488, in _make_request
  File "urllib3\connectionpool.py", line 464, in _make_request
  File "urllib3\connectionpool.py", line 1093, in _validate_conn
  File "urllib3\connection.py", line 704, in connect
  File "urllib3\connection.py", line 207, in _new_conn
urllib3.exceptions.ConnectTimeoutError: (<urllib3.connection.HTTPSConnection object at 0x0000023F6CBA3E00>, 'Connection to api.github.com timed out. (connect timeout=None)')

The above exception was the direct cause of the following exception:

Traceback (most recent call last):
  File "requests\adapters.py", line 667, in send
  File "urllib3\connectionpool.py", line 841, in urlopen
  File "urllib3\util\retry.py", line 519, in increment
urllib3.exceptions.MaxRetryError: HTTPSConnectionPool(host='api.github.com', port=443): Max retries exceeded with url: /repos/Ilikectrlmusic/auto_ip/contents/781_result/2025-02-14.txt (Caused by ConnectTimeoutError(<urllib3.connection.HTTPSConnection object at 0x0000023F6CBA3E00>, 'Connection to api.github.com timed out. (connect timeout=None)'))

During handling of the above exception, another exception occurred:

Traceback (most recent call last):
  File "main.py", line 339, in <module>
  File "main.py", line 307, in upload_result
  File "requests\api.py", line 130, in put
  File "requests\api.py", line 59, in request
  File "requests\sessions.py", line 589, in request
  File "requests\sessions.py", line 703, in send
  File "requests\adapters.py", line 688, in send
requests.exceptions.ConnectTimeout: HTTPSConnectionPool(host='api.github.com', port=443): Max retries exceeded with url: /repos/Ilikectrlmusic/auto_ip/contents/781_result/2025-02-14.txt (Caused by ConnectTimeoutError(<urllib3.connection.HTTPSConnection object at 0x0000023F6CBA3E00>, 'Connection to api.github.com timed out. (connect timeout=None)'))

Error during execution: Traceback (most recent call last):
  File "urllib3\connection.py", line 198, in _new_conn
  File "urllib3\util\connection.py", line 85, in create_connection
  File "urllib3\util\connection.py", line 73, in create_connection
TimeoutError: [WinError 10060] 由于连接方在一段时间后没有正确答复或连接的主机没有反应，连接尝试失败。

The above exception was the direct cause of the following exception:

Traceback (most recent call last):
  File "urllib3\connectionpool.py", line 787, in urlopen
  File "urllib3\connectionpool.py", line 488, in _make_request
  File "urllib3\connectionpool.py", line 464, in _make_request
  File "urllib3\connectionpool.py", line 1093, in _validate_conn
  File "urllib3\connection.py", line 704, in connect
  File "urllib3\connection.py", line 207, in _new_conn
urllib3.exceptions.ConnectTimeoutError: (<urllib3.connection.HTTPSConnection object at 0x0000023F6CBA3170>, 'Connection to api.github.com timed out. (connect timeout=None)')

The above exception was the direct cause of the following exception:

Traceback (most recent call last):
  File "requests\adapters.py", line 667, in send
  File "urllib3\connectionpool.py", line 841, in urlopen
  File "urllib3\util\retry.py", line 519, in increment
urllib3.exceptions.MaxRetryError: HTTPSConnectionPool(host='api.github.com', port=443): Max retries exceeded with url: /repos/Ilikectrlmusic/auto_ip/contents/781_result/2025-02-14.txt (Caused by ConnectTimeoutError(<urllib3.connection.HTTPSConnection object at 0x0000023F6CBA3170>, 'Connection to api.github.com timed out. (connect timeout=None)'))

During handling of the above exception, another exception occurred:

Traceback (most recent call last):
  File "main.py", line 339, in <module>
  File "main.py", line 288, in upload_result
  File "requests\api.py", line 73, in get
  File "requests\api.py", line 59, in request
  File "requests\sessions.py", line 589, in request
  File "requests\sessions.py", line 703, in send
  File "requests\adapters.py", line 688, in send
requests.exceptions.ConnectTimeout: HTTPSConnectionPool(host='api.github.com', port=443): Max retries exceeded with url: /repos/Ilikectrlmusic/auto_ip/contents/781_result/2025-02-14.txt (Caused by ConnectTimeoutError(<urllib3.connection.HTTPSConnection object at 0x0000023F6CBA3170>, 'Connection to api.github.com timed out. (connect timeout=None)'))

Error during execution: Traceback (most recent call last):
  File "urllib3\connection.py", line 198, in _new_conn
  File "urllib3\util\connection.py", line 85, in create_connection
  File "urllib3\util\connection.py", line 73, in create_connection
TimeoutError: [WinError 10060] 由于连接方在一段时间后没有正确答复或连接的主机没有反应，连接尝试失败。

The above exception was the direct cause of the following exception:

Traceback (most recent call last):
  File "urllib3\connectionpool.py", line 787, in urlopen
  File "urllib3\connectionpool.py", line 488, in _make_request
  File "urllib3\connectionpool.py", line 464, in _make_request
  File "urllib3\connectionpool.py", line 1093, in _validate_conn
  File "urllib3\connection.py", line 704, in connect
  File "urllib3\connection.py", line 207, in _new_conn
urllib3.exceptions.ConnectTimeoutError: (<urllib3.connection.HTTPSConnection object at 0x0000023F6CBBE030>, 'Connection to api.github.com timed out. (connect timeout=None)')

The above exception was the direct cause of the following exception:

Traceback (most recent call last):
  File "requests\adapters.py", line 667, in send
  File "urllib3\connectionpool.py", line 841, in urlopen
  File "urllib3\util\retry.py", line 519, in increment
urllib3.exceptions.MaxRetryError: HTTPSConnectionPool(host='api.github.com', port=443): Max retries exceeded with url: /repos/Ilikectrlmusic/auto_ip/contents/781_result/2025-02-14.txt (Caused by ConnectTimeoutError(<urllib3.connection.HTTPSConnection object at 0x0000023F6CBBE030>, 'Connection to api.github.com timed out. (connect timeout=None)'))

During handling of the above exception, another exception occurred:

Traceback (most recent call last):
  File "main.py", line 339, in <module>
  File "main.py", line 307, in upload_result
  File "requests\api.py", line 130, in put
  File "requests\api.py", line 59, in request
  File "requests\sessions.py", line 589, in request
  File "requests\sessions.py", line 703, in send
  File "requests\adapters.py", line 688, in send
requests.exceptions.ConnectTimeout: HTTPSConnectionPool(host='api.github.com', port=443): Max retries exceeded with url: /repos/Ilikectrlmusic/auto_ip/contents/781_result/2025-02-14.txt (Caused by ConnectTimeoutError(<urllib3.connection.HTTPSConnection object at 0x0000023F6CBBE030>, 'Connection to api.github.com timed out. (connect timeout=None)'))

Error during execution: Traceback (most recent call last):
  File "urllib3\connection.py", line 198, in _new_conn
  File "urllib3\util\connection.py", line 85, in create_connection
  File "urllib3\util\connection.py", line 73, in create_connection
TimeoutError: [WinError 10060] 由于连接方在一段时间后没有正确答复或连接的主机没有反应，连接尝试失败。

The above exception was the direct cause of the following exception:

Traceback (most recent call last):
  File "urllib3\connectionpool.py", line 787, in urlopen
  File "urllib3\connectionpool.py", line 488, in _make_request
  File "urllib3\connectionpool.py", line 464, in _make_request
  File "urllib3\connectionpool.py", line 1093, in _validate_conn
  File "urllib3\connection.py", line 704, in connect
  File "urllib3\connection.py", line 207, in _new_conn
urllib3.exceptions.ConnectTimeoutError: (<urllib3.connection.HTTPSConnection object at 0x0000023F6CBBC920>, 'Connection to api.github.com timed out. (connect timeout=None)')

The above exception was the direct cause of the following exception:

Traceback (most recent call last):
  File "requests\adapters.py", line 667, in send
  File "urllib3\connectionpool.py", line 841, in urlopen
  File "urllib3\util\retry.py", line 519, in increment
urllib3.exceptions.MaxRetryError: HTTPSConnectionPool(host='api.github.com', port=443): Max retries exceeded with url: /repos/Ilikectrlmusic/auto_ip/contents/781_result/2025-02-14.txt (Caused by ConnectTimeoutError(<urllib3.connection.HTTPSConnection object at 0x0000023F6CBBC920>, 'Connection to api.github.com timed out. (connect timeout=None)'))

During handling of the above exception, another exception occurred:

Traceback (most recent call last):
  File "main.py", line 339, in <module>
  File "main.py", line 307, in upload_result
  File "requests\api.py", line 130, in put
  File "requests\api.py", line 59, in request
  File "requests\sessions.py", line 589, in request
  File "requests\sessions.py", line 703, in send
  File "requests\adapters.py", line 688, in send
requests.exceptions.ConnectTimeout: HTTPSConnectionPool(host='api.github.com', port=443): Max retries exceeded with url: /repos/Ilikectrlmusic/auto_ip/contents/781_result/2025-02-14.txt (Caused by ConnectTimeoutError(<urllib3.connection.HTTPSConnection object at 0x0000023F6CBBC920>, 'Connection to api.github.com timed out. (connect timeout=None)'))

Error during execution: Traceback (most recent call last):
  File "urllib3\connection.py", line 198, in _new_conn
  File "urllib3\util\connection.py", line 85, in create_connection
  File "urllib3\util\connection.py", line 73, in create_connection
TimeoutError: [WinError 10060] 由于连接方在一段时间后没有正确答复或连接的主机没有反应，连接尝试失败。

The above exception was the direct cause of the following exception:

Traceback (most recent call last):
  File "urllib3\connectionpool.py", line 787, in urlopen
  File "urllib3\connectionpool.py", line 488, in _make_request
  File "urllib3\connectionpool.py", line 464, in _make_request
  File "urllib3\connectionpool.py", line 1093, in _validate_conn
  File "urllib3\connection.py", line 704, in connect
  File "urllib3\connection.py", line 207, in _new_conn
urllib3.exceptions.ConnectTimeoutError: (<urllib3.connection.HTTPSConnection object at 0x0000023F6CBC1310>, 'Connection to api.github.com timed out. (connect timeout=None)')

The above exception was the direct cause of the following exception:

Traceback (most recent call last):
  File "requests\adapters.py", line 667, in send
  File "urllib3\connectionpool.py", line 841, in urlopen
  File "urllib3\util\retry.py", line 519, in increment
urllib3.exceptions.MaxRetryError: HTTPSConnectionPool(host='api.github.com', port=443): Max retries exceeded with url: /repos/Ilikectrlmusic/auto_ip/contents/781_result/2025-02-14.txt (Caused by ConnectTimeoutError(<urllib3.connection.HTTPSConnection object at 0x0000023F6CBC1310>, 'Connection to api.github.com timed out. (connect timeout=None)'))

During handling of the above exception, another exception occurred:

Traceback (most recent call last):
  File "main.py", line 339, in <module>
  File "main.py", line 307, in upload_result
  File "requests\api.py", line 130, in put
  File "requests\api.py", line 59, in request
  File "requests\sessions.py", line 589, in request
  File "requests\sessions.py", line 703, in send
  File "requests\adapters.py", line 688, in send
requests.exceptions.ConnectTimeout: HTTPSConnectionPool(host='api.github.com', port=443): Max retries exceeded with url: /repos/Ilikectrlmusic/auto_ip/contents/781_result/2025-02-14.txt (Caused by ConnectTimeoutError(<urllib3.connection.HTTPSConnection object at 0x0000023F6CBC1310>, 'Connection to api.github.com timed out. (connect timeout=None)'))

Error during execution: Traceback (most recent call last):
  File "urllib3\connection.py", line 198, in _new_conn
  File "urllib3\util\connection.py", line 85, in create_connection
  File "urllib3\util\connection.py", line 73, in create_connection
TimeoutError: [WinError 10060] 由于连接方在一段时间后没有正确答复或连接的主机没有反应，连接尝试失败。

The above exception was the direct cause of the following exception:

Traceback (most recent call last):
  File "urllib3\connectionpool.py", line 787, in urlopen
  File "urllib3\connectionpool.py", line 488, in _make_request
  File "urllib3\connectionpool.py", line 464, in _make_request
  File "urllib3\connectionpool.py", line 1093, in _validate_conn
  File "urllib3\connection.py", line 704, in connect
  File "urllib3\connection.py", line 207, in _new_conn
urllib3.exceptions.ConnectTimeoutError: (<urllib3.connection.HTTPSConnection object at 0x0000023F6CBC05C0>, 'Connection to api.github.com timed out. (connect timeout=None)')

The above exception was the direct cause of the following exception:

Traceback (most recent call last):
  File "requests\adapters.py", line 667, in send
  File "urllib3\connectionpool.py", line 841, in urlopen
  File "urllib3\util\retry.py", line 519, in increment
urllib3.exceptions.MaxRetryError: HTTPSConnectionPool(host='api.github.com', port=443): Max retries exceeded with url: /repos/Ilikectrlmusic/auto_ip/contents/781_result/2025-02-14.txt (Caused by ConnectTimeoutError(<urllib3.connection.HTTPSConnection object at 0x0000023F6CBC05C0>, 'Connection to api.github.com timed out. (connect timeout=None)'))

During handling of the above exception, another exception occurred:

Traceback (most recent call last):
  File "main.py", line 339, in <module>
  File "main.py", line 307, in upload_result
  File "requests\api.py", line 130, in put
  File "requests\api.py", line 59, in request
  File "requests\sessions.py", line 589, in request
  File "requests\sessions.py", line 703, in send
  File "requests\adapters.py", line 688, in send
requests.exceptions.ConnectTimeout: HTTPSConnectionPool(host='api.github.com', port=443): Max retries exceeded with url: /repos/Ilikectrlmusic/auto_ip/contents/781_result/2025-02-14.txt (Caused by ConnectTimeoutError(<urllib3.connection.HTTPSConnection object at 0x0000023F6CBC05C0>, 'Connection to api.github.com timed out. (connect timeout=None)'))

Error during execution: Traceback (most recent call last):
  File "urllib3\connection.py", line 198, in _new_conn
  File "urllib3\util\connection.py", line 85, in create_connection
  File "urllib3\util\connection.py", line 73, in create_connection
TimeoutError: [WinError 10060] 由于连接方在一段时间后没有正确答复或连接的主机没有反应，连接尝试失败。

The above exception was the direct cause of the following exception:

Traceback (most recent call last):
  File "urllib3\connectionpool.py", line 787, in urlopen
  File "urllib3\connectionpool.py", line 488, in _make_request
  File "urllib3\connectionpool.py", line 464, in _make_request
  File "urllib3\connectionpool.py", line 1093, in _validate_conn
  File "urllib3\connection.py", line 704, in connect
  File "urllib3\connection.py", line 207, in _new_conn
urllib3.exceptions.ConnectTimeoutError: (<urllib3.connection.HTTPSConnection object at 0x0000023F6CBA3D40>, 'Connection to api.github.com timed out. (connect timeout=None)')

The above exception was the direct cause of the following exception:

Traceback (most recent call last):
  File "requests\adapters.py", line 667, in send
  File "urllib3\connectionpool.py", line 841, in urlopen
  File "urllib3\util\retry.py", line 519, in increment
urllib3.exceptions.MaxRetryError: HTTPSConnectionPool(host='api.github.com', port=443): Max retries exceeded with url: /repos/Ilikectrlmusic/auto_ip/contents/781_result/2025-02-14.txt (Caused by ConnectTimeoutError(<urllib3.connection.HTTPSConnection object at 0x0000023F6CBA3D40>, 'Connection to api.github.com timed out. (connect timeout=None)'))

During handling of the above exception, another exception occurred:

Traceback (most recent call last):
  File "main.py", line 339, in <module>
  File "main.py", line 288, in upload_result
  File "requests\api.py", line 73, in get
  File "requests\api.py", line 59, in request
  File "requests\sessions.py", line 589, in request
  File "requests\sessions.py", line 703, in send
  File "requests\adapters.py", line 688, in send
requests.exceptions.ConnectTimeout: HTTPSConnectionPool(host='api.github.com', port=443): Max retries exceeded with url: /repos/Ilikectrlmusic/auto_ip/contents/781_result/2025-02-14.txt (Caused by ConnectTimeoutError(<urllib3.connection.HTTPSConnection object at 0x0000023F6CBA3D40>, 'Connection to api.github.com timed out. (connect timeout=None)'))

Error during execution: Traceback (most recent call last):
  File "urllib3\connection.py", line 198, in _new_conn
  File "urllib3\util\connection.py", line 85, in create_connection
  File "urllib3\util\connection.py", line 73, in create_connection
TimeoutError: [WinError 10060] 由于连接方在一段时间后没有正确答复或连接的主机没有反应，连接尝试失败。

The above exception was the direct cause of the following exception:

Traceback (most recent call last):
  File "urllib3\connectionpool.py", line 787, in urlopen
  File "urllib3\connectionpool.py", line 488, in _make_request
  File "urllib3\connectionpool.py", line 464, in _make_request
  File "urllib3\connectionpool.py", line 1093, in _validate_conn
  File "urllib3\connection.py", line 704, in connect
  File "urllib3\connection.py", line 207, in _new_conn
urllib3.exceptions.ConnectTimeoutError: (<urllib3.connection.HTTPSConnection object at 0x0000023F6CBBF110>, 'Connection to api.github.com timed out. (connect timeout=None)')

The above exception was the direct cause of the following exception:

Traceback (most recent call last):
  File "requests\adapters.py", line 667, in send
  File "urllib3\connectionpool.py", line 841, in urlopen
  File "urllib3\util\retry.py", line 519, in increment
urllib3.exceptions.MaxRetryError: HTTPSConnectionPool(host='api.github.com', port=443): Max retries exceeded with url: /repos/Ilikectrlmusic/auto_ip/contents/781_result/2025-02-14.txt (Caused by ConnectTimeoutError(<urllib3.connection.HTTPSConnection object at 0x0000023F6CBBF110>, 'Connection to api.github.com timed out. (connect timeout=None)'))

During handling of the above exception, another exception occurred:

Traceback (most recent call last):
  File "main.py", line 339, in <module>
  File "main.py", line 288, in upload_result
  File "requests\api.py", line 73, in get
  File "requests\api.py", line 59, in request
  File "requests\sessions.py", line 589, in request
  File "requests\sessions.py", line 703, in send
  File "requests\adapters.py", line 688, in send
requests.exceptions.ConnectTimeout: HTTPSConnectionPool(host='api.github.com', port=443): Max retries exceeded with url: /repos/Ilikectrlmusic/auto_ip/contents/781_result/2025-02-14.txt (Caused by ConnectTimeoutError(<urllib3.connection.HTTPSConnection object at 0x0000023F6CBBF110>, 'Connection to api.github.com timed out. (connect timeout=None)'))

Error during execution: Traceback (most recent call last):
  File "urllib3\connection.py", line 198, in _new_conn
  File "urllib3\util\connection.py", line 85, in create_connection
  File "urllib3\util\connection.py", line 73, in create_connection
TimeoutError: [WinError 10060] 由于连接方在一段时间后没有正确答复或连接的主机没有反应，连接尝试失败。

The above exception was the direct cause of the following exception:

Traceback (most recent call last):
  File "urllib3\connectionpool.py", line 787, in urlopen
  File "urllib3\connectionpool.py", line 488, in _make_request
  File "urllib3\connectionpool.py", line 464, in _make_request
  File "urllib3\connectionpool.py", line 1093, in _validate_conn
  File "urllib3\connection.py", line 704, in connect
  File "urllib3\connection.py", line 207, in _new_conn
urllib3.exceptions.ConnectTimeoutError: (<urllib3.connection.HTTPSConnection object at 0x0000023F6CBA2540>, 'Connection to api.github.com timed out. (connect timeout=None)')

The above exception was the direct cause of the following exception:

Traceback (most recent call last):
  File "requests\adapters.py", line 667, in send
  File "urllib3\connectionpool.py", line 841, in urlopen
  File "urllib3\util\retry.py", line 519, in increment
urllib3.exceptions.MaxRetryError: HTTPSConnectionPool(host='api.github.com', port=443): Max retries exceeded with url: /repos/Ilikectrlmusic/auto_ip/contents/781_result/2025-02-14.txt (Caused by ConnectTimeoutError(<urllib3.connection.HTTPSConnection object at 0x0000023F6CBA2540>, 'Connection to api.github.com timed out. (connect timeout=None)'))

During handling of the above exception, another exception occurred:

Traceback (most recent call last):
  File "main.py", line 339, in <module>
  File "main.py", line 307, in upload_result
  File "requests\api.py", line 130, in put
  File "requests\api.py", line 59, in request
  File "requests\sessions.py", line 589, in request
  File "requests\sessions.py", line 703, in send
  File "requests\adapters.py", line 688, in send
requests.exceptions.ConnectTimeout: HTTPSConnectionPool(host='api.github.com', port=443): Max retries exceeded with url: /repos/Ilikectrlmusic/auto_ip/contents/781_result/2025-02-14.txt (Caused by ConnectTimeoutError(<urllib3.connection.HTTPSConnection object at 0x0000023F6CBA2540>, 'Connection to api.github.com timed out. (connect timeout=None)'))

Error during execution: Traceback (most recent call last):
  File "urllib3\connection.py", line 198, in _new_conn
  File "urllib3\util\connection.py", line 85, in create_connection
  File "urllib3\util\connection.py", line 73, in create_connection
TimeoutError: [WinError 10060] 由于连接方在一段时间后没有正确答复或连接的主机没有反应，连接尝试失败。

The above exception was the direct cause of the following exception:

Traceback (most recent call last):
  File "urllib3\connectionpool.py", line 787, in urlopen
  File "urllib3\connectionpool.py", line 488, in _make_request
  File "urllib3\connectionpool.py", line 464, in _make_request
  File "urllib3\connectionpool.py", line 1093, in _validate_conn
  File "urllib3\connection.py", line 704, in connect
  File "urllib3\connection.py", line 207, in _new_conn
urllib3.exceptions.ConnectTimeoutError: (<urllib3.connection.HTTPSConnection object at 0x0000023F6CBA0CE0>, 'Connection to api.github.com timed out. (connect timeout=None)')

The above exception was the direct cause of the following exception:

Traceback (most recent call last):
  File "requests\adapters.py", line 667, in send
  File "urllib3\connectionpool.py", line 841, in urlopen
  File "urllib3\util\retry.py", line 519, in increment
urllib3.exceptions.MaxRetryError: HTTPSConnectionPool(host='api.github.com', port=443): Max retries exceeded with url: /repos/Ilikectrlmusic/auto_ip/contents/781_result/2025-02-14.txt (Caused by ConnectTimeoutError(<urllib3.connection.HTTPSConnection object at 0x0000023F6CBA0CE0>, 'Connection to api.github.com timed out. (connect timeout=None)'))

During handling of the above exception, another exception occurred:

Traceback (most recent call last):
  File "main.py", line 339, in <module>
  File "main.py", line 288, in upload_result
  File "requests\api.py", line 73, in get
  File "requests\api.py", line 59, in request
  File "requests\sessions.py", line 589, in request
  File "requests\sessions.py", line 703, in send
  File "requests\adapters.py", line 688, in send
requests.exceptions.ConnectTimeout: HTTPSConnectionPool(host='api.github.com', port=443): Max retries exceeded with url: /repos/Ilikectrlmusic/auto_ip/contents/781_result/2025-02-14.txt (Caused by ConnectTimeoutError(<urllib3.connection.HTTPSConnection object at 0x0000023F6CBA0CE0>, 'Connection to api.github.com timed out. (connect timeout=None)'))

Error during execution: Traceback (most recent call last):
  File "urllib3\connection.py", line 198, in _new_conn
  File "urllib3\util\connection.py", line 85, in create_connection
  File "urllib3\util\connection.py", line 73, in create_connection
TimeoutError: [WinError 10060] 由于连接方在一段时间后没有正确答复或连接的主机没有反应，连接尝试失败。

The above exception was the direct cause of the following exception:

Traceback (most recent call last):
  File "urllib3\connectionpool.py", line 787, in urlopen
  File "urllib3\connectionpool.py", line 488, in _make_request
  File "urllib3\connectionpool.py", line 464, in _make_request
  File "urllib3\connectionpool.py", line 1093, in _validate_conn
  File "urllib3\connection.py", line 704, in connect
  File "urllib3\connection.py", line 207, in _new_conn
urllib3.exceptions.ConnectTimeoutError: (<urllib3.connection.HTTPSConnection object at 0x0000023F6CBBFEF0>, 'Connection to api.github.com timed out. (connect timeout=None)')

The above exception was the direct cause of the following exception:

Traceback (most recent call last):
  File "requests\adapters.py", line 667, in send
  File "urllib3\connectionpool.py", line 841, in urlopen
  File "urllib3\util\retry.py", line 519, in increment
urllib3.exceptions.MaxRetryError: HTTPSConnectionPool(host='api.github.com', port=443): Max retries exceeded with url: /repos/Ilikectrlmusic/auto_ip/contents/781_result/2025-02-14.txt (Caused by ConnectTimeoutError(<urllib3.connection.HTTPSConnection object at 0x0000023F6CBBFEF0>, 'Connection to api.github.com timed out. (connect timeout=None)'))

During handling of the above exception, another exception occurred:

Traceback (most recent call last):
  File "main.py", line 339, in <module>
  File "main.py", line 307, in upload_result
  File "requests\api.py", line 130, in put
  File "requests\api.py", line 59, in request
  File "requests\sessions.py", line 589, in request
  File "requests\sessions.py", line 703, in send
  File "requests\adapters.py", line 688, in send
requests.exceptions.ConnectTimeout: HTTPSConnectionPool(host='api.github.com', port=443): Max retries exceeded with url: /repos/Ilikectrlmusic/auto_ip/contents/781_result/2025-02-14.txt (Caused by ConnectTimeoutError(<urllib3.connection.HTTPSConnection object at 0x0000023F6CBBFEF0>, 'Connection to api.github.com timed out. (connect timeout=None)'))

Error during execution: Traceback (most recent call last):
  File "urllib3\connection.py", line 198, in _new_conn
  File "urllib3\util\connection.py", line 85, in create_connection
  File "urllib3\util\connection.py", line 73, in create_connection
TimeoutError: [WinError 10060] 由于连接方在一段时间后没有正确答复或连接的主机没有反应，连接尝试失败。

The above exception was the direct cause of the following exception:

Traceback (most recent call last):
  File "urllib3\connectionpool.py", line 787, in urlopen
  File "urllib3\connectionpool.py", line 488, in _make_request
  File "urllib3\connectionpool.py", line 464, in _make_request
  File "urllib3\connectionpool.py", line 1093, in _validate_conn
  File "urllib3\connection.py", line 704, in connect
  File "urllib3\connection.py", line 207, in _new_conn
urllib3.exceptions.ConnectTimeoutError: (<urllib3.connection.HTTPSConnection object at 0x0000023F6CBBFDA0>, 'Connection to api.github.com timed out. (connect timeout=None)')

The above exception was the direct cause of the following exception:

Traceback (most recent call last):
  File "requests\adapters.py", line 667, in send
  File "urllib3\connectionpool.py", line 841, in urlopen
  File "urllib3\util\retry.py", line 519, in increment
urllib3.exceptions.MaxRetryError: HTTPSConnectionPool(host='api.github.com', port=443): Max retries exceeded with url: /repos/Ilikectrlmusic/auto_ip/contents/781_result/2025-02-14.txt (Caused by ConnectTimeoutError(<urllib3.connection.HTTPSConnection object at 0x0000023F6CBBFDA0>, 'Connection to api.github.com timed out. (connect timeout=None)'))

During handling of the above exception, another exception occurred:

Traceback (most recent call last):
  File "main.py", line 339, in <module>
  File "main.py", line 288, in upload_result
  File "requests\api.py", line 73, in get
  File "requests\api.py", line 59, in request
  File "requests\sessions.py", line 589, in request
  File "requests\sessions.py", line 703, in send
  File "requests\adapters.py", line 688, in send
requests.exceptions.ConnectTimeout: HTTPSConnectionPool(host='api.github.com', port=443): Max retries exceeded with url: /repos/Ilikectrlmusic/auto_ip/contents/781_result/2025-02-14.txt (Caused by ConnectTimeoutError(<urllib3.connection.HTTPSConnection object at 0x0000023F6CBBFDA0>, 'Connection to api.github.com timed out. (connect timeout=None)'))

Error during execution: Traceback (most recent call last):
  File "urllib3\connection.py", line 198, in _new_conn
  File "urllib3\util\connection.py", line 85, in create_connection
  File "urllib3\util\connection.py", line 73, in create_connection
TimeoutError: [WinError 10060] 由于连接方在一段时间后没有正确答复或连接的主机没有反应，连接尝试失败。

The above exception was the direct cause of the following exception:

Traceback (most recent call last):
  File "urllib3\connectionpool.py", line 787, in urlopen
  File "urllib3\connectionpool.py", line 488, in _make_request
  File "urllib3\connectionpool.py", line 464, in _make_request
  File "urllib3\connectionpool.py", line 1093, in _validate_conn
  File "urllib3\connection.py", line 704, in connect
  File "urllib3\connection.py", line 207, in _new_conn
urllib3.exceptions.ConnectTimeoutError: (<urllib3.connection.HTTPSConnection object at 0x0000023F6CB60C20>, 'Connection to api.github.com timed out. (connect timeout=None)')

The above exception was the direct cause of the following exception:

Traceback (most recent call last):
  File "requests\adapters.py", line 667, in send
  File "urllib3\connectionpool.py", line 841, in urlopen
  File "urllib3\util\retry.py", line 519, in increment
urllib3.exceptions.MaxRetryError: HTTPSConnectionPool(host='api.github.com', port=443): Max retries exceeded with url: /repos/Ilikectrlmusic/auto_ip/contents/781_result/2025-02-14.txt (Caused by ConnectTimeoutError(<urllib3.connection.HTTPSConnection object at 0x0000023F6CB60C20>, 'Connection to api.github.com timed out. (connect timeout=None)'))

During handling of the above exception, another exception occurred:

Traceback (most recent call last):
  File "main.py", line 339, in <module>
  File "main.py", line 288, in upload_result
  File "requests\api.py", line 73, in get
  File "requests\api.py", line 59, in request
  File "requests\sessions.py", line 589, in request
  File "requests\sessions.py", line 703, in send
  File "requests\adapters.py", line 688, in send
requests.exceptions.ConnectTimeout: HTTPSConnectionPool(host='api.github.com', port=443): Max retries exceeded with url: /repos/Ilikectrlmusic/auto_ip/contents/781_result/2025-02-14.txt (Caused by ConnectTimeoutError(<urllib3.connection.HTTPSConnection object at 0x0000023F6CB60C20>, 'Connection to api.github.com timed out. (connect timeout=None)'))

Error during execution: Traceback (most recent call last):
  File "urllib3\connection.py", line 198, in _new_conn
  File "urllib3\util\connection.py", line 85, in create_connection
  File "urllib3\util\connection.py", line 73, in create_connection
TimeoutError: [WinError 10060] 由于连接方在一段时间后没有正确答复或连接的主机没有反应，连接尝试失败。

The above exception was the direct cause of the following exception:

Traceback (most recent call last):
  File "urllib3\connectionpool.py", line 787, in urlopen
  File "urllib3\connectionpool.py", line 488, in _make_request
  File "urllib3\connectionpool.py", line 464, in _make_request
  File "urllib3\connectionpool.py", line 1093, in _validate_conn
  File "urllib3\connection.py", line 704, in connect
  File "urllib3\connection.py", line 207, in _new_conn
urllib3.exceptions.ConnectTimeoutError: (<urllib3.connection.HTTPSConnection object at 0x0000023F6CBBF140>, 'Connection to api.github.com timed out. (connect timeout=None)')

The above exception was the direct cause of the following exception:

Traceback (most recent call last):
  File "requests\adapters.py", line 667, in send
  File "urllib3\connectionpool.py", line 841, in urlopen
  File "urllib3\util\retry.py", line 519, in increment
urllib3.exceptions.MaxRetryError: HTTPSConnectionPool(host='api.github.com', port=443): Max retries exceeded with url: /repos/Ilikectrlmusic/auto_ip/contents/781_result/2025-02-14.txt (Caused by ConnectTimeoutError(<urllib3.connection.HTTPSConnection object at 0x0000023F6CBBF140>, 'Connection to api.github.com timed out. (connect timeout=None)'))

During handling of the above exception, another exception occurred:

Traceback (most recent call last):
  File "main.py", line 339, in <module>
  File "main.py", line 288, in upload_result
  File "requests\api.py", line 73, in get
  File "requests\api.py", line 59, in request
  File "requests\sessions.py", line 589, in request
  File "requests\sessions.py", line 703, in send
  File "requests\adapters.py", line 688, in send
requests.exceptions.ConnectTimeout: HTTPSConnectionPool(host='api.github.com', port=443): Max retries exceeded with url: /repos/Ilikectrlmusic/auto_ip/contents/781_result/2025-02-14.txt (Caused by ConnectTimeoutError(<urllib3.connection.HTTPSConnection object at 0x0000023F6CBBF140>, 'Connection to api.github.com timed out. (connect timeout=None)'))

Error during execution: Traceback (most recent call last):
  File "urllib3\connection.py", line 198, in _new_conn
  File "urllib3\util\connection.py", line 85, in create_connection
  File "urllib3\util\connection.py", line 73, in create_connection
TimeoutError: [WinError 10060] 由于连接方在一段时间后没有正确答复或连接的主机没有反应，连接尝试失败。

The above exception was the direct cause of the following exception:

Traceback (most recent call last):
  File "urllib3\connectionpool.py", line 787, in urlopen
  File "urllib3\connectionpool.py", line 488, in _make_request
  File "urllib3\connectionpool.py", line 464, in _make_request
  File "urllib3\connectionpool.py", line 1093, in _validate_conn
  File "urllib3\connection.py", line 704, in connect
  File "urllib3\connection.py", line 207, in _new_conn
urllib3.exceptions.ConnectTimeoutError: (<urllib3.connection.HTTPSConnection object at 0x0000023F6CB63050>, 'Connection to api.github.com timed out. (connect timeout=None)')

The above exception was the direct cause of the following exception:

Traceback (most recent call last):
  File "requests\adapters.py", line 667, in send
  File "urllib3\connectionpool.py", line 841, in urlopen
  File "urllib3\util\retry.py", line 519, in increment
urllib3.exceptions.MaxRetryError: HTTPSConnectionPool(host='api.github.com', port=443): Max retries exceeded with url: /repos/Ilikectrlmusic/auto_ip/contents/781_result/2025-02-14.txt (Caused by ConnectTimeoutError(<urllib3.connection.HTTPSConnection object at 0x0000023F6CB63050>, 'Connection to api.github.com timed out. (connect timeout=None)'))

During handling of the above exception, another exception occurred:

Traceback (most recent call last):
  File "main.py", line 339, in <module>
  File "main.py", line 307, in upload_result
  File "requests\api.py", line 130, in put
  File "requests\api.py", line 59, in request
  File "requests\sessions.py", line 589, in request
  File "requests\sessions.py", line 703, in send
  File "requests\adapters.py", line 688, in send
requests.exceptions.ConnectTimeout: HTTPSConnectionPool(host='api.github.com', port=443): Max retries exceeded with url: /repos/Ilikectrlmusic/auto_ip/contents/781_result/2025-02-14.txt (Caused by ConnectTimeoutError(<urllib3.connection.HTTPSConnection object at 0x0000023F6CB63050>, 'Connection to api.github.com timed out. (connect timeout=None)'))

Error during execution: Traceback (most recent call last):
  File "urllib3\connection.py", line 198, in _new_conn
  File "urllib3\util\connection.py", line 85, in create_connection
  File "urllib3\util\connection.py", line 73, in create_connection
TimeoutError: [WinError 10060] 由于连接方在一段时间后没有正确答复或连接的主机没有反应，连接尝试失败。

The above exception was the direct cause of the following exception:

Traceback (most recent call last):
  File "urllib3\connectionpool.py", line 787, in urlopen
  File "urllib3\connectionpool.py", line 488, in _make_request
  File "urllib3\connectionpool.py", line 464, in _make_request
  File "urllib3\connectionpool.py", line 1093, in _validate_conn
  File "urllib3\connection.py", line 704, in connect
  File "urllib3\connection.py", line 207, in _new_conn
urllib3.exceptions.ConnectTimeoutError: (<urllib3.connection.HTTPSConnection object at 0x0000023F6CBA1130>, 'Connection to api.github.com timed out. (connect timeout=None)')

The above exception was the direct cause of the following exception:

Traceback (most recent call last):
  File "requests\adapters.py", line 667, in send
  File "urllib3\connectionpool.py", line 841, in urlopen
  File "urllib3\util\retry.py", line 519, in increment
urllib3.exceptions.MaxRetryError: HTTPSConnectionPool(host='api.github.com', port=443): Max retries exceeded with url: /repos/Ilikectrlmusic/auto_ip/contents/781_result/2025-02-14.txt (Caused by ConnectTimeoutError(<urllib3.connection.HTTPSConnection object at 0x0000023F6CBA1130>, 'Connection to api.github.com timed out. (connect timeout=None)'))

During handling of the above exception, another exception occurred:

Traceback (most recent call last):
  File "main.py", line 339, in <module>
  File "main.py", line 288, in upload_result
  File "requests\api.py", line 73, in get
  File "requests\api.py", line 59, in request
  File "requests\sessions.py", line 589, in request
  File "requests\sessions.py", line 703, in send
  File "requests\adapters.py", line 688, in send
requests.exceptions.ConnectTimeout: HTTPSConnectionPool(host='api.github.com', port=443): Max retries exceeded with url: /repos/Ilikectrlmusic/auto_ip/contents/781_result/2025-02-14.txt (Caused by ConnectTimeoutError(<urllib3.connection.HTTPSConnection object at 0x0000023F6CBA1130>, 'Connection to api.github.com timed out. (connect timeout=None)'))

Error during execution: Traceback (most recent call last):
  File "urllib3\connection.py", line 198, in _new_conn
  File "urllib3\util\connection.py", line 85, in create_connection
  File "urllib3\util\connection.py", line 73, in create_connection
TimeoutError: [WinError 10060] 由于连接方在一段时间后没有正确答复或连接的主机没有反应，连接尝试失败。

The above exception was the direct cause of the following exception:

Traceback (most recent call last):
  File "urllib3\connectionpool.py", line 787, in urlopen
  File "urllib3\connectionpool.py", line 488, in _make_request
  File "urllib3\connectionpool.py", line 464, in _make_request
  File "urllib3\connectionpool.py", line 1093, in _validate_conn
  File "urllib3\connection.py", line 704, in connect
  File "urllib3\connection.py", line 207, in _new_conn
urllib3.exceptions.ConnectTimeoutError: (<urllib3.connection.HTTPSConnection object at 0x0000023F6CB60E30>, 'Connection to api.github.com timed out. (connect timeout=None)')

The above exception was the direct cause of the following exception:

Traceback (most recent call last):
  File "requests\adapters.py", line 667, in send
  File "urllib3\connectionpool.py", line 841, in urlopen
  File "urllib3\util\retry.py", line 519, in increment
urllib3.exceptions.MaxRetryError: HTTPSConnectionPool(host='api.github.com', port=443): Max retries exceeded with url: /repos/Ilikectrlmusic/auto_ip/contents/781_result/2025-02-14.txt (Caused by ConnectTimeoutError(<urllib3.connection.HTTPSConnection object at 0x0000023F6CB60E30>, 'Connection to api.github.com timed out. (connect timeout=None)'))

During handling of the above exception, another exception occurred:

Traceback (most recent call last):
  File "main.py", line 339, in <module>
  File "main.py", line 307, in upload_result
  File "requests\api.py", line 130, in put
  File "requests\api.py", line 59, in request
  File "requests\sessions.py", line 589, in request
  File "requests\sessions.py", line 703, in send
  File "requests\adapters.py", line 688, in send
requests.exceptions.ConnectTimeout: HTTPSConnectionPool(host='api.github.com', port=443): Max retries exceeded with url: /repos/Ilikectrlmusic/auto_ip/contents/781_result/2025-02-14.txt (Caused by ConnectTimeoutError(<urllib3.connection.HTTPSConnection object at 0x0000023F6CB60E30>, 'Connection to api.github.com timed out. (connect timeout=None)'))

Error during execution: Traceback (most recent call last):
  File "urllib3\connection.py", line 198, in _new_conn
  File "urllib3\util\connection.py", line 85, in create_connection
  File "urllib3\util\connection.py", line 73, in create_connection
TimeoutError: [WinError 10060] 由于连接方在一段时间后没有正确答复或连接的主机没有反应，连接尝试失败。

The above exception was the direct cause of the following exception:

Traceback (most recent call last):
  File "urllib3\connectionpool.py", line 787, in urlopen
  File "urllib3\connectionpool.py", line 488, in _make_request
  File "urllib3\connectionpool.py", line 464, in _make_request
  File "urllib3\connectionpool.py", line 1093, in _validate_conn
  File "urllib3\connection.py", line 704, in connect
  File "urllib3\connection.py", line 207, in _new_conn
urllib3.exceptions.ConnectTimeoutError: (<urllib3.connection.HTTPSConnection object at 0x0000023F6CBA1010>, 'Connection to api.github.com timed out. (connect timeout=None)')

The above exception was the direct cause of the following exception:

Traceback (most recent call last):
  File "requests\adapters.py", line 667, in send
  File "urllib3\connectionpool.py", line 841, in urlopen
  File "urllib3\util\retry.py", line 519, in increment
urllib3.exceptions.MaxRetryError: HTTPSConnectionPool(host='api.github.com', port=443): Max retries exceeded with url: /repos/Ilikectrlmusic/auto_ip/contents/781_result/2025-02-14.txt (Caused by ConnectTimeoutError(<urllib3.connection.HTTPSConnection object at 0x0000023F6CBA1010>, 'Connection to api.github.com timed out. (connect timeout=None)'))

During handling of the above exception, another exception occurred:

Traceback (most recent call last):
  File "main.py", line 339, in <module>
  File "main.py", line 307, in upload_result
  File "requests\api.py", line 130, in put
  File "requests\api.py", line 59, in request
  File "requests\sessions.py", line 589, in request
  File "requests\sessions.py", line 703, in send
  File "requests\adapters.py", line 688, in send
requests.exceptions.ConnectTimeout: HTTPSConnectionPool(host='api.github.com', port=443): Max retries exceeded with url: /repos/Ilikectrlmusic/auto_ip/contents/781_result/2025-02-14.txt (Caused by ConnectTimeoutError(<urllib3.connection.HTTPSConnection object at 0x0000023F6CBA1010>, 'Connection to api.github.com timed out. (connect timeout=None)'))

Error during execution: Traceback (most recent call last):
  File "urllib3\connection.py", line 198, in _new_conn
  File "urllib3\util\connection.py", line 85, in create_connection
  File "urllib3\util\connection.py", line 73, in create_connection
TimeoutError: [WinError 10060] 由于连接方在一段时间后没有正确答复或连接的主机没有反应，连接尝试失败。

The above exception was the direct cause of the following exception:

Traceback (most recent call last):
  File "urllib3\connectionpool.py", line 787, in urlopen
  File "urllib3\connectionpool.py", line 488, in _make_request
  File "urllib3\connectionpool.py", line 464, in _make_request
  File "urllib3\connectionpool.py", line 1093, in _validate_conn
  File "urllib3\connection.py", line 704, in connect
  File "urllib3\connection.py", line 207, in _new_conn
urllib3.exceptions.ConnectTimeoutError: (<urllib3.connection.HTTPSConnection object at 0x0000023F6CBA1A90>, 'Connection to api.github.com timed out. (connect timeout=None)')

The above exception was the direct cause of the following exception:

Traceback (most recent call last):
  File "requests\adapters.py", line 667, in send
  File "urllib3\connectionpool.py", line 841, in urlopen
  File "urllib3\util\retry.py", line 519, in increment
urllib3.exceptions.MaxRetryError: HTTPSConnectionPool(host='api.github.com', port=443): Max retries exceeded with url: /repos/Ilikectrlmusic/auto_ip/contents/781_result/2025-02-14.txt (Caused by ConnectTimeoutError(<urllib3.connection.HTTPSConnection object at 0x0000023F6CBA1A90>, 'Connection to api.github.com timed out. (connect timeout=None)'))

During handling of the above exception, another exception occurred:

Traceback (most recent call last):
  File "main.py", line 339, in <module>
  File "main.py", line 288, in upload_result
  File "requests\api.py", line 73, in get
  File "requests\api.py", line 59, in request
  File "requests\sessions.py", line 589, in request
  File "requests\sessions.py", line 703, in send
  File "requests\adapters.py", line 688, in send
requests.exceptions.ConnectTimeout: HTTPSConnectionPool(host='api.github.com', port=443): Max retries exceeded with url: /repos/Ilikectrlmusic/auto_ip/contents/781_result/2025-02-14.txt (Caused by ConnectTimeoutError(<urllib3.connection.HTTPSConnection object at 0x0000023F6CBA1A90>, 'Connection to api.github.com timed out. (connect timeout=None)'))

Error during execution: Traceback (most recent call last):
  File "urllib3\connection.py", line 198, in _new_conn
  File "urllib3\util\connection.py", line 85, in create_connection
  File "urllib3\util\connection.py", line 73, in create_connection
TimeoutError: [WinError 10060] 由于连接方在一段时间后没有正确答复或连接的主机没有反应，连接尝试失败。

The above exception was the direct cause of the following exception:

Traceback (most recent call last):
  File "urllib3\connectionpool.py", line 787, in urlopen
  File "urllib3\connectionpool.py", line 488, in _make_request
  File "urllib3\connectionpool.py", line 464, in _make_request
  File "urllib3\connectionpool.py", line 1093, in _validate_conn
  File "urllib3\connection.py", line 704, in connect
  File "urllib3\connection.py", line 207, in _new_conn
urllib3.exceptions.ConnectTimeoutError: (<urllib3.connection.HTTPSConnection object at 0x0000023F6CBA1040>, 'Connection to api.github.com timed out. (connect timeout=None)')

The above exception was the direct cause of the following exception:

Traceback (most recent call last):
  File "requests\adapters.py", line 667, in send
  File "urllib3\connectionpool.py", line 841, in urlopen
  File "urllib3\util\retry.py", line 519, in increment
urllib3.exceptions.MaxRetryError: HTTPSConnectionPool(host='api.github.com', port=443): Max retries exceeded with url: /repos/Ilikectrlmusic/auto_ip/contents/781_result/2025-02-14.txt (Caused by ConnectTimeoutError(<urllib3.connection.HTTPSConnection object at 0x0000023F6CBA1040>, 'Connection to api.github.com timed out. (connect timeout=None)'))

During handling of the above exception, another exception occurred:

Traceback (most recent call last):
  File "main.py", line 339, in <module>
  File "main.py", line 307, in upload_result
  File "requests\api.py", line 130, in put
  File "requests\api.py", line 59, in request
  File "requests\sessions.py", line 589, in request
  File "requests\sessions.py", line 703, in send
  File "requests\adapters.py", line 688, in send
requests.exceptions.ConnectTimeout: HTTPSConnectionPool(host='api.github.com', port=443): Max retries exceeded with url: /repos/Ilikectrlmusic/auto_ip/contents/781_result/2025-02-14.txt (Caused by ConnectTimeoutError(<urllib3.connection.HTTPSConnection object at 0x0000023F6CBA1040>, 'Connection to api.github.com timed out. (connect timeout=None)'))

Error during execution: Traceback (most recent call last):
  File "urllib3\connection.py", line 198, in _new_conn
  File "urllib3\util\connection.py", line 85, in create_connection
  File "urllib3\util\connection.py", line 73, in create_connection
TimeoutError: [WinError 10060] 由于连接方在一段时间后没有正确答复或连接的主机没有反应，连接尝试失败。

The above exception was the direct cause of the following exception:

Traceback (most recent call last):
  File "urllib3\connectionpool.py", line 787, in urlopen
  File "urllib3\connectionpool.py", line 488, in _make_request
  File "urllib3\connectionpool.py", line 464, in _make_request
  File "urllib3\connectionpool.py", line 1093, in _validate_conn
  File "urllib3\connection.py", line 704, in connect
  File "urllib3\connection.py", line 207, in _new_conn
urllib3.exceptions.ConnectTimeoutError: (<urllib3.connection.HTTPSConnection object at 0x0000023F6CBC3A40>, 'Connection to api.github.com timed out. (connect timeout=None)')

The above exception was the direct cause of the following exception:

Traceback (most recent call last):
  File "requests\adapters.py", line 667, in send
  File "urllib3\connectionpool.py", line 841, in urlopen
  File "urllib3\util\retry.py", line 519, in increment
urllib3.exceptions.MaxRetryError: HTTPSConnectionPool(host='api.github.com', port=443): Max retries exceeded with url: /repos/Ilikectrlmusic/auto_ip/contents/781_result/2025-02-14.txt (Caused by ConnectTimeoutError(<urllib3.connection.HTTPSConnection object at 0x0000023F6CBC3A40>, 'Connection to api.github.com timed out. (connect timeout=None)'))

During handling of the above exception, another exception occurred:

Traceback (most recent call last):
  File "main.py", line 339, in <module>
  File "main.py", line 288, in upload_result
  File "requests\api.py", line 73, in get
  File "requests\api.py", line 59, in request
  File "requests\sessions.py", line 589, in request
  File "requests\sessions.py", line 703, in send
  File "requests\adapters.py", line 688, in send
requests.exceptions.ConnectTimeout: HTTPSConnectionPool(host='api.github.com', port=443): Max retries exceeded with url: /repos/Ilikectrlmusic/auto_ip/contents/781_result/2025-02-14.txt (Caused by ConnectTimeoutError(<urllib3.connection.HTTPSConnection object at 0x0000023F6CBC3A40>, 'Connection to api.github.com timed out. (connect timeout=None)'))

Error uploading log: HTTPSConnectionPool(host='api.github.com', port=443): Max retries exceeded with url: /repos/Ilikectrlmusic/auto_ip/contents/log/2025-02-14.log (Caused by ConnectTimeoutError(<urllib3.connection.HTTPSConnection object at 0x0000023F6CB951C0>, 'Connection to api.github.com timed out. (connect timeout=None)'))
Error during execution: Traceback (most recent call last):
  File "urllib3\connection.py", line 198, in _new_conn
  File "urllib3\util\connection.py", line 85, in create_connection
  File "urllib3\util\connection.py", line 73, in create_connection
TimeoutError: [WinError 10060] 由于连接方在一段时间后没有正确答复或连接的主机没有反应，连接尝试失败。

The above exception was the direct cause of the following exception:

Traceback (most recent call last):
  File "urllib3\connectionpool.py", line 787, in urlopen
  File "urllib3\connectionpool.py", line 488, in _make_request
  File "urllib3\connectionpool.py", line 464, in _make_request
  File "urllib3\connectionpool.py", line 1093, in _validate_conn
  File "urllib3\connection.py", line 704, in connect
  File "urllib3\connection.py", line 207, in _new_conn
urllib3.exceptions.ConnectTimeoutError: (<urllib3.connection.HTTPSConnection object at 0x0000023F6CBA0140>, 'Connection to api.github.com timed out. (connect timeout=None)')

The above exception was the direct cause of the following exception:

Traceback (most recent call last):
  File "requests\adapters.py", line 667, in send
  File "urllib3\connectionpool.py", line 841, in urlopen
  File "urllib3\util\retry.py", line 519, in increment
urllib3.exceptions.MaxRetryError: HTTPSConnectionPool(host='api.github.com', port=443): Max retries exceeded with url: /repos/Ilikectrlmusic/auto_ip/contents/781_result/2025-02-14.txt (Caused by ConnectTimeoutError(<urllib3.connection.HTTPSConnection object at 0x0000023F6CBA0140>, 'Connection to api.github.com timed out. (connect timeout=None)'))

During handling of the above exception, another exception occurred:

Traceback (most recent call last):
  File "main.py", line 339, in <module>
  File "main.py", line 288, in upload_result
  File "requests\api.py", line 73, in get
  File "requests\api.py", line 59, in request
  File "requests\sessions.py", line 589, in request
  File "requests\sessions.py", line 703, in send
  File "requests\adapters.py", line 688, in send
requests.exceptions.ConnectTimeout: HTTPSConnectionPool(host='api.github.com', port=443): Max retries exceeded with url: /repos/Ilikectrlmusic/auto_ip/contents/781_result/2025-02-14.txt (Caused by ConnectTimeoutError(<urllib3.connection.HTTPSConnection object at 0x0000023F6CBA0140>, 'Connection to api.github.com timed out. (connect timeout=None)'))

Error during execution: Traceback (most recent call last):
  File "urllib3\connection.py", line 198, in _new_conn
  File "urllib3\util\connection.py", line 85, in create_connection
  File "urllib3\util\connection.py", line 73, in create_connection
TimeoutError: [WinError 10060] 由于连接方在一段时间后没有正确答复或连接的主机没有反应，连接尝试失败。

The above exception was the direct cause of the following exception:

Traceback (most recent call last):
  File "urllib3\connectionpool.py", line 787, in urlopen
  File "urllib3\connectionpool.py", line 488, in _make_request
  File "urllib3\connectionpool.py", line 464, in _make_request
  File "urllib3\connectionpool.py", line 1093, in _validate_conn
  File "urllib3\connection.py", line 704, in connect
  File "urllib3\connection.py", line 207, in _new_conn
urllib3.exceptions.ConnectTimeoutError: (<urllib3.connection.HTTPSConnection object at 0x0000023F6CBA3EC0>, 'Connection to api.github.com timed out. (connect timeout=None)')

The above exception was the direct cause of the following exception:

Traceback (most recent call last):
  File "requests\adapters.py", line 667, in send
  File "urllib3\connectionpool.py", line 841, in urlopen
  File "urllib3\util\retry.py", line 519, in increment
urllib3.exceptions.MaxRetryError: HTTPSConnectionPool(host='api.github.com', port=443): Max retries exceeded with url: /repos/Ilikectrlmusic/auto_ip/contents/781_result/2025-02-14.txt (Caused by ConnectTimeoutError(<urllib3.connection.HTTPSConnection object at 0x0000023F6CBA3EC0>, 'Connection to api.github.com timed out. (connect timeout=None)'))

During handling of the above exception, another exception occurred:

Traceback (most recent call last):
  File "main.py", line 339, in <module>
  File "main.py", line 307, in upload_result
  File "requests\api.py", line 130, in put
  File "requests\api.py", line 59, in request
  File "requests\sessions.py", line 589, in request
  File "requests\sessions.py", line 703, in send
  File "requests\adapters.py", line 688, in send
requests.exceptions.ConnectTimeout: HTTPSConnectionPool(host='api.github.com', port=443): Max retries exceeded with url: /repos/Ilikectrlmusic/auto_ip/contents/781_result/2025-02-14.txt (Caused by ConnectTimeoutError(<urllib3.connection.HTTPSConnection object at 0x0000023F6CBA3EC0>, 'Connection to api.github.com timed out. (connect timeout=None)'))

Error during execution: Traceback (most recent call last):
  File "urllib3\connection.py", line 198, in _new_conn
  File "urllib3\util\connection.py", line 85, in create_connection
  File "urllib3\util\connection.py", line 73, in create_connection
TimeoutError: [WinError 10060] 由于连接方在一段时间后没有正确答复或连接的主机没有反应，连接尝试失败。

The above exception was the direct cause of the following exception:

Traceback (most recent call last):
  File "urllib3\connectionpool.py", line 787, in urlopen
  File "urllib3\connectionpool.py", line 488, in _make_request
  File "urllib3\connectionpool.py", line 464, in _make_request
  File "urllib3\connectionpool.py", line 1093, in _validate_conn
  File "urllib3\connection.py", line 704, in connect
  File "urllib3\connection.py", line 207, in _new_conn
urllib3.exceptions.ConnectTimeoutError: (<urllib3.connection.HTTPSConnection object at 0x0000023F6CB96B40>, 'Connection to api.github.com timed out. (connect timeout=None)')

The above exception was the direct cause of the following exception:

Traceback (most recent call last):
  File "requests\adapters.py", line 667, in send
  File "urllib3\connectionpool.py", line 841, in urlopen
  File "urllib3\util\retry.py", line 519, in increment
urllib3.exceptions.MaxRetryError: HTTPSConnectionPool(host='api.github.com', port=443): Max retries exceeded with url: /repos/Ilikectrlmusic/auto_ip/contents/781_result/2025-02-14.txt (Caused by ConnectTimeoutError(<urllib3.connection.HTTPSConnection object at 0x0000023F6CB96B40>, 'Connection to api.github.com timed out. (connect timeout=None)'))

During handling of the above exception, another exception occurred:

Traceback (most recent call last):
  File "main.py", line 339, in <module>
  File "main.py", line 307, in upload_result
  File "requests\api.py", line 130, in put
  File "requests\api.py", line 59, in request
  File "requests\sessions.py", line 589, in request
  File "requests\sessions.py", line 703, in send
  File "requests\adapters.py", line 688, in send
requests.exceptions.ConnectTimeout: HTTPSConnectionPool(host='api.github.com', port=443): Max retries exceeded with url: /repos/Ilikectrlmusic/auto_ip/contents/781_result/2025-02-14.txt (Caused by ConnectTimeoutError(<urllib3.connection.HTTPSConnection object at 0x0000023F6CB96B40>, 'Connection to api.github.com timed out. (connect timeout=None)'))

Error during execution: Traceback (most recent call last):
  File "urllib3\connection.py", line 198, in _new_conn
  File "urllib3\util\connection.py", line 85, in create_connection
  File "urllib3\util\connection.py", line 73, in create_connection
TimeoutError: [WinError 10060] 由于连接方在一段时间后没有正确答复或连接的主机没有反应，连接尝试失败。

The above exception was the direct cause of the following exception:

Traceback (most recent call last):
  File "urllib3\connectionpool.py", line 787, in urlopen
  File "urllib3\connectionpool.py", line 488, in _make_request
  File "urllib3\connectionpool.py", line 464, in _make_request
  File "urllib3\connectionpool.py", line 1093, in _validate_conn
  File "urllib3\connection.py", line 704, in connect
  File "urllib3\connection.py", line 207, in _new_conn
urllib3.exceptions.ConnectTimeoutError: (<urllib3.connection.HTTPSConnection object at 0x0000023F6CBC0260>, 'Connection to api.github.com timed out. (connect timeout=None)')

The above exception was the direct cause of the following exception:

Traceback (most recent call last):
  File "requests\adapters.py", line 667, in send
  File "urllib3\connectionpool.py", line 841, in urlopen
  File "urllib3\util\retry.py", line 519, in increment
urllib3.exceptions.MaxRetryError: HTTPSConnectionPool(host='api.github.com', port=443): Max retries exceeded with url: /repos/Ilikectrlmusic/auto_ip/contents/781_result/2025-02-14.txt (Caused by ConnectTimeoutError(<urllib3.connection.HTTPSConnection object at 0x0000023F6CBC0260>, 'Connection to api.github.com timed out. (connect timeout=None)'))

During handling of the above exception, another exception occurred:

Traceback (most recent call last):
  File "main.py", line 339, in <module>
  File "main.py", line 307, in upload_result
  File "requests\api.py", line 130, in put
  File "requests\api.py", line 59, in request
  File "requests\sessions.py", line 589, in request
  File "requests\sessions.py", line 703, in send
  File "requests\adapters.py", line 688, in send
requests.exceptions.ConnectTimeout: HTTPSConnectionPool(host='api.github.com', port=443): Max retries exceeded with url: /repos/Ilikectrlmusic/auto_ip/contents/781_result/2025-02-14.txt (Caused by ConnectTimeoutError(<urllib3.connection.HTTPSConnection object at 0x0000023F6CBC0260>, 'Connection to api.github.com timed out. (connect timeout=None)'))

Error during execution: Traceback (most recent call last):
  File "urllib3\connection.py", line 198, in _new_conn
  File "urllib3\util\connection.py", line 85, in create_connection
  File "urllib3\util\connection.py", line 73, in create_connection
TimeoutError: [WinError 10060] 由于连接方在一段时间后没有正确答复或连接的主机没有反应，连接尝试失败。

The above exception was the direct cause of the following exception:

Traceback (most recent call last):
  File "urllib3\connectionpool.py", line 787, in urlopen
  File "urllib3\connectionpool.py", line 488, in _make_request
  File "urllib3\connectionpool.py", line 464, in _make_request
  File "urllib3\connectionpool.py", line 1093, in _validate_conn
  File "urllib3\connection.py", line 704, in connect
  File "urllib3\connection.py", line 207, in _new_conn
urllib3.exceptions.ConnectTimeoutError: (<urllib3.connection.HTTPSConnection object at 0x0000023F6CBBD6A0>, 'Connection to api.github.com timed out. (connect timeout=None)')

The above exception was the direct cause of the following exception:

Traceback (most recent call last):
  File "requests\adapters.py", line 667, in send
  File "urllib3\connectionpool.py", line 841, in urlopen
  File "urllib3\util\retry.py", line 519, in increment
urllib3.exceptions.MaxRetryError: HTTPSConnectionPool(host='api.github.com', port=443): Max retries exceeded with url: /repos/Ilikectrlmusic/auto_ip/contents/781_result/2025-02-14.txt (Caused by ConnectTimeoutError(<urllib3.connection.HTTPSConnection object at 0x0000023F6CBBD6A0>, 'Connection to api.github.com timed out. (connect timeout=None)'))

During handling of the above exception, another exception occurred:

Traceback (most recent call last):
  File "main.py", line 339, in <module>
  File "main.py", line 307, in upload_result
  File "requests\api.py", line 130, in put
  File "requests\api.py", line 59, in request
  File "requests\sessions.py", line 589, in request
  File "requests\sessions.py", line 703, in send
  File "requests\adapters.py", line 688, in send
requests.exceptions.ConnectTimeout: HTTPSConnectionPool(host='api.github.com', port=443): Max retries exceeded with url: /repos/Ilikectrlmusic/auto_ip/contents/781_result/2025-02-14.txt (Caused by ConnectTimeoutError(<urllib3.connection.HTTPSConnection object at 0x0000023F6CBBD6A0>, 'Connection to api.github.com timed out. (connect timeout=None)'))

Error during execution: Traceback (most recent call last):
  File "urllib3\connection.py", line 198, in _new_conn
  File "urllib3\util\connection.py", line 85, in create_connection
  File "urllib3\util\connection.py", line 73, in create_connection
TimeoutError: [WinError 10060] 由于连接方在一段时间后没有正确答复或连接的主机没有反应，连接尝试失败。

The above exception was the direct cause of the following exception:

Traceback (most recent call last):
  File "urllib3\connectionpool.py", line 787, in urlopen
  File "urllib3\connectionpool.py", line 488, in _make_request
  File "urllib3\connectionpool.py", line 464, in _make_request
  File "urllib3\connectionpool.py", line 1093, in _validate_conn
  File "urllib3\connection.py", line 704, in connect
  File "urllib3\connection.py", line 207, in _new_conn
urllib3.exceptions.ConnectTimeoutError: (<urllib3.connection.HTTPSConnection object at 0x0000023F6CBC28D0>, 'Connection to api.github.com timed out. (connect timeout=None)')

The above exception was the direct cause of the following exception:

Traceback (most recent call last):
  File "requests\adapters.py", line 667, in send
  File "urllib3\connectionpool.py", line 841, in urlopen
  File "urllib3\util\retry.py", line 519, in increment
urllib3.exceptions.MaxRetryError: HTTPSConnectionPool(host='api.github.com', port=443): Max retries exceeded with url: /repos/Ilikectrlmusic/auto_ip/contents/781_result/2025-02-14.txt (Caused by ConnectTimeoutError(<urllib3.connection.HTTPSConnection object at 0x0000023F6CBC28D0>, 'Connection to api.github.com timed out. (connect timeout=None)'))

During handling of the above exception, another exception occurred:

Traceback (most recent call last):
  File "main.py", line 339, in <module>
  File "main.py", line 307, in upload_result
  File "requests\api.py", line 130, in put
  File "requests\api.py", line 59, in request
  File "requests\sessions.py", line 589, in request
  File "requests\sessions.py", line 703, in send
  File "requests\adapters.py", line 688, in send
requests.exceptions.ConnectTimeout: HTTPSConnectionPool(host='api.github.com', port=443): Max retries exceeded with url: /repos/Ilikectrlmusic/auto_ip/contents/781_result/2025-02-14.txt (Caused by ConnectTimeoutError(<urllib3.connection.HTTPSConnection object at 0x0000023F6CBC28D0>, 'Connection to api.github.com timed out. (connect timeout=None)'))

Error during execution: Traceback (most recent call last):
  File "urllib3\connection.py", line 198, in _new_conn
  File "urllib3\util\connection.py", line 85, in create_connection
  File "urllib3\util\connection.py", line 73, in create_connection
TimeoutError: [WinError 10060] 由于连接方在一段时间后没有正确答复或连接的主机没有反应，连接尝试失败。

The above exception was the direct cause of the following exception:

Traceback (most recent call last):
  File "urllib3\connectionpool.py", line 787, in urlopen
  File "urllib3\connectionpool.py", line 488, in _make_request
  File "urllib3\connectionpool.py", line 464, in _make_request
  File "urllib3\connectionpool.py", line 1093, in _validate_conn
  File "urllib3\connection.py", line 704, in connect
  File "urllib3\connection.py", line 207, in _new_conn
urllib3.exceptions.ConnectTimeoutError: (<urllib3.connection.HTTPSConnection object at 0x0000023F6CB63350>, 'Connection to api.github.com timed out. (connect timeout=None)')

The above exception was the direct cause of the following exception:

Traceback (most recent call last):
  File "requests\adapters.py", line 667, in send
  File "urllib3\connectionpool.py", line 841, in urlopen
  File "urllib3\util\retry.py", line 519, in increment
urllib3.exceptions.MaxRetryError: HTTPSConnectionPool(host='api.github.com', port=443): Max retries exceeded with url: /repos/Ilikectrlmusic/auto_ip/contents/781_result/2025-02-14.txt (Caused by ConnectTimeoutError(<urllib3.connection.HTTPSConnection object at 0x0000023F6CB63350>, 'Connection to api.github.com timed out. (connect timeout=None)'))

During handling of the above exception, another exception occurred:

Traceback (most recent call last):
  File "main.py", line 339, in <module>
  File "main.py", line 307, in upload_result
  File "requests\api.py", line 130, in put
  File "requests\api.py", line 59, in request
  File "requests\sessions.py", line 589, in request
  File "requests\sessions.py", line 703, in send
  File "requests\adapters.py", line 688, in send
requests.exceptions.ConnectTimeout: HTTPSConnectionPool(host='api.github.com', port=443): Max retries exceeded with url: /repos/Ilikectrlmusic/auto_ip/contents/781_result/2025-02-14.txt (Caused by ConnectTimeoutError(<urllib3.connection.HTTPSConnection object at 0x0000023F6CB63350>, 'Connection to api.github.com timed out. (connect timeout=None)'))

Error during execution: Traceback (most recent call last):
  File "urllib3\connection.py", line 198, in _new_conn
  File "urllib3\util\connection.py", line 85, in create_connection
  File "urllib3\util\connection.py", line 73, in create_connection
TimeoutError: [WinError 10060] 由于连接方在一段时间后没有正确答复或连接的主机没有反应，连接尝试失败。

The above exception was the direct cause of the following exception:

Traceback (most recent call last):
  File "urllib3\connectionpool.py", line 787, in urlopen
  File "urllib3\connectionpool.py", line 488, in _make_request
  File "urllib3\connectionpool.py", line 464, in _make_request
  File "urllib3\connectionpool.py", line 1093, in _validate_conn
  File "urllib3\connection.py", line 704, in connect
  File "urllib3\connection.py", line 207, in _new_conn
urllib3.exceptions.ConnectTimeoutError: (<urllib3.connection.HTTPSConnection object at 0x0000023F6CB949E0>, 'Connection to api.github.com timed out. (connect timeout=None)')

The above exception was the direct cause of the following exception:

Traceback (most recent call last):
  File "requests\adapters.py", line 667, in send
  File "urllib3\connectionpool.py", line 841, in urlopen
  File "urllib3\util\retry.py", line 519, in increment
urllib3.exceptions.MaxRetryError: HTTPSConnectionPool(host='api.github.com', port=443): Max retries exceeded with url: /repos/Ilikectrlmusic/auto_ip/contents/781_result/2025-02-14.txt (Caused by ConnectTimeoutError(<urllib3.connection.HTTPSConnection object at 0x0000023F6CB949E0>, 'Connection to api.github.com timed out. (connect timeout=None)'))

During handling of the above exception, another exception occurred:

Traceback (most recent call last):
  File "main.py", line 339, in <module>
  File "main.py", line 307, in upload_result
  File "requests\api.py", line 130, in put
  File "requests\api.py", line 59, in request
  File "requests\sessions.py", line 589, in request
  File "requests\sessions.py", line 703, in send
  File "requests\adapters.py", line 688, in send
requests.exceptions.ConnectTimeout: HTTPSConnectionPool(host='api.github.com', port=443): Max retries exceeded with url: /repos/Ilikectrlmusic/auto_ip/contents/781_result/2025-02-14.txt (Caused by ConnectTimeoutError(<urllib3.connection.HTTPSConnection object at 0x0000023F6CB949E0>, 'Connection to api.github.com timed out. (connect timeout=None)'))

Error during execution: Traceback (most recent call last):
  File "urllib3\connection.py", line 198, in _new_conn
  File "urllib3\util\connection.py", line 85, in create_connection
  File "urllib3\util\connection.py", line 73, in create_connection
TimeoutError: [WinError 10060] 由于连接方在一段时间后没有正确答复或连接的主机没有反应，连接尝试失败。

The above exception was the direct cause of the following exception:

Traceback (most recent call last):
  File "urllib3\connectionpool.py", line 787, in urlopen
  File "urllib3\connectionpool.py", line 488, in _make_request
  File "urllib3\connectionpool.py", line 464, in _make_request
  File "urllib3\connectionpool.py", line 1093, in _validate_conn
  File "urllib3\connection.py", line 704, in connect
  File "urllib3\connection.py", line 207, in _new_conn
urllib3.exceptions.ConnectTimeoutError: (<urllib3.connection.HTTPSConnection object at 0x0000023F6CBC1A30>, 'Connection to api.github.com timed out. (connect timeout=None)')

The above exception was the direct cause of the following exception:

Traceback (most recent call last):
  File "requests\adapters.py", line 667, in send
  File "urllib3\connectionpool.py", line 841, in urlopen
  File "urllib3\util\retry.py", line 519, in increment
urllib3.exceptions.MaxRetryError: HTTPSConnectionPool(host='api.github.com', port=443): Max retries exceeded with url: /repos/Ilikectrlmusic/auto_ip/contents/781_result/2025-02-14.txt (Caused by ConnectTimeoutError(<urllib3.connection.HTTPSConnection object at 0x0000023F6CBC1A30>, 'Connection to api.github.com timed out. (connect timeout=None)'))

During handling of the above exception, another exception occurred:

Traceback (most recent call last):
  File "main.py", line 339, in <module>
  File "main.py", line 288, in upload_result
  File "requests\api.py", line 73, in get
  File "requests\api.py", line 59, in request
  File "requests\sessions.py", line 589, in request
  File "requests\sessions.py", line 703, in send
  File "requests\adapters.py", line 688, in send
requests.exceptions.ConnectTimeout: HTTPSConnectionPool(host='api.github.com', port=443): Max retries exceeded with url: /repos/Ilikectrlmusic/auto_ip/contents/781_result/2025-02-14.txt (Caused by ConnectTimeoutError(<urllib3.connection.HTTPSConnection object at 0x0000023F6CBC1A30>, 'Connection to api.github.com timed out. (connect timeout=None)'))

Error during execution: Traceback (most recent call last):
  File "urllib3\connection.py", line 198, in _new_conn
  File "urllib3\util\connection.py", line 85, in create_connection
  File "urllib3\util\connection.py", line 73, in create_connection
TimeoutError: [WinError 10060] 由于连接方在一段时间后没有正确答复或连接的主机没有反应，连接尝试失败。

The above exception was the direct cause of the following exception:

Traceback (most recent call last):
  File "urllib3\connectionpool.py", line 787, in urlopen
  File "urllib3\connectionpool.py", line 488, in _make_request
  File "urllib3\connectionpool.py", line 464, in _make_request
  File "urllib3\connectionpool.py", line 1093, in _validate_conn
  File "urllib3\connection.py", line 704, in connect
  File "urllib3\connection.py", line 207, in _new_conn
urllib3.exceptions.ConnectTimeoutError: (<urllib3.connection.HTTPSConnection object at 0x0000023F6CBC2780>, 'Connection to api.github.com timed out. (connect timeout=None)')

The above exception was the direct cause of the following exception:

Traceback (most recent call last):
  File "requests\adapters.py", line 667, in send
  File "urllib3\connectionpool.py", line 841, in urlopen
  File "urllib3\util\retry.py", line 519, in increment
urllib3.exceptions.MaxRetryError: HTTPSConnectionPool(host='api.github.com', port=443): Max retries exceeded with url: /repos/Ilikectrlmusic/auto_ip/contents/781_result/2025-02-14.txt (Caused by ConnectTimeoutError(<urllib3.connection.HTTPSConnection object at 0x0000023F6CBC2780>, 'Connection to api.github.com timed out. (connect timeout=None)'))

During handling of the above exception, another exception occurred:

Traceback (most recent call last):
  File "main.py", line 339, in <module>
  File "main.py", line 307, in upload_result
  File "requests\api.py", line 130, in put
  File "requests\api.py", line 59, in request
  File "requests\sessions.py", line 589, in request
  File "requests\sessions.py", line 703, in send
  File "requests\adapters.py", line 688, in send
requests.exceptions.ConnectTimeout: HTTPSConnectionPool(host='api.github.com', port=443): Max retries exceeded with url: /repos/Ilikectrlmusic/auto_ip/contents/781_result/2025-02-14.txt (Caused by ConnectTimeoutError(<urllib3.connection.HTTPSConnection object at 0x0000023F6CBC2780>, 'Connection to api.github.com timed out. (connect timeout=None)'))

Error during execution: Traceback (most recent call last):
  File "urllib3\connection.py", line 198, in _new_conn
  File "urllib3\util\connection.py", line 85, in create_connection
  File "urllib3\util\connection.py", line 73, in create_connection
TimeoutError: [WinError 10060] 由于连接方在一段时间后没有正确答复或连接的主机没有反应，连接尝试失败。

The above exception was the direct cause of the following exception:

Traceback (most recent call last):
  File "urllib3\connectionpool.py", line 787, in urlopen
  File "urllib3\connectionpool.py", line 488, in _make_request
  File "urllib3\connectionpool.py", line 464, in _make_request
  File "urllib3\connectionpool.py", line 1093, in _validate_conn
  File "urllib3\connection.py", line 704, in connect
  File "urllib3\connection.py", line 207, in _new_conn
urllib3.exceptions.ConnectTimeoutError: (<urllib3.connection.HTTPSConnection object at 0x0000023F6CBA03B0>, 'Connection to api.github.com timed out. (connect timeout=None)')

The above exception was the direct cause of the following exception:

Traceback (most recent call last):
  File "requests\adapters.py", line 667, in send
  File "urllib3\connectionpool.py", line 841, in urlopen
  File "urllib3\util\retry.py", line 519, in increment
urllib3.exceptions.MaxRetryError: HTTPSConnectionPool(host='api.github.com', port=443): Max retries exceeded with url: /repos/Ilikectrlmusic/auto_ip/contents/781_result/2025-02-14.txt (Caused by ConnectTimeoutError(<urllib3.connection.HTTPSConnection object at 0x0000023F6CBA03B0>, 'Connection to api.github.com timed out. (connect timeout=None)'))

During handling of the above exception, another exception occurred:

Traceback (most recent call last):
  File "main.py", line 339, in <module>
  File "main.py", line 288, in upload_result
  File "requests\api.py", line 73, in get
  File "requests\api.py", line 59, in request
  File "requests\sessions.py", line 589, in request
  File "requests\sessions.py", line 703, in send
  File "requests\adapters.py", line 688, in send
requests.exceptions.ConnectTimeout: HTTPSConnectionPool(host='api.github.com', port=443): Max retries exceeded with url: /repos/Ilikectrlmusic/auto_ip/contents/781_result/2025-02-14.txt (Caused by ConnectTimeoutError(<urllib3.connection.HTTPSConnection object at 0x0000023F6CBA03B0>, 'Connection to api.github.com timed out. (connect timeout=None)'))

Error during execution: Traceback (most recent call last):
  File "urllib3\connection.py", line 198, in _new_conn
  File "urllib3\util\connection.py", line 85, in create_connection
  File "urllib3\util\connection.py", line 73, in create_connection
TimeoutError: [WinError 10060] 由于连接方在一段时间后没有正确答复或连接的主机没有反应，连接尝试失败。

The above exception was the direct cause of the following exception:

Traceback (most recent call last):
  File "urllib3\connectionpool.py", line 787, in urlopen
  File "urllib3\connectionpool.py", line 488, in _make_request
  File "urllib3\connectionpool.py", line 464, in _make_request
  File "urllib3\connectionpool.py", line 1093, in _validate_conn
  File "urllib3\connection.py", line 704, in connect
  File "urllib3\connection.py", line 207, in _new_conn
urllib3.exceptions.ConnectTimeoutError: (<urllib3.connection.HTTPSConnection object at 0x0000023F6CBC2630>, 'Connection to api.github.com timed out. (connect timeout=None)')

The above exception was the direct cause of the following exception:

Traceback (most recent call last):
  File "requests\adapters.py", line 667, in send
  File "urllib3\connectionpool.py", line 841, in urlopen
  File "urllib3\util\retry.py", line 519, in increment
urllib3.exceptions.MaxRetryError: HTTPSConnectionPool(host='api.github.com', port=443): Max retries exceeded with url: /repos/Ilikectrlmusic/auto_ip/contents/781_result/2025-02-14.txt (Caused by ConnectTimeoutError(<urllib3.connection.HTTPSConnection object at 0x0000023F6CBC2630>, 'Connection to api.github.com timed out. (connect timeout=None)'))

During handling of the above exception, another exception occurred:

Traceback (most recent call last):
  File "main.py", line 339, in <module>
  File "main.py", line 288, in upload_result
  File "requests\api.py", line 73, in get
  File "requests\api.py", line 59, in request
  File "requests\sessions.py", line 589, in request
  File "requests\sessions.py", line 703, in send
  File "requests\adapters.py", line 688, in send
requests.exceptions.ConnectTimeout: HTTPSConnectionPool(host='api.github.com', port=443): Max retries exceeded with url: /repos/Ilikectrlmusic/auto_ip/contents/781_result/2025-02-14.txt (Caused by ConnectTimeoutError(<urllib3.connection.HTTPSConnection object at 0x0000023F6CBC2630>, 'Connection to api.github.com timed out. (connect timeout=None)'))

Error during execution: Traceback (most recent call last):
  File "urllib3\connection.py", line 198, in _new_conn
  File "urllib3\util\connection.py", line 85, in create_connection
  File "urllib3\util\connection.py", line 73, in create_connection
TimeoutError: [WinError 10060] 由于连接方在一段时间后没有正确答复或连接的主机没有反应，连接尝试失败。

The above exception was the direct cause of the following exception:

Traceback (most recent call last):
  File "urllib3\connectionpool.py", line 787, in urlopen
  File "urllib3\connectionpool.py", line 488, in _make_request
  File "urllib3\connectionpool.py", line 464, in _make_request
  File "urllib3\connectionpool.py", line 1093, in _validate_conn
  File "urllib3\connection.py", line 704, in connect
  File "urllib3\connection.py", line 207, in _new_conn
urllib3.exceptions.ConnectTimeoutError: (<urllib3.connection.HTTPSConnection object at 0x0000023F6CBA1010>, 'Connection to api.github.com timed out. (connect timeout=None)')

The above exception was the direct cause of the following exception:

Traceback (most recent call last):
  File "requests\adapters.py", line 667, in send
  File "urllib3\connectionpool.py", line 841, in urlopen
  File "urllib3\util\retry.py", line 519, in increment
urllib3.exceptions.MaxRetryError: HTTPSConnectionPool(host='api.github.com', port=443): Max retries exceeded with url: /repos/Ilikectrlmusic/auto_ip/contents/781_result/2025-02-14.txt (Caused by ConnectTimeoutError(<urllib3.connection.HTTPSConnection object at 0x0000023F6CBA1010>, 'Connection to api.github.com timed out. (connect timeout=None)'))

During handling of the above exception, another exception occurred:

Traceback (most recent call last):
  File "main.py", line 339, in <module>
  File "main.py", line 307, in upload_result
  File "requests\api.py", line 130, in put
  File "requests\api.py", line 59, in request
  File "requests\sessions.py", line 589, in request
  File "requests\sessions.py", line 703, in send
  File "requests\adapters.py", line 688, in send
requests.exceptions.ConnectTimeout: HTTPSConnectionPool(host='api.github.com', port=443): Max retries exceeded with url: /repos/Ilikectrlmusic/auto_ip/contents/781_result/2025-02-14.txt (Caused by ConnectTimeoutError(<urllib3.connection.HTTPSConnection object at 0x0000023F6CBA1010>, 'Connection to api.github.com timed out. (connect timeout=None)'))

