Error during execution: Traceback (most recent call last):
  File "urllib3\connection.py", line 198, in _new_conn
  File "urllib3\util\connection.py", line 85, in create_connection
  File "urllib3\util\connection.py", line 73, in create_connection
TimeoutError: [WinError 10060] 由于连接方在一段时间后没有正确答复或连接的主机没有反应，连接尝试失败。

The above exception was the direct cause of the following exception:

Traceback (most recent call last):
  File "urllib3\connectionpool.py", line 787, in urlopen
  File "urllib3\connectionpool.py", line 488, in _make_request
  File "urllib3\connectionpool.py", line 464, in _make_request
  File "urllib3\connectionpool.py", line 1093, in _validate_conn
  File "urllib3\connection.py", line 704, in connect
  File "urllib3\connection.py", line 207, in _new_conn
urllib3.exceptions.ConnectTimeoutError: (<urllib3.connection.HTTPSConnection object at 0x00000207A907C2F0>, 'Connection to api.github.com timed out. (connect timeout=None)')

The above exception was the direct cause of the following exception:

Traceback (most recent call last):
  File "requests\adapters.py", line 667, in send
  File "urllib3\connectionpool.py", line 841, in urlopen
  File "urllib3\util\retry.py", line 519, in increment
urllib3.exceptions.MaxRetryError: HTTPSConnectionPool(host='api.github.com', port=443): Max retries exceeded with url: /repos/Ilikectrlmusic/auto_ip/contents/781_result/2025-03-08.txt (Caused by ConnectTimeoutError(<urllib3.connection.HTTPSConnection object at 0x00000207A907C2F0>, 'Connection to api.github.com timed out. (connect timeout=None)'))

During handling of the above exception, another exception occurred:

Traceback (most recent call last):
  File "main.py", line 288, in <module>
  File "main.py", line 242, in upload_result
  File "requests\api.py", line 73, in get
  File "requests\api.py", line 59, in request
  File "requests\sessions.py", line 589, in request
  File "requests\sessions.py", line 703, in send
  File "requests\adapters.py", line 688, in send
requests.exceptions.ConnectTimeout: HTTPSConnectionPool(host='api.github.com', port=443): Max retries exceeded with url: /repos/Ilikectrlmusic/auto_ip/contents/781_result/2025-03-08.txt (Caused by ConnectTimeoutError(<urllib3.connection.HTTPSConnection object at 0x00000207A907C2F0>, 'Connection to api.github.com timed out. (connect timeout=None)'))

Error during execution: Traceback (most recent call last):
  File "urllib3\connection.py", line 198, in _new_conn
  File "urllib3\util\connection.py", line 85, in create_connection
  File "urllib3\util\connection.py", line 73, in create_connection
TimeoutError: [WinError 10060] 由于连接方在一段时间后没有正确答复或连接的主机没有反应，连接尝试失败。

The above exception was the direct cause of the following exception:

Traceback (most recent call last):
  File "urllib3\connectionpool.py", line 787, in urlopen
  File "urllib3\connectionpool.py", line 488, in _make_request
  File "urllib3\connectionpool.py", line 464, in _make_request
  File "urllib3\connectionpool.py", line 1093, in _validate_conn
  File "urllib3\connection.py", line 704, in connect
  File "urllib3\connection.py", line 207, in _new_conn
urllib3.exceptions.ConnectTimeoutError: (<urllib3.connection.HTTPSConnection object at 0x00000207A90947D0>, 'Connection to api.github.com timed out. (connect timeout=None)')

The above exception was the direct cause of the following exception:

Traceback (most recent call last):
  File "requests\adapters.py", line 667, in send
  File "urllib3\connectionpool.py", line 841, in urlopen
  File "urllib3\util\retry.py", line 519, in increment
urllib3.exceptions.MaxRetryError: HTTPSConnectionPool(host='api.github.com', port=443): Max retries exceeded with url: /repos/Ilikectrlmusic/auto_ip/contents/781_result/2025-03-08.txt (Caused by ConnectTimeoutError(<urllib3.connection.HTTPSConnection object at 0x00000207A90947D0>, 'Connection to api.github.com timed out. (connect timeout=None)'))

During handling of the above exception, another exception occurred:

Traceback (most recent call last):
  File "main.py", line 288, in <module>
  File "main.py", line 261, in upload_result
  File "requests\api.py", line 130, in put
  File "requests\api.py", line 59, in request
  File "requests\sessions.py", line 589, in request
  File "requests\sessions.py", line 703, in send
  File "requests\adapters.py", line 688, in send
requests.exceptions.ConnectTimeout: HTTPSConnectionPool(host='api.github.com', port=443): Max retries exceeded with url: /repos/Ilikectrlmusic/auto_ip/contents/781_result/2025-03-08.txt (Caused by ConnectTimeoutError(<urllib3.connection.HTTPSConnection object at 0x00000207A90947D0>, 'Connection to api.github.com timed out. (connect timeout=None)'))

Error during execution: Traceback (most recent call last):
  File "urllib3\connection.py", line 198, in _new_conn
  File "urllib3\util\connection.py", line 85, in create_connection
  File "urllib3\util\connection.py", line 73, in create_connection
TimeoutError: [WinError 10060] 由于连接方在一段时间后没有正确答复或连接的主机没有反应，连接尝试失败。

The above exception was the direct cause of the following exception:

Traceback (most recent call last):
  File "urllib3\connectionpool.py", line 787, in urlopen
  File "urllib3\connectionpool.py", line 488, in _make_request
  File "urllib3\connectionpool.py", line 464, in _make_request
  File "urllib3\connectionpool.py", line 1093, in _validate_conn
  File "urllib3\connection.py", line 704, in connect
  File "urllib3\connection.py", line 207, in _new_conn
urllib3.exceptions.ConnectTimeoutError: (<urllib3.connection.HTTPSConnection object at 0x00000207A907D250>, 'Connection to api.github.com timed out. (connect timeout=None)')

The above exception was the direct cause of the following exception:

Traceback (most recent call last):
  File "requests\adapters.py", line 667, in send
  File "urllib3\connectionpool.py", line 841, in urlopen
  File "urllib3\util\retry.py", line 519, in increment
urllib3.exceptions.MaxRetryError: HTTPSConnectionPool(host='api.github.com', port=443): Max retries exceeded with url: /repos/Ilikectrlmusic/auto_ip/contents/781_result/2025-03-08.txt (Caused by ConnectTimeoutError(<urllib3.connection.HTTPSConnection object at 0x00000207A907D250>, 'Connection to api.github.com timed out. (connect timeout=None)'))

During handling of the above exception, another exception occurred:

Traceback (most recent call last):
  File "main.py", line 288, in <module>
  File "main.py", line 261, in upload_result
  File "requests\api.py", line 130, in put
  File "requests\api.py", line 59, in request
  File "requests\sessions.py", line 589, in request
  File "requests\sessions.py", line 703, in send
  File "requests\adapters.py", line 688, in send
requests.exceptions.ConnectTimeout: HTTPSConnectionPool(host='api.github.com', port=443): Max retries exceeded with url: /repos/Ilikectrlmusic/auto_ip/contents/781_result/2025-03-08.txt (Caused by ConnectTimeoutError(<urllib3.connection.HTTPSConnection object at 0x00000207A907D250>, 'Connection to api.github.com timed out. (connect timeout=None)'))

Error during execution: Traceback (most recent call last):
  File "urllib3\connection.py", line 198, in _new_conn
  File "urllib3\util\connection.py", line 85, in create_connection
  File "urllib3\util\connection.py", line 73, in create_connection
TimeoutError: [WinError 10060] 由于连接方在一段时间后没有正确答复或连接的主机没有反应，连接尝试失败。

The above exception was the direct cause of the following exception:

Traceback (most recent call last):
  File "urllib3\connectionpool.py", line 787, in urlopen
  File "urllib3\connectionpool.py", line 488, in _make_request
  File "urllib3\connectionpool.py", line 464, in _make_request
  File "urllib3\connectionpool.py", line 1093, in _validate_conn
  File "urllib3\connection.py", line 704, in connect
  File "urllib3\connection.py", line 207, in _new_conn
urllib3.exceptions.ConnectTimeoutError: (<urllib3.connection.HTTPSConnection object at 0x00000207A907B710>, 'Connection to api.github.com timed out. (connect timeout=None)')

The above exception was the direct cause of the following exception:

Traceback (most recent call last):
  File "requests\adapters.py", line 667, in send
  File "urllib3\connectionpool.py", line 841, in urlopen
  File "urllib3\util\retry.py", line 519, in increment
urllib3.exceptions.MaxRetryError: HTTPSConnectionPool(host='api.github.com', port=443): Max retries exceeded with url: /repos/Ilikectrlmusic/auto_ip/contents/781_result/2025-03-08.txt (Caused by ConnectTimeoutError(<urllib3.connection.HTTPSConnection object at 0x00000207A907B710>, 'Connection to api.github.com timed out. (connect timeout=None)'))

During handling of the above exception, another exception occurred:

Traceback (most recent call last):
  File "main.py", line 288, in <module>
  File "main.py", line 261, in upload_result
  File "requests\api.py", line 130, in put
  File "requests\api.py", line 59, in request
  File "requests\sessions.py", line 589, in request
  File "requests\sessions.py", line 703, in send
  File "requests\adapters.py", line 688, in send
requests.exceptions.ConnectTimeout: HTTPSConnectionPool(host='api.github.com', port=443): Max retries exceeded with url: /repos/Ilikectrlmusic/auto_ip/contents/781_result/2025-03-08.txt (Caused by ConnectTimeoutError(<urllib3.connection.HTTPSConnection object at 0x00000207A907B710>, 'Connection to api.github.com timed out. (connect timeout=None)'))

Error during execution: Traceback (most recent call last):
  File "urllib3\connection.py", line 198, in _new_conn
  File "urllib3\util\connection.py", line 85, in create_connection
  File "urllib3\util\connection.py", line 73, in create_connection
TimeoutError: [WinError 10060] 由于连接方在一段时间后没有正确答复或连接的主机没有反应，连接尝试失败。

The above exception was the direct cause of the following exception:

Traceback (most recent call last):
  File "urllib3\connectionpool.py", line 787, in urlopen
  File "urllib3\connectionpool.py", line 488, in _make_request
  File "urllib3\connectionpool.py", line 464, in _make_request
  File "urllib3\connectionpool.py", line 1093, in _validate_conn
  File "urllib3\connection.py", line 704, in connect
  File "urllib3\connection.py", line 207, in _new_conn
urllib3.exceptions.ConnectTimeoutError: (<urllib3.connection.HTTPSConnection object at 0x00000207A90964B0>, 'Connection to api.github.com timed out. (connect timeout=None)')

The above exception was the direct cause of the following exception:

Traceback (most recent call last):
  File "requests\adapters.py", line 667, in send
  File "urllib3\connectionpool.py", line 841, in urlopen
  File "urllib3\util\retry.py", line 519, in increment
urllib3.exceptions.MaxRetryError: HTTPSConnectionPool(host='api.github.com', port=443): Max retries exceeded with url: /repos/Ilikectrlmusic/auto_ip/contents/781_result/2025-03-08.txt (Caused by ConnectTimeoutError(<urllib3.connection.HTTPSConnection object at 0x00000207A90964B0>, 'Connection to api.github.com timed out. (connect timeout=None)'))

During handling of the above exception, another exception occurred:

Traceback (most recent call last):
  File "main.py", line 288, in <module>
  File "main.py", line 261, in upload_result
  File "requests\api.py", line 130, in put
  File "requests\api.py", line 59, in request
  File "requests\sessions.py", line 589, in request
  File "requests\sessions.py", line 703, in send
  File "requests\adapters.py", line 688, in send
requests.exceptions.ConnectTimeout: HTTPSConnectionPool(host='api.github.com', port=443): Max retries exceeded with url: /repos/Ilikectrlmusic/auto_ip/contents/781_result/2025-03-08.txt (Caused by ConnectTimeoutError(<urllib3.connection.HTTPSConnection object at 0x00000207A90964B0>, 'Connection to api.github.com timed out. (connect timeout=None)'))

Error during execution: Traceback (most recent call last):
  File "urllib3\connection.py", line 198, in _new_conn
  File "urllib3\util\connection.py", line 85, in create_connection
  File "urllib3\util\connection.py", line 73, in create_connection
TimeoutError: [WinError 10060] 由于连接方在一段时间后没有正确答复或连接的主机没有反应，连接尝试失败。

The above exception was the direct cause of the following exception:

Traceback (most recent call last):
  File "urllib3\connectionpool.py", line 787, in urlopen
  File "urllib3\connectionpool.py", line 488, in _make_request
  File "urllib3\connectionpool.py", line 464, in _make_request
  File "urllib3\connectionpool.py", line 1093, in _validate_conn
  File "urllib3\connection.py", line 704, in connect
  File "urllib3\connection.py", line 207, in _new_conn
urllib3.exceptions.ConnectTimeoutError: (<urllib3.connection.HTTPSConnection object at 0x00000207A907ED50>, 'Connection to api.github.com timed out. (connect timeout=None)')

The above exception was the direct cause of the following exception:

Traceback (most recent call last):
  File "requests\adapters.py", line 667, in send
  File "urllib3\connectionpool.py", line 841, in urlopen
  File "urllib3\util\retry.py", line 519, in increment
urllib3.exceptions.MaxRetryError: HTTPSConnectionPool(host='api.github.com', port=443): Max retries exceeded with url: /repos/Ilikectrlmusic/auto_ip/contents/781_result/2025-03-08.txt (Caused by ConnectTimeoutError(<urllib3.connection.HTTPSConnection object at 0x00000207A907ED50>, 'Connection to api.github.com timed out. (connect timeout=None)'))

During handling of the above exception, another exception occurred:

Traceback (most recent call last):
  File "main.py", line 288, in <module>
  File "main.py", line 242, in upload_result
  File "requests\api.py", line 73, in get
  File "requests\api.py", line 59, in request
  File "requests\sessions.py", line 589, in request
  File "requests\sessions.py", line 703, in send
  File "requests\adapters.py", line 688, in send
requests.exceptions.ConnectTimeout: HTTPSConnectionPool(host='api.github.com', port=443): Max retries exceeded with url: /repos/Ilikectrlmusic/auto_ip/contents/781_result/2025-03-08.txt (Caused by ConnectTimeoutError(<urllib3.connection.HTTPSConnection object at 0x00000207A907ED50>, 'Connection to api.github.com timed out. (connect timeout=None)'))

Error during execution: Traceback (most recent call last):
  File "urllib3\connection.py", line 198, in _new_conn
  File "urllib3\util\connection.py", line 85, in create_connection
  File "urllib3\util\connection.py", line 73, in create_connection
TimeoutError: [WinError 10060] 由于连接方在一段时间后没有正确答复或连接的主机没有反应，连接尝试失败。

The above exception was the direct cause of the following exception:

Traceback (most recent call last):
  File "urllib3\connectionpool.py", line 787, in urlopen
  File "urllib3\connectionpool.py", line 488, in _make_request
  File "urllib3\connectionpool.py", line 464, in _make_request
  File "urllib3\connectionpool.py", line 1093, in _validate_conn
  File "urllib3\connection.py", line 704, in connect
  File "urllib3\connection.py", line 207, in _new_conn
urllib3.exceptions.ConnectTimeoutError: (<urllib3.connection.HTTPSConnection object at 0x00000207A903F350>, 'Connection to api.github.com timed out. (connect timeout=None)')

The above exception was the direct cause of the following exception:

Traceback (most recent call last):
  File "requests\adapters.py", line 667, in send
  File "urllib3\connectionpool.py", line 841, in urlopen
  File "urllib3\util\retry.py", line 519, in increment
urllib3.exceptions.MaxRetryError: HTTPSConnectionPool(host='api.github.com', port=443): Max retries exceeded with url: /repos/Ilikectrlmusic/auto_ip/contents/781_result/2025-03-08.txt (Caused by ConnectTimeoutError(<urllib3.connection.HTTPSConnection object at 0x00000207A903F350>, 'Connection to api.github.com timed out. (connect timeout=None)'))

During handling of the above exception, another exception occurred:

Traceback (most recent call last):
  File "main.py", line 288, in <module>
  File "main.py", line 261, in upload_result
  File "requests\api.py", line 130, in put
  File "requests\api.py", line 59, in request
  File "requests\sessions.py", line 589, in request
  File "requests\sessions.py", line 703, in send
  File "requests\adapters.py", line 688, in send
requests.exceptions.ConnectTimeout: HTTPSConnectionPool(host='api.github.com', port=443): Max retries exceeded with url: /repos/Ilikectrlmusic/auto_ip/contents/781_result/2025-03-08.txt (Caused by ConnectTimeoutError(<urllib3.connection.HTTPSConnection object at 0x00000207A903F350>, 'Connection to api.github.com timed out. (connect timeout=None)'))

Error during execution: Traceback (most recent call last):
  File "urllib3\connection.py", line 198, in _new_conn
  File "urllib3\util\connection.py", line 85, in create_connection
  File "urllib3\util\connection.py", line 73, in create_connection
TimeoutError: [WinError 10060] 由于连接方在一段时间后没有正确答复或连接的主机没有反应，连接尝试失败。

The above exception was the direct cause of the following exception:

Traceback (most recent call last):
  File "urllib3\connectionpool.py", line 787, in urlopen
  File "urllib3\connectionpool.py", line 488, in _make_request
  File "urllib3\connectionpool.py", line 464, in _make_request
  File "urllib3\connectionpool.py", line 1093, in _validate_conn
  File "urllib3\connection.py", line 704, in connect
  File "urllib3\connection.py", line 207, in _new_conn
urllib3.exceptions.ConnectTimeoutError: (<urllib3.connection.HTTPSConnection object at 0x00000207A907F920>, 'Connection to api.github.com timed out. (connect timeout=None)')

The above exception was the direct cause of the following exception:

Traceback (most recent call last):
  File "requests\adapters.py", line 667, in send
  File "urllib3\connectionpool.py", line 841, in urlopen
  File "urllib3\util\retry.py", line 519, in increment
urllib3.exceptions.MaxRetryError: HTTPSConnectionPool(host='api.github.com', port=443): Max retries exceeded with url: /repos/Ilikectrlmusic/auto_ip/contents/781_result/2025-03-08.txt (Caused by ConnectTimeoutError(<urllib3.connection.HTTPSConnection object at 0x00000207A907F920>, 'Connection to api.github.com timed out. (connect timeout=None)'))

During handling of the above exception, another exception occurred:

Traceback (most recent call last):
  File "main.py", line 288, in <module>
  File "main.py", line 242, in upload_result
  File "requests\api.py", line 73, in get
  File "requests\api.py", line 59, in request
  File "requests\sessions.py", line 589, in request
  File "requests\sessions.py", line 703, in send
  File "requests\adapters.py", line 688, in send
requests.exceptions.ConnectTimeout: HTTPSConnectionPool(host='api.github.com', port=443): Max retries exceeded with url: /repos/Ilikectrlmusic/auto_ip/contents/781_result/2025-03-08.txt (Caused by ConnectTimeoutError(<urllib3.connection.HTTPSConnection object at 0x00000207A907F920>, 'Connection to api.github.com timed out. (connect timeout=None)'))

Error during execution: Traceback (most recent call last):
  File "urllib3\connection.py", line 198, in _new_conn
  File "urllib3\util\connection.py", line 85, in create_connection
  File "urllib3\util\connection.py", line 73, in create_connection
TimeoutError: [WinError 10060] 由于连接方在一段时间后没有正确答复或连接的主机没有反应，连接尝试失败。

The above exception was the direct cause of the following exception:

Traceback (most recent call last):
  File "urllib3\connectionpool.py", line 787, in urlopen
  File "urllib3\connectionpool.py", line 488, in _make_request
  File "urllib3\connectionpool.py", line 464, in _make_request
  File "urllib3\connectionpool.py", line 1093, in _validate_conn
  File "urllib3\connection.py", line 704, in connect
  File "urllib3\connection.py", line 207, in _new_conn
urllib3.exceptions.ConnectTimeoutError: (<urllib3.connection.HTTPSConnection object at 0x00000207A903EC00>, 'Connection to api.github.com timed out. (connect timeout=None)')

The above exception was the direct cause of the following exception:

Traceback (most recent call last):
  File "requests\adapters.py", line 667, in send
  File "urllib3\connectionpool.py", line 841, in urlopen
  File "urllib3\util\retry.py", line 519, in increment
urllib3.exceptions.MaxRetryError: HTTPSConnectionPool(host='api.github.com', port=443): Max retries exceeded with url: /repos/Ilikectrlmusic/auto_ip/contents/781_result/2025-03-08.txt (Caused by ConnectTimeoutError(<urllib3.connection.HTTPSConnection object at 0x00000207A903EC00>, 'Connection to api.github.com timed out. (connect timeout=None)'))

During handling of the above exception, another exception occurred:

Traceback (most recent call last):
  File "main.py", line 288, in <module>
  File "main.py", line 242, in upload_result
  File "requests\api.py", line 73, in get
  File "requests\api.py", line 59, in request
  File "requests\sessions.py", line 589, in request
  File "requests\sessions.py", line 703, in send
  File "requests\adapters.py", line 688, in send
requests.exceptions.ConnectTimeout: HTTPSConnectionPool(host='api.github.com', port=443): Max retries exceeded with url: /repos/Ilikectrlmusic/auto_ip/contents/781_result/2025-03-08.txt (Caused by ConnectTimeoutError(<urllib3.connection.HTTPSConnection object at 0x00000207A903EC00>, 'Connection to api.github.com timed out. (connect timeout=None)'))

Error during execution: Traceback (most recent call last):
  File "urllib3\connection.py", line 198, in _new_conn
  File "urllib3\util\connection.py", line 85, in create_connection
  File "urllib3\util\connection.py", line 73, in create_connection
TimeoutError: [WinError 10060] 由于连接方在一段时间后没有正确答复或连接的主机没有反应，连接尝试失败。

The above exception was the direct cause of the following exception:

Traceback (most recent call last):
  File "urllib3\connectionpool.py", line 787, in urlopen
  File "urllib3\connectionpool.py", line 488, in _make_request
  File "urllib3\connectionpool.py", line 464, in _make_request
  File "urllib3\connectionpool.py", line 1093, in _validate_conn
  File "urllib3\connection.py", line 704, in connect
  File "urllib3\connection.py", line 207, in _new_conn
urllib3.exceptions.ConnectTimeoutError: (<urllib3.connection.HTTPSConnection object at 0x00000207A7FC68D0>, 'Connection to api.github.com timed out. (connect timeout=None)')

The above exception was the direct cause of the following exception:

Traceback (most recent call last):
  File "requests\adapters.py", line 667, in send
  File "urllib3\connectionpool.py", line 841, in urlopen
  File "urllib3\util\retry.py", line 519, in increment
urllib3.exceptions.MaxRetryError: HTTPSConnectionPool(host='api.github.com', port=443): Max retries exceeded with url: /repos/Ilikectrlmusic/auto_ip/contents/781_result/2025-03-08.txt (Caused by ConnectTimeoutError(<urllib3.connection.HTTPSConnection object at 0x00000207A7FC68D0>, 'Connection to api.github.com timed out. (connect timeout=None)'))

During handling of the above exception, another exception occurred:

Traceback (most recent call last):
  File "main.py", line 288, in <module>
  File "main.py", line 261, in upload_result
  File "requests\api.py", line 130, in put
  File "requests\api.py", line 59, in request
  File "requests\sessions.py", line 589, in request
  File "requests\sessions.py", line 703, in send
  File "requests\adapters.py", line 688, in send
requests.exceptions.ConnectTimeout: HTTPSConnectionPool(host='api.github.com', port=443): Max retries exceeded with url: /repos/Ilikectrlmusic/auto_ip/contents/781_result/2025-03-08.txt (Caused by ConnectTimeoutError(<urllib3.connection.HTTPSConnection object at 0x00000207A7FC68D0>, 'Connection to api.github.com timed out. (connect timeout=None)'))

Error during execution: Traceback (most recent call last):
  File "urllib3\connection.py", line 198, in _new_conn
  File "urllib3\util\connection.py", line 85, in create_connection
  File "urllib3\util\connection.py", line 73, in create_connection
TimeoutError: [WinError 10060] 由于连接方在一段时间后没有正确答复或连接的主机没有反应，连接尝试失败。

The above exception was the direct cause of the following exception:

Traceback (most recent call last):
  File "urllib3\connectionpool.py", line 787, in urlopen
  File "urllib3\connectionpool.py", line 488, in _make_request
  File "urllib3\connectionpool.py", line 464, in _make_request
  File "urllib3\connectionpool.py", line 1093, in _validate_conn
  File "urllib3\connection.py", line 704, in connect
  File "urllib3\connection.py", line 207, in _new_conn
urllib3.exceptions.ConnectTimeoutError: (<urllib3.connection.HTTPSConnection object at 0x00000207A907A960>, 'Connection to api.github.com timed out. (connect timeout=None)')

The above exception was the direct cause of the following exception:

Traceback (most recent call last):
  File "requests\adapters.py", line 667, in send
  File "urllib3\connectionpool.py", line 841, in urlopen
  File "urllib3\util\retry.py", line 519, in increment
urllib3.exceptions.MaxRetryError: HTTPSConnectionPool(host='api.github.com', port=443): Max retries exceeded with url: /repos/Ilikectrlmusic/auto_ip/contents/781_result/2025-03-08.txt (Caused by ConnectTimeoutError(<urllib3.connection.HTTPSConnection object at 0x00000207A907A960>, 'Connection to api.github.com timed out. (connect timeout=None)'))

During handling of the above exception, another exception occurred:

Traceback (most recent call last):
  File "main.py", line 288, in <module>
  File "main.py", line 242, in upload_result
  File "requests\api.py", line 73, in get
  File "requests\api.py", line 59, in request
  File "requests\sessions.py", line 589, in request
  File "requests\sessions.py", line 703, in send
  File "requests\adapters.py", line 688, in send
requests.exceptions.ConnectTimeout: HTTPSConnectionPool(host='api.github.com', port=443): Max retries exceeded with url: /repos/Ilikectrlmusic/auto_ip/contents/781_result/2025-03-08.txt (Caused by ConnectTimeoutError(<urllib3.connection.HTTPSConnection object at 0x00000207A907A960>, 'Connection to api.github.com timed out. (connect timeout=None)'))

Error during execution: Traceback (most recent call last):
  File "urllib3\connection.py", line 198, in _new_conn
  File "urllib3\util\connection.py", line 85, in create_connection
  File "urllib3\util\connection.py", line 73, in create_connection
TimeoutError: [WinError 10060] 由于连接方在一段时间后没有正确答复或连接的主机没有反应，连接尝试失败。

The above exception was the direct cause of the following exception:

Traceback (most recent call last):
  File "urllib3\connectionpool.py", line 787, in urlopen
  File "urllib3\connectionpool.py", line 488, in _make_request
  File "urllib3\connectionpool.py", line 464, in _make_request
  File "urllib3\connectionpool.py", line 1093, in _validate_conn
  File "urllib3\connection.py", line 704, in connect
  File "urllib3\connection.py", line 207, in _new_conn
urllib3.exceptions.ConnectTimeoutError: (<urllib3.connection.HTTPSConnection object at 0x00000207A907D400>, 'Connection to api.github.com timed out. (connect timeout=None)')

The above exception was the direct cause of the following exception:

Traceback (most recent call last):
  File "requests\adapters.py", line 667, in send
  File "urllib3\connectionpool.py", line 841, in urlopen
  File "urllib3\util\retry.py", line 519, in increment
urllib3.exceptions.MaxRetryError: HTTPSConnectionPool(host='api.github.com', port=443): Max retries exceeded with url: /repos/Ilikectrlmusic/auto_ip/contents/781_result/2025-03-08.txt (Caused by ConnectTimeoutError(<urllib3.connection.HTTPSConnection object at 0x00000207A907D400>, 'Connection to api.github.com timed out. (connect timeout=None)'))

During handling of the above exception, another exception occurred:

Traceback (most recent call last):
  File "main.py", line 288, in <module>
  File "main.py", line 261, in upload_result
  File "requests\api.py", line 130, in put
  File "requests\api.py", line 59, in request
  File "requests\sessions.py", line 589, in request
  File "requests\sessions.py", line 703, in send
  File "requests\adapters.py", line 688, in send
requests.exceptions.ConnectTimeout: HTTPSConnectionPool(host='api.github.com', port=443): Max retries exceeded with url: /repos/Ilikectrlmusic/auto_ip/contents/781_result/2025-03-08.txt (Caused by ConnectTimeoutError(<urllib3.connection.HTTPSConnection object at 0x00000207A907D400>, 'Connection to api.github.com timed out. (connect timeout=None)'))

Error during execution: Traceback (most recent call last):
  File "urllib3\connection.py", line 198, in _new_conn
  File "urllib3\util\connection.py", line 85, in create_connection
  File "urllib3\util\connection.py", line 73, in create_connection
TimeoutError: [WinError 10060] 由于连接方在一段时间后没有正确答复或连接的主机没有反应，连接尝试失败。

The above exception was the direct cause of the following exception:

Traceback (most recent call last):
  File "urllib3\connectionpool.py", line 787, in urlopen
  File "urllib3\connectionpool.py", line 488, in _make_request
  File "urllib3\connectionpool.py", line 464, in _make_request
  File "urllib3\connectionpool.py", line 1093, in _validate_conn
  File "urllib3\connection.py", line 704, in connect
  File "urllib3\connection.py", line 207, in _new_conn
urllib3.exceptions.ConnectTimeoutError: (<urllib3.connection.HTTPSConnection object at 0x00000207A9095370>, 'Connection to api.github.com timed out. (connect timeout=None)')

The above exception was the direct cause of the following exception:

Traceback (most recent call last):
  File "requests\adapters.py", line 667, in send
  File "urllib3\connectionpool.py", line 841, in urlopen
  File "urllib3\util\retry.py", line 519, in increment
urllib3.exceptions.MaxRetryError: HTTPSConnectionPool(host='api.github.com', port=443): Max retries exceeded with url: /repos/Ilikectrlmusic/auto_ip/contents/781_result/2025-03-08.txt (Caused by ConnectTimeoutError(<urllib3.connection.HTTPSConnection object at 0x00000207A9095370>, 'Connection to api.github.com timed out. (connect timeout=None)'))

During handling of the above exception, another exception occurred:

Traceback (most recent call last):
  File "main.py", line 288, in <module>
  File "main.py", line 261, in upload_result
  File "requests\api.py", line 130, in put
  File "requests\api.py", line 59, in request
  File "requests\sessions.py", line 589, in request
  File "requests\sessions.py", line 703, in send
  File "requests\adapters.py", line 688, in send
requests.exceptions.ConnectTimeout: HTTPSConnectionPool(host='api.github.com', port=443): Max retries exceeded with url: /repos/Ilikectrlmusic/auto_ip/contents/781_result/2025-03-08.txt (Caused by ConnectTimeoutError(<urllib3.connection.HTTPSConnection object at 0x00000207A9095370>, 'Connection to api.github.com timed out. (connect timeout=None)'))

Error during execution: Traceback (most recent call last):
  File "urllib3\connection.py", line 198, in _new_conn
  File "urllib3\util\connection.py", line 85, in create_connection
  File "urllib3\util\connection.py", line 73, in create_connection
TimeoutError: [WinError 10060] 由于连接方在一段时间后没有正确答复或连接的主机没有反应，连接尝试失败。

The above exception was the direct cause of the following exception:

Traceback (most recent call last):
  File "urllib3\connectionpool.py", line 787, in urlopen
  File "urllib3\connectionpool.py", line 488, in _make_request
  File "urllib3\connectionpool.py", line 464, in _make_request
  File "urllib3\connectionpool.py", line 1093, in _validate_conn
  File "urllib3\connection.py", line 704, in connect
  File "urllib3\connection.py", line 207, in _new_conn
urllib3.exceptions.ConnectTimeoutError: (<urllib3.connection.HTTPSConnection object at 0x00000207A907A000>, 'Connection to api.github.com timed out. (connect timeout=None)')

The above exception was the direct cause of the following exception:

Traceback (most recent call last):
  File "requests\adapters.py", line 667, in send
  File "urllib3\connectionpool.py", line 841, in urlopen
  File "urllib3\util\retry.py", line 519, in increment
urllib3.exceptions.MaxRetryError: HTTPSConnectionPool(host='api.github.com', port=443): Max retries exceeded with url: /repos/Ilikectrlmusic/auto_ip/contents/781_result/2025-03-08.txt (Caused by ConnectTimeoutError(<urllib3.connection.HTTPSConnection object at 0x00000207A907A000>, 'Connection to api.github.com timed out. (connect timeout=None)'))

During handling of the above exception, another exception occurred:

Traceback (most recent call last):
  File "main.py", line 288, in <module>
  File "main.py", line 242, in upload_result
  File "requests\api.py", line 73, in get
  File "requests\api.py", line 59, in request
  File "requests\sessions.py", line 589, in request
  File "requests\sessions.py", line 703, in send
  File "requests\adapters.py", line 688, in send
requests.exceptions.ConnectTimeout: HTTPSConnectionPool(host='api.github.com', port=443): Max retries exceeded with url: /repos/Ilikectrlmusic/auto_ip/contents/781_result/2025-03-08.txt (Caused by ConnectTimeoutError(<urllib3.connection.HTTPSConnection object at 0x00000207A907A000>, 'Connection to api.github.com timed out. (connect timeout=None)'))

Error during execution: Traceback (most recent call last):
  File "urllib3\connection.py", line 198, in _new_conn
  File "urllib3\util\connection.py", line 85, in create_connection
  File "urllib3\util\connection.py", line 73, in create_connection
TimeoutError: [WinError 10060] 由于连接方在一段时间后没有正确答复或连接的主机没有反应，连接尝试失败。

The above exception was the direct cause of the following exception:

Traceback (most recent call last):
  File "urllib3\connectionpool.py", line 787, in urlopen
  File "urllib3\connectionpool.py", line 488, in _make_request
  File "urllib3\connectionpool.py", line 464, in _make_request
  File "urllib3\connectionpool.py", line 1093, in _validate_conn
  File "urllib3\connection.py", line 704, in connect
  File "urllib3\connection.py", line 207, in _new_conn
urllib3.exceptions.ConnectTimeoutError: (<urllib3.connection.HTTPSConnection object at 0x00000207A907DF10>, 'Connection to api.github.com timed out. (connect timeout=None)')

The above exception was the direct cause of the following exception:

Traceback (most recent call last):
  File "requests\adapters.py", line 667, in send
  File "urllib3\connectionpool.py", line 841, in urlopen
  File "urllib3\util\retry.py", line 519, in increment
urllib3.exceptions.MaxRetryError: HTTPSConnectionPool(host='api.github.com', port=443): Max retries exceeded with url: /repos/Ilikectrlmusic/auto_ip/contents/781_result/2025-03-08.txt (Caused by ConnectTimeoutError(<urllib3.connection.HTTPSConnection object at 0x00000207A907DF10>, 'Connection to api.github.com timed out. (connect timeout=None)'))

During handling of the above exception, another exception occurred:

Traceback (most recent call last):
  File "main.py", line 288, in <module>
  File "main.py", line 242, in upload_result
  File "requests\api.py", line 73, in get
  File "requests\api.py", line 59, in request
  File "requests\sessions.py", line 589, in request
  File "requests\sessions.py", line 703, in send
  File "requests\adapters.py", line 688, in send
requests.exceptions.ConnectTimeout: HTTPSConnectionPool(host='api.github.com', port=443): Max retries exceeded with url: /repos/Ilikectrlmusic/auto_ip/contents/781_result/2025-03-08.txt (Caused by ConnectTimeoutError(<urllib3.connection.HTTPSConnection object at 0x00000207A907DF10>, 'Connection to api.github.com timed out. (connect timeout=None)'))

Error during execution: Traceback (most recent call last):
  File "urllib3\connection.py", line 198, in _new_conn
  File "urllib3\util\connection.py", line 85, in create_connection
  File "urllib3\util\connection.py", line 73, in create_connection
TimeoutError: [WinError 10060] 由于连接方在一段时间后没有正确答复或连接的主机没有反应，连接尝试失败。

The above exception was the direct cause of the following exception:

Traceback (most recent call last):
  File "urllib3\connectionpool.py", line 787, in urlopen
  File "urllib3\connectionpool.py", line 488, in _make_request
  File "urllib3\connectionpool.py", line 464, in _make_request
  File "urllib3\connectionpool.py", line 1093, in _validate_conn
  File "urllib3\connection.py", line 704, in connect
  File "urllib3\connection.py", line 207, in _new_conn
urllib3.exceptions.ConnectTimeoutError: (<urllib3.connection.HTTPSConnection object at 0x00000207A9078590>, 'Connection to api.github.com timed out. (connect timeout=None)')

The above exception was the direct cause of the following exception:

Traceback (most recent call last):
  File "requests\adapters.py", line 667, in send
  File "urllib3\connectionpool.py", line 841, in urlopen
  File "urllib3\util\retry.py", line 519, in increment
urllib3.exceptions.MaxRetryError: HTTPSConnectionPool(host='api.github.com', port=443): Max retries exceeded with url: /repos/Ilikectrlmusic/auto_ip/contents/781_result/2025-03-08.txt (Caused by ConnectTimeoutError(<urllib3.connection.HTTPSConnection object at 0x00000207A9078590>, 'Connection to api.github.com timed out. (connect timeout=None)'))

During handling of the above exception, another exception occurred:

Traceback (most recent call last):
  File "main.py", line 288, in <module>
  File "main.py", line 261, in upload_result
  File "requests\api.py", line 130, in put
  File "requests\api.py", line 59, in request
  File "requests\sessions.py", line 589, in request
  File "requests\sessions.py", line 703, in send
  File "requests\adapters.py", line 688, in send
requests.exceptions.ConnectTimeout: HTTPSConnectionPool(host='api.github.com', port=443): Max retries exceeded with url: /repos/Ilikectrlmusic/auto_ip/contents/781_result/2025-03-08.txt (Caused by ConnectTimeoutError(<urllib3.connection.HTTPSConnection object at 0x00000207A9078590>, 'Connection to api.github.com timed out. (connect timeout=None)'))

Error during execution: Traceback (most recent call last):
  File "urllib3\connection.py", line 198, in _new_conn
  File "urllib3\util\connection.py", line 85, in create_connection
  File "urllib3\util\connection.py", line 73, in create_connection
TimeoutError: [WinError 10060] 由于连接方在一段时间后没有正确答复或连接的主机没有反应，连接尝试失败。

The above exception was the direct cause of the following exception:

Traceback (most recent call last):
  File "urllib3\connectionpool.py", line 787, in urlopen
  File "urllib3\connectionpool.py", line 488, in _make_request
  File "urllib3\connectionpool.py", line 464, in _make_request
  File "urllib3\connectionpool.py", line 1093, in _validate_conn
  File "urllib3\connection.py", line 704, in connect
  File "urllib3\connection.py", line 207, in _new_conn
urllib3.exceptions.ConnectTimeoutError: (<urllib3.connection.HTTPSConnection object at 0x00000207A907CF20>, 'Connection to api.github.com timed out. (connect timeout=None)')

The above exception was the direct cause of the following exception:

Traceback (most recent call last):
  File "requests\adapters.py", line 667, in send
  File "urllib3\connectionpool.py", line 841, in urlopen
  File "urllib3\util\retry.py", line 519, in increment
urllib3.exceptions.MaxRetryError: HTTPSConnectionPool(host='api.github.com', port=443): Max retries exceeded with url: /repos/Ilikectrlmusic/auto_ip/contents/781_result/2025-03-08.txt (Caused by ConnectTimeoutError(<urllib3.connection.HTTPSConnection object at 0x00000207A907CF20>, 'Connection to api.github.com timed out. (connect timeout=None)'))

During handling of the above exception, another exception occurred:

Traceback (most recent call last):
  File "main.py", line 288, in <module>
  File "main.py", line 261, in upload_result
  File "requests\api.py", line 130, in put
  File "requests\api.py", line 59, in request
  File "requests\sessions.py", line 589, in request
  File "requests\sessions.py", line 703, in send
  File "requests\adapters.py", line 688, in send
requests.exceptions.ConnectTimeout: HTTPSConnectionPool(host='api.github.com', port=443): Max retries exceeded with url: /repos/Ilikectrlmusic/auto_ip/contents/781_result/2025-03-08.txt (Caused by ConnectTimeoutError(<urllib3.connection.HTTPSConnection object at 0x00000207A907CF20>, 'Connection to api.github.com timed out. (connect timeout=None)'))

Error during execution: Traceback (most recent call last):
  File "urllib3\connection.py", line 198, in _new_conn
  File "urllib3\util\connection.py", line 85, in create_connection
  File "urllib3\util\connection.py", line 73, in create_connection
TimeoutError: [WinError 10060] 由于连接方在一段时间后没有正确答复或连接的主机没有反应，连接尝试失败。

The above exception was the direct cause of the following exception:

Traceback (most recent call last):
  File "urllib3\connectionpool.py", line 787, in urlopen
  File "urllib3\connectionpool.py", line 488, in _make_request
  File "urllib3\connectionpool.py", line 464, in _make_request
  File "urllib3\connectionpool.py", line 1093, in _validate_conn
  File "urllib3\connection.py", line 704, in connect
  File "urllib3\connection.py", line 207, in _new_conn
urllib3.exceptions.ConnectTimeoutError: (<urllib3.connection.HTTPSConnection object at 0x00000207A907C470>, 'Connection to api.github.com timed out. (connect timeout=None)')

The above exception was the direct cause of the following exception:

Traceback (most recent call last):
  File "requests\adapters.py", line 667, in send
  File "urllib3\connectionpool.py", line 841, in urlopen
  File "urllib3\util\retry.py", line 519, in increment
urllib3.exceptions.MaxRetryError: HTTPSConnectionPool(host='api.github.com', port=443): Max retries exceeded with url: /repos/Ilikectrlmusic/auto_ip/contents/781_result/2025-03-08.txt (Caused by ConnectTimeoutError(<urllib3.connection.HTTPSConnection object at 0x00000207A907C470>, 'Connection to api.github.com timed out. (connect timeout=None)'))

During handling of the above exception, another exception occurred:

Traceback (most recent call last):
  File "main.py", line 288, in <module>
  File "main.py", line 261, in upload_result
  File "requests\api.py", line 130, in put
  File "requests\api.py", line 59, in request
  File "requests\sessions.py", line 589, in request
  File "requests\sessions.py", line 703, in send
  File "requests\adapters.py", line 688, in send
requests.exceptions.ConnectTimeout: HTTPSConnectionPool(host='api.github.com', port=443): Max retries exceeded with url: /repos/Ilikectrlmusic/auto_ip/contents/781_result/2025-03-08.txt (Caused by ConnectTimeoutError(<urllib3.connection.HTTPSConnection object at 0x00000207A907C470>, 'Connection to api.github.com timed out. (connect timeout=None)'))

Error during execution: Traceback (most recent call last):
  File "urllib3\connection.py", line 198, in _new_conn
  File "urllib3\util\connection.py", line 85, in create_connection
  File "urllib3\util\connection.py", line 73, in create_connection
TimeoutError: [WinError 10060] 由于连接方在一段时间后没有正确答复或连接的主机没有反应，连接尝试失败。

The above exception was the direct cause of the following exception:

Traceback (most recent call last):
  File "urllib3\connectionpool.py", line 787, in urlopen
  File "urllib3\connectionpool.py", line 488, in _make_request
  File "urllib3\connectionpool.py", line 464, in _make_request
  File "urllib3\connectionpool.py", line 1093, in _validate_conn
  File "urllib3\connection.py", line 704, in connect
  File "urllib3\connection.py", line 207, in _new_conn
urllib3.exceptions.ConnectTimeoutError: (<urllib3.connection.HTTPSConnection object at 0x00000207A9079250>, 'Connection to api.github.com timed out. (connect timeout=None)')

The above exception was the direct cause of the following exception:

Traceback (most recent call last):
  File "requests\adapters.py", line 667, in send
  File "urllib3\connectionpool.py", line 841, in urlopen
  File "urllib3\util\retry.py", line 519, in increment
urllib3.exceptions.MaxRetryError: HTTPSConnectionPool(host='api.github.com', port=443): Max retries exceeded with url: /repos/Ilikectrlmusic/auto_ip/contents/781_result/2025-03-08.txt (Caused by ConnectTimeoutError(<urllib3.connection.HTTPSConnection object at 0x00000207A9079250>, 'Connection to api.github.com timed out. (connect timeout=None)'))

During handling of the above exception, another exception occurred:

Traceback (most recent call last):
  File "main.py", line 288, in <module>
  File "main.py", line 242, in upload_result
  File "requests\api.py", line 73, in get
  File "requests\api.py", line 59, in request
  File "requests\sessions.py", line 589, in request
  File "requests\sessions.py", line 703, in send
  File "requests\adapters.py", line 688, in send
requests.exceptions.ConnectTimeout: HTTPSConnectionPool(host='api.github.com', port=443): Max retries exceeded with url: /repos/Ilikectrlmusic/auto_ip/contents/781_result/2025-03-08.txt (Caused by ConnectTimeoutError(<urllib3.connection.HTTPSConnection object at 0x00000207A9079250>, 'Connection to api.github.com timed out. (connect timeout=None)'))

Error during execution: Traceback (most recent call last):
  File "urllib3\connection.py", line 198, in _new_conn
  File "urllib3\util\connection.py", line 85, in create_connection
  File "urllib3\util\connection.py", line 73, in create_connection
TimeoutError: [WinError 10060] 由于连接方在一段时间后没有正确答复或连接的主机没有反应，连接尝试失败。

The above exception was the direct cause of the following exception:

Traceback (most recent call last):
  File "urllib3\connectionpool.py", line 787, in urlopen
  File "urllib3\connectionpool.py", line 488, in _make_request
  File "urllib3\connectionpool.py", line 464, in _make_request
  File "urllib3\connectionpool.py", line 1093, in _validate_conn
  File "urllib3\connection.py", line 704, in connect
  File "urllib3\connection.py", line 207, in _new_conn
urllib3.exceptions.ConnectTimeoutError: (<urllib3.connection.HTTPSConnection object at 0x00000207A90791C0>, 'Connection to api.github.com timed out. (connect timeout=None)')

The above exception was the direct cause of the following exception:

Traceback (most recent call last):
  File "requests\adapters.py", line 667, in send
  File "urllib3\connectionpool.py", line 841, in urlopen
  File "urllib3\util\retry.py", line 519, in increment
urllib3.exceptions.MaxRetryError: HTTPSConnectionPool(host='api.github.com', port=443): Max retries exceeded with url: /repos/Ilikectrlmusic/auto_ip/contents/781_result/2025-03-08.txt (Caused by ConnectTimeoutError(<urllib3.connection.HTTPSConnection object at 0x00000207A90791C0>, 'Connection to api.github.com timed out. (connect timeout=None)'))

During handling of the above exception, another exception occurred:

Traceback (most recent call last):
  File "main.py", line 288, in <module>
  File "main.py", line 261, in upload_result
  File "requests\api.py", line 130, in put
  File "requests\api.py", line 59, in request
  File "requests\sessions.py", line 589, in request
  File "requests\sessions.py", line 703, in send
  File "requests\adapters.py", line 688, in send
requests.exceptions.ConnectTimeout: HTTPSConnectionPool(host='api.github.com', port=443): Max retries exceeded with url: /repos/Ilikectrlmusic/auto_ip/contents/781_result/2025-03-08.txt (Caused by ConnectTimeoutError(<urllib3.connection.HTTPSConnection object at 0x00000207A90791C0>, 'Connection to api.github.com timed out. (connect timeout=None)'))

Error during execution: Traceback (most recent call last):
  File "urllib3\connection.py", line 198, in _new_conn
  File "urllib3\util\connection.py", line 85, in create_connection
  File "urllib3\util\connection.py", line 73, in create_connection
TimeoutError: [WinError 10060] 由于连接方在一段时间后没有正确答复或连接的主机没有反应，连接尝试失败。

The above exception was the direct cause of the following exception:

Traceback (most recent call last):
  File "urllib3\connectionpool.py", line 787, in urlopen
  File "urllib3\connectionpool.py", line 488, in _make_request
  File "urllib3\connectionpool.py", line 464, in _make_request
  File "urllib3\connectionpool.py", line 1093, in _validate_conn
  File "urllib3\connection.py", line 704, in connect
  File "urllib3\connection.py", line 207, in _new_conn
urllib3.exceptions.ConnectTimeoutError: (<urllib3.connection.HTTPSConnection object at 0x00000207A903EE10>, 'Connection to api.github.com timed out. (connect timeout=None)')

The above exception was the direct cause of the following exception:

Traceback (most recent call last):
  File "requests\adapters.py", line 667, in send
  File "urllib3\connectionpool.py", line 841, in urlopen
  File "urllib3\util\retry.py", line 519, in increment
urllib3.exceptions.MaxRetryError: HTTPSConnectionPool(host='api.github.com', port=443): Max retries exceeded with url: /repos/Ilikectrlmusic/auto_ip/contents/781_result/2025-03-08.txt (Caused by ConnectTimeoutError(<urllib3.connection.HTTPSConnection object at 0x00000207A903EE10>, 'Connection to api.github.com timed out. (connect timeout=None)'))

During handling of the above exception, another exception occurred:

Traceback (most recent call last):
  File "main.py", line 288, in <module>
  File "main.py", line 242, in upload_result
  File "requests\api.py", line 73, in get
  File "requests\api.py", line 59, in request
  File "requests\sessions.py", line 589, in request
  File "requests\sessions.py", line 703, in send
  File "requests\adapters.py", line 688, in send
requests.exceptions.ConnectTimeout: HTTPSConnectionPool(host='api.github.com', port=443): Max retries exceeded with url: /repos/Ilikectrlmusic/auto_ip/contents/781_result/2025-03-08.txt (Caused by ConnectTimeoutError(<urllib3.connection.HTTPSConnection object at 0x00000207A903EE10>, 'Connection to api.github.com timed out. (connect timeout=None)'))

Error during execution: Traceback (most recent call last):
  File "urllib3\connection.py", line 198, in _new_conn
  File "urllib3\util\connection.py", line 85, in create_connection
  File "urllib3\util\connection.py", line 73, in create_connection
TimeoutError: [WinError 10060] 由于连接方在一段时间后没有正确答复或连接的主机没有反应，连接尝试失败。

The above exception was the direct cause of the following exception:

Traceback (most recent call last):
  File "urllib3\connectionpool.py", line 787, in urlopen
  File "urllib3\connectionpool.py", line 488, in _make_request
  File "urllib3\connectionpool.py", line 464, in _make_request
  File "urllib3\connectionpool.py", line 1093, in _validate_conn
  File "urllib3\connection.py", line 704, in connect
  File "urllib3\connection.py", line 207, in _new_conn
urllib3.exceptions.ConnectTimeoutError: (<urllib3.connection.HTTPSConnection object at 0x00000207A9078290>, 'Connection to api.github.com timed out. (connect timeout=None)')

The above exception was the direct cause of the following exception:

Traceback (most recent call last):
  File "requests\adapters.py", line 667, in send
  File "urllib3\connectionpool.py", line 841, in urlopen
  File "urllib3\util\retry.py", line 519, in increment
urllib3.exceptions.MaxRetryError: HTTPSConnectionPool(host='api.github.com', port=443): Max retries exceeded with url: /repos/Ilikectrlmusic/auto_ip/contents/781_result/2025-03-08.txt (Caused by ConnectTimeoutError(<urllib3.connection.HTTPSConnection object at 0x00000207A9078290>, 'Connection to api.github.com timed out. (connect timeout=None)'))

During handling of the above exception, another exception occurred:

Traceback (most recent call last):
  File "main.py", line 288, in <module>
  File "main.py", line 261, in upload_result
  File "requests\api.py", line 130, in put
  File "requests\api.py", line 59, in request
  File "requests\sessions.py", line 589, in request
  File "requests\sessions.py", line 703, in send
  File "requests\adapters.py", line 688, in send
requests.exceptions.ConnectTimeout: HTTPSConnectionPool(host='api.github.com', port=443): Max retries exceeded with url: /repos/Ilikectrlmusic/auto_ip/contents/781_result/2025-03-08.txt (Caused by ConnectTimeoutError(<urllib3.connection.HTTPSConnection object at 0x00000207A9078290>, 'Connection to api.github.com timed out. (connect timeout=None)'))

Error during execution: Traceback (most recent call last):
  File "urllib3\connection.py", line 198, in _new_conn
  File "urllib3\util\connection.py", line 85, in create_connection
  File "urllib3\util\connection.py", line 73, in create_connection
TimeoutError: [WinError 10060] 由于连接方在一段时间后没有正确答复或连接的主机没有反应，连接尝试失败。

The above exception was the direct cause of the following exception:

Traceback (most recent call last):
  File "urllib3\connectionpool.py", line 787, in urlopen
  File "urllib3\connectionpool.py", line 488, in _make_request
  File "urllib3\connectionpool.py", line 464, in _make_request
  File "urllib3\connectionpool.py", line 1093, in _validate_conn
  File "urllib3\connection.py", line 704, in connect
  File "urllib3\connection.py", line 207, in _new_conn
urllib3.exceptions.ConnectTimeoutError: (<urllib3.connection.HTTPSConnection object at 0x00000207A907E090>, 'Connection to api.github.com timed out. (connect timeout=None)')

The above exception was the direct cause of the following exception:

Traceback (most recent call last):
  File "requests\adapters.py", line 667, in send
  File "urllib3\connectionpool.py", line 841, in urlopen
  File "urllib3\util\retry.py", line 519, in increment
urllib3.exceptions.MaxRetryError: HTTPSConnectionPool(host='api.github.com', port=443): Max retries exceeded with url: /repos/Ilikectrlmusic/auto_ip/contents/781_result/2025-03-08.txt (Caused by ConnectTimeoutError(<urllib3.connection.HTTPSConnection object at 0x00000207A907E090>, 'Connection to api.github.com timed out. (connect timeout=None)'))

During handling of the above exception, another exception occurred:

Traceback (most recent call last):
  File "main.py", line 288, in <module>
  File "main.py", line 261, in upload_result
  File "requests\api.py", line 130, in put
  File "requests\api.py", line 59, in request
  File "requests\sessions.py", line 589, in request
  File "requests\sessions.py", line 703, in send
  File "requests\adapters.py", line 688, in send
requests.exceptions.ConnectTimeout: HTTPSConnectionPool(host='api.github.com', port=443): Max retries exceeded with url: /repos/Ilikectrlmusic/auto_ip/contents/781_result/2025-03-08.txt (Caused by ConnectTimeoutError(<urllib3.connection.HTTPSConnection object at 0x00000207A907E090>, 'Connection to api.github.com timed out. (connect timeout=None)'))

Error during execution: Traceback (most recent call last):
  File "urllib3\connection.py", line 198, in _new_conn
  File "urllib3\util\connection.py", line 85, in create_connection
  File "urllib3\util\connection.py", line 73, in create_connection
TimeoutError: [WinError 10060] 由于连接方在一段时间后没有正确答复或连接的主机没有反应，连接尝试失败。

The above exception was the direct cause of the following exception:

Traceback (most recent call last):
  File "urllib3\connectionpool.py", line 787, in urlopen
  File "urllib3\connectionpool.py", line 488, in _make_request
  File "urllib3\connectionpool.py", line 464, in _make_request
  File "urllib3\connectionpool.py", line 1093, in _validate_conn
  File "urllib3\connection.py", line 704, in connect
  File "urllib3\connection.py", line 207, in _new_conn
urllib3.exceptions.ConnectTimeoutError: (<urllib3.connection.HTTPSConnection object at 0x00000207A9094410>, 'Connection to api.github.com timed out. (connect timeout=None)')

The above exception was the direct cause of the following exception:

Traceback (most recent call last):
  File "requests\adapters.py", line 667, in send
  File "urllib3\connectionpool.py", line 841, in urlopen
  File "urllib3\util\retry.py", line 519, in increment
urllib3.exceptions.MaxRetryError: HTTPSConnectionPool(host='api.github.com', port=443): Max retries exceeded with url: /repos/Ilikectrlmusic/auto_ip/contents/781_result/2025-03-08.txt (Caused by ConnectTimeoutError(<urllib3.connection.HTTPSConnection object at 0x00000207A9094410>, 'Connection to api.github.com timed out. (connect timeout=None)'))

During handling of the above exception, another exception occurred:

Traceback (most recent call last):
  File "main.py", line 288, in <module>
  File "main.py", line 261, in upload_result
  File "requests\api.py", line 130, in put
  File "requests\api.py", line 59, in request
  File "requests\sessions.py", line 589, in request
  File "requests\sessions.py", line 703, in send
  File "requests\adapters.py", line 688, in send
requests.exceptions.ConnectTimeout: HTTPSConnectionPool(host='api.github.com', port=443): Max retries exceeded with url: /repos/Ilikectrlmusic/auto_ip/contents/781_result/2025-03-08.txt (Caused by ConnectTimeoutError(<urllib3.connection.HTTPSConnection object at 0x00000207A9094410>, 'Connection to api.github.com timed out. (connect timeout=None)'))

Error during execution: Traceback (most recent call last):
  File "urllib3\connection.py", line 198, in _new_conn
  File "urllib3\util\connection.py", line 85, in create_connection
  File "urllib3\util\connection.py", line 73, in create_connection
TimeoutError: [WinError 10060] 由于连接方在一段时间后没有正确答复或连接的主机没有反应，连接尝试失败。

The above exception was the direct cause of the following exception:

Traceback (most recent call last):
  File "urllib3\connectionpool.py", line 787, in urlopen
  File "urllib3\connectionpool.py", line 488, in _make_request
  File "urllib3\connectionpool.py", line 464, in _make_request
  File "urllib3\connectionpool.py", line 1093, in _validate_conn
  File "urllib3\connection.py", line 704, in connect
  File "urllib3\connection.py", line 207, in _new_conn
urllib3.exceptions.ConnectTimeoutError: (<urllib3.connection.HTTPSConnection object at 0x00000207A907CAD0>, 'Connection to api.github.com timed out. (connect timeout=None)')

The above exception was the direct cause of the following exception:

Traceback (most recent call last):
  File "requests\adapters.py", line 667, in send
  File "urllib3\connectionpool.py", line 841, in urlopen
  File "urllib3\util\retry.py", line 519, in increment
urllib3.exceptions.MaxRetryError: HTTPSConnectionPool(host='api.github.com', port=443): Max retries exceeded with url: /repos/Ilikectrlmusic/auto_ip/contents/781_result/2025-03-08.txt (Caused by ConnectTimeoutError(<urllib3.connection.HTTPSConnection object at 0x00000207A907CAD0>, 'Connection to api.github.com timed out. (connect timeout=None)'))

During handling of the above exception, another exception occurred:

Traceback (most recent call last):
  File "main.py", line 288, in <module>
  File "main.py", line 242, in upload_result
  File "requests\api.py", line 73, in get
  File "requests\api.py", line 59, in request
  File "requests\sessions.py", line 589, in request
  File "requests\sessions.py", line 703, in send
  File "requests\adapters.py", line 688, in send
requests.exceptions.ConnectTimeout: HTTPSConnectionPool(host='api.github.com', port=443): Max retries exceeded with url: /repos/Ilikectrlmusic/auto_ip/contents/781_result/2025-03-08.txt (Caused by ConnectTimeoutError(<urllib3.connection.HTTPSConnection object at 0x00000207A907CAD0>, 'Connection to api.github.com timed out. (connect timeout=None)'))

Error during execution: Traceback (most recent call last):
  File "urllib3\connection.py", line 198, in _new_conn
  File "urllib3\util\connection.py", line 85, in create_connection
  File "urllib3\util\connection.py", line 73, in create_connection
TimeoutError: [WinError 10060] 由于连接方在一段时间后没有正确答复或连接的主机没有反应，连接尝试失败。

The above exception was the direct cause of the following exception:

Traceback (most recent call last):
  File "urllib3\connectionpool.py", line 787, in urlopen
  File "urllib3\connectionpool.py", line 488, in _make_request
  File "urllib3\connectionpool.py", line 464, in _make_request
  File "urllib3\connectionpool.py", line 1093, in _validate_conn
  File "urllib3\connection.py", line 704, in connect
  File "urllib3\connection.py", line 207, in _new_conn
urllib3.exceptions.ConnectTimeoutError: (<urllib3.connection.HTTPSConnection object at 0x00000207A907D670>, 'Connection to api.github.com timed out. (connect timeout=None)')

The above exception was the direct cause of the following exception:

Traceback (most recent call last):
  File "requests\adapters.py", line 667, in send
  File "urllib3\connectionpool.py", line 841, in urlopen
  File "urllib3\util\retry.py", line 519, in increment
urllib3.exceptions.MaxRetryError: HTTPSConnectionPool(host='api.github.com', port=443): Max retries exceeded with url: /repos/Ilikectrlmusic/auto_ip/contents/781_result/2025-03-08.txt (Caused by ConnectTimeoutError(<urllib3.connection.HTTPSConnection object at 0x00000207A907D670>, 'Connection to api.github.com timed out. (connect timeout=None)'))

During handling of the above exception, another exception occurred:

Traceback (most recent call last):
  File "main.py", line 288, in <module>
  File "main.py", line 261, in upload_result
  File "requests\api.py", line 130, in put
  File "requests\api.py", line 59, in request
  File "requests\sessions.py", line 589, in request
  File "requests\sessions.py", line 703, in send
  File "requests\adapters.py", line 688, in send
requests.exceptions.ConnectTimeout: HTTPSConnectionPool(host='api.github.com', port=443): Max retries exceeded with url: /repos/Ilikectrlmusic/auto_ip/contents/781_result/2025-03-08.txt (Caused by ConnectTimeoutError(<urllib3.connection.HTTPSConnection object at 0x00000207A907D670>, 'Connection to api.github.com timed out. (connect timeout=None)'))

